25-02-2021 08:19:53 INFO     [autoreload.py:617] Watching for file changes with StatReloader
25-02-2021 08:21:58 INFO     [autoreload.py:240] /home/mohamedwahba/Desktop/DEV/Order-System/utils/fixer.py changed, reloading.
25-02-2021 08:21:58 DEBUG    [selector_events.py:59] Using selector: EpollSelector
25-02-2021 08:21:58 INFO     [autoreload.py:617] Watching for file changes with StatReloader
25-02-2021 08:23:56 INFO     [autoreload.py:240] /home/mohamedwahba/Desktop/DEV/Order-System/product/urls.py changed, reloading.
25-02-2021 08:23:56 DEBUG    [selector_events.py:59] Using selector: EpollSelector
25-02-2021 08:23:56 INFO     [autoreload.py:617] Watching for file changes with StatReloader
25-02-2021 08:37:38 DEBUG    [selector_events.py:59] Using selector: EpollSelector
25-02-2021 08:37:43 DEBUG    [selector_events.py:59] Using selector: EpollSelector
25-02-2021 08:37:43 INFO     [connectionpool.py:212] Starting new HTTP connection (1): data.fixer.io
25-02-2021 08:37:44 DEBUG    [connectionpool.py:394] "GET /api/latest?access_key=34e2df461e05e5871c51b4293d8a62c8 HTTP/1.1" 200 None
25-02-2021 08:37:46 WARNING  [log.py:224] Method Not Allowed: /api/user/me/
25-02-2021 08:37:47 WARNING  [log.py:224] Bad Request: /api/user/token/
25-02-2021 08:37:47 WARNING  [log.py:224] Bad Request: /api/user/token/
25-02-2021 08:37:47 WARNING  [log.py:224] Bad Request: /api/user/token/
25-02-2021 08:37:47 WARNING  [log.py:224] Bad Request: /api/user/create/
25-02-2021 08:37:47 WARNING  [log.py:224] Unauthorized: /api/user/me/
25-02-2021 08:37:47 WARNING  [log.py:224] Bad Request: /api/user/create/
25-02-2021 08:37:52 DEBUG    [selector_events.py:59] Using selector: EpollSelector
25-02-2021 08:37:52 INFO     [connectionpool.py:212] Starting new HTTP connection (1): data.fixer.io
25-02-2021 08:37:53 DEBUG    [connectionpool.py:394] "GET /api/latest?access_key=34e2df461e05e5871c51b4293d8a62c8 HTTP/1.1" 200 None
25-02-2021 08:37:54 WARNING  [log.py:224] Method Not Allowed: /api/user/me/
25-02-2021 08:37:55 WARNING  [log.py:224] Bad Request: /api/user/token/
25-02-2021 08:37:55 WARNING  [log.py:224] Bad Request: /api/user/token/
25-02-2021 08:37:55 WARNING  [log.py:224] Bad Request: /api/user/token/
25-02-2021 08:37:55 WARNING  [log.py:224] Bad Request: /api/user/create/
25-02-2021 08:37:55 WARNING  [log.py:224] Unauthorized: /api/user/me/
25-02-2021 08:37:55 WARNING  [log.py:224] Bad Request: /api/user/create/
25-02-2021 08:38:33 DEBUG    [selector_events.py:59] Using selector: EpollSelector
25-02-2021 08:38:34 INFO     [connectionpool.py:212] Starting new HTTP connection (1): data.fixer.io
25-02-2021 08:38:34 DEBUG    [connectionpool.py:394] "GET /api/latest?access_key=34e2df461e05e5871c51b4293d8a62c8 HTTP/1.1" 200 None
25-02-2021 08:38:35 WARNING  [log.py:224] Method Not Allowed: /api/user/me/
25-02-2021 08:38:36 WARNING  [log.py:224] Bad Request: /api/user/token/
25-02-2021 08:38:36 WARNING  [log.py:224] Bad Request: /api/user/token/
25-02-2021 08:38:36 WARNING  [log.py:224] Bad Request: /api/user/token/
25-02-2021 08:38:37 WARNING  [log.py:224] Bad Request: /api/user/create/
25-02-2021 08:38:37 WARNING  [log.py:224] Unauthorized: /api/user/me/
25-02-2021 08:38:37 WARNING  [log.py:224] Bad Request: /api/user/create/
25-02-2021 08:39:39 DEBUG    [selector_events.py:59] Using selector: EpollSelector
25-02-2021 08:39:39 INFO     [connectionpool.py:212] Starting new HTTP connection (1): data.fixer.io
25-02-2021 08:39:40 DEBUG    [connectionpool.py:394] "GET /api/latest?access_key=34e2df461e05e5871c51b4293d8a62c8 HTTP/1.1" 200 None
25-02-2021 08:39:41 WARNING  [log.py:224] Method Not Allowed: /api/user/me/
25-02-2021 08:39:42 WARNING  [log.py:224] Bad Request: /api/user/token/
25-02-2021 08:39:42 WARNING  [log.py:224] Bad Request: /api/user/token/
25-02-2021 08:39:42 WARNING  [log.py:224] Bad Request: /api/user/token/
25-02-2021 08:39:42 WARNING  [log.py:224] Bad Request: /api/user/create/
25-02-2021 08:39:42 WARNING  [log.py:224] Unauthorized: /api/user/me/
25-02-2021 08:39:43 WARNING  [log.py:224] Bad Request: /api/user/create/
25-02-2021 08:40:21 DEBUG    [selector_events.py:59] Using selector: EpollSelector
25-02-2021 08:40:21 INFO     [connectionpool.py:212] Starting new HTTP connection (1): data.fixer.io
25-02-2021 08:40:22 DEBUG    [connectionpool.py:394] "GET /api/latest?access_key=34e2df461e05e5871c51b4293d8a62c8 HTTP/1.1" 200 None
25-02-2021 08:40:23 WARNING  [log.py:224] Method Not Allowed: /api/user/me/
25-02-2021 08:40:24 WARNING  [log.py:224] Bad Request: /api/user/token/
25-02-2021 08:40:24 WARNING  [log.py:224] Bad Request: /api/user/token/
25-02-2021 08:40:24 WARNING  [log.py:224] Bad Request: /api/user/token/
25-02-2021 08:40:24 WARNING  [log.py:224] Bad Request: /api/user/create/
25-02-2021 08:40:24 WARNING  [log.py:224] Unauthorized: /api/user/me/
25-02-2021 08:40:24 WARNING  [log.py:224] Bad Request: /api/user/create/
25-02-2021 08:40:40 DEBUG    [selector_events.py:59] Using selector: EpollSelector
25-02-2021 08:40:40 INFO     [connectionpool.py:212] Starting new HTTP connection (1): data.fixer.io
25-02-2021 08:40:40 DEBUG    [connectionpool.py:394] "GET /api/latest?access_key=34e2df461e05e5871c51b4293d8a62c8 HTTP/1.1" 200 None
25-02-2021 08:40:42 WARNING  [log.py:224] Method Not Allowed: /api/user/me/
25-02-2021 08:40:43 WARNING  [log.py:224] Bad Request: /api/user/token/
25-02-2021 08:40:43 WARNING  [log.py:224] Bad Request: /api/user/token/
25-02-2021 08:40:43 WARNING  [log.py:224] Bad Request: /api/user/token/
25-02-2021 08:40:43 WARNING  [log.py:224] Bad Request: /api/user/create/
25-02-2021 08:40:43 WARNING  [log.py:224] Unauthorized: /api/user/me/
25-02-2021 08:40:43 WARNING  [log.py:224] Bad Request: /api/user/create/
25-02-2021 08:47:25 DEBUG    [selector_events.py:59] Using selector: EpollSelector
25-02-2021 08:47:25 INFO     [connectionpool.py:212] Starting new HTTP connection (1): data.fixer.io
25-02-2021 08:47:26 DEBUG    [connectionpool.py:394] "GET /api/latest?access_key=34e2df461e05e5871c51b4293d8a62c8 HTTP/1.1" 200 None
25-02-2021 08:47:27 WARNING  [log.py:224] Method Not Allowed: /api/user/me/
25-02-2021 08:47:28 WARNING  [log.py:224] Bad Request: /api/user/token/
25-02-2021 08:47:28 WARNING  [log.py:224] Bad Request: /api/user/token/
25-02-2021 08:47:28 WARNING  [log.py:224] Bad Request: /api/user/token/
25-02-2021 08:47:28 WARNING  [log.py:224] Bad Request: /api/user/create/
25-02-2021 08:47:28 WARNING  [log.py:224] Unauthorized: /api/user/me/
25-02-2021 08:47:28 WARNING  [log.py:224] Bad Request: /api/user/create/
25-02-2021 08:47:29 WARNING  [log.py:224] Unauthorized: /api/product/product/
25-02-2021 08:47:43 DEBUG    [selector_events.py:59] Using selector: EpollSelector
25-02-2021 08:47:43 INFO     [connectionpool.py:212] Starting new HTTP connection (1): data.fixer.io
25-02-2021 08:47:44 DEBUG    [connectionpool.py:394] "GET /api/latest?access_key=34e2df461e05e5871c51b4293d8a62c8 HTTP/1.1" 200 None
25-02-2021 08:47:45 WARNING  [log.py:224] Method Not Allowed: /api/user/me/
25-02-2021 08:47:46 WARNING  [log.py:224] Bad Request: /api/user/token/
25-02-2021 08:47:46 WARNING  [log.py:224] Bad Request: /api/user/token/
25-02-2021 08:47:46 WARNING  [log.py:224] Bad Request: /api/user/token/
25-02-2021 08:47:47 WARNING  [log.py:224] Bad Request: /api/user/create/
25-02-2021 08:47:47 WARNING  [log.py:224] Unauthorized: /api/user/me/
25-02-2021 08:47:47 WARNING  [log.py:224] Bad Request: /api/user/create/
25-02-2021 08:47:47 WARNING  [log.py:224] Unauthorized: /api/product/product/
25-02-2021 08:53:51 DEBUG    [selector_events.py:59] Using selector: EpollSelector
25-02-2021 08:53:51 INFO     [connectionpool.py:212] Starting new HTTP connection (1): data.fixer.io
25-02-2021 08:53:52 DEBUG    [connectionpool.py:394] "GET /api/latest?access_key=34e2df461e05e5871c51b4293d8a62c8 HTTP/1.1" 200 None
25-02-2021 08:53:53 WARNING  [log.py:224] Method Not Allowed: /api/user/me/
25-02-2021 08:53:54 WARNING  [log.py:224] Bad Request: /api/user/token/
25-02-2021 08:53:54 WARNING  [log.py:224] Bad Request: /api/user/token/
25-02-2021 08:53:54 WARNING  [log.py:224] Bad Request: /api/user/token/
25-02-2021 08:53:54 WARNING  [log.py:224] Bad Request: /api/user/create/
25-02-2021 08:53:54 WARNING  [log.py:224] Unauthorized: /api/user/me/
25-02-2021 08:53:54 WARNING  [log.py:224] Bad Request: /api/user/create/
25-02-2021 08:53:55 WARNING  [log.py:224] Unauthorized: /api/product/product/
25-02-2021 08:54:20 DEBUG    [selector_events.py:59] Using selector: EpollSelector
25-02-2021 08:54:20 INFO     [connectionpool.py:212] Starting new HTTP connection (1): data.fixer.io
25-02-2021 08:54:20 DEBUG    [connectionpool.py:394] "GET /api/latest?access_key=34e2df461e05e5871c51b4293d8a62c8 HTTP/1.1" 200 None
25-02-2021 08:54:22 WARNING  [log.py:224] Method Not Allowed: /api/user/me/
25-02-2021 08:54:23 WARNING  [log.py:224] Bad Request: /api/user/token/
25-02-2021 08:54:23 WARNING  [log.py:224] Bad Request: /api/user/token/
25-02-2021 08:54:23 WARNING  [log.py:224] Bad Request: /api/user/token/
25-02-2021 08:54:23 WARNING  [log.py:224] Bad Request: /api/user/create/
25-02-2021 08:54:23 WARNING  [log.py:224] Unauthorized: /api/user/me/
25-02-2021 08:54:23 WARNING  [log.py:224] Bad Request: /api/user/create/
25-02-2021 08:54:24 WARNING  [log.py:224] Unauthorized: /api/product/product/
25-02-2021 08:54:53 DEBUG    [selector_events.py:59] Using selector: EpollSelector
25-02-2021 08:54:53 INFO     [connectionpool.py:212] Starting new HTTP connection (1): data.fixer.io
25-02-2021 08:54:53 DEBUG    [connectionpool.py:394] "GET /api/latest?access_key=34e2df461e05e5871c51b4293d8a62c8 HTTP/1.1" 200 None
25-02-2021 08:54:55 WARNING  [log.py:224] Method Not Allowed: /api/user/me/
25-02-2021 08:54:56 WARNING  [log.py:224] Bad Request: /api/user/token/
25-02-2021 08:54:56 WARNING  [log.py:224] Bad Request: /api/user/token/
25-02-2021 08:54:56 WARNING  [log.py:224] Bad Request: /api/user/token/
25-02-2021 08:54:56 WARNING  [log.py:224] Bad Request: /api/user/create/
25-02-2021 08:54:56 WARNING  [log.py:224] Unauthorized: /api/user/me/
25-02-2021 08:54:56 WARNING  [log.py:224] Bad Request: /api/user/create/
25-02-2021 08:54:56 WARNING  [log.py:224] Unauthorized: /api/product/product/
25-02-2021 08:55:34 DEBUG    [selector_events.py:59] Using selector: EpollSelector
25-02-2021 08:55:34 INFO     [connectionpool.py:212] Starting new HTTP connection (1): data.fixer.io
25-02-2021 08:55:34 DEBUG    [connectionpool.py:394] "GET /api/latest?access_key=34e2df461e05e5871c51b4293d8a62c8 HTTP/1.1" 200 None
25-02-2021 08:55:36 WARNING  [log.py:224] Method Not Allowed: /api/user/me/
25-02-2021 08:55:37 WARNING  [log.py:224] Bad Request: /api/user/token/
25-02-2021 08:55:37 WARNING  [log.py:224] Bad Request: /api/user/token/
25-02-2021 08:55:37 WARNING  [log.py:224] Bad Request: /api/user/token/
25-02-2021 08:55:37 WARNING  [log.py:224] Bad Request: /api/user/create/
25-02-2021 08:55:37 WARNING  [log.py:224] Unauthorized: /api/user/me/
25-02-2021 08:55:37 WARNING  [log.py:224] Bad Request: /api/user/create/
25-02-2021 08:55:37 WARNING  [log.py:224] Unauthorized: /api/product/product/
25-02-2021 08:59:35 DEBUG    [selector_events.py:59] Using selector: EpollSelector
25-02-2021 08:59:35 INFO     [connectionpool.py:212] Starting new HTTP connection (1): data.fixer.io
25-02-2021 08:59:35 DEBUG    [connectionpool.py:394] "GET /api/latest?access_key=34e2df461e05e5871c51b4293d8a62c8 HTTP/1.1" 200 None
25-02-2021 08:59:37 WARNING  [log.py:224] Method Not Allowed: /api/user/me/
25-02-2021 08:59:37 WARNING  [log.py:224] Bad Request: /api/user/token/
25-02-2021 08:59:37 WARNING  [log.py:224] Bad Request: /api/user/token/
25-02-2021 08:59:38 WARNING  [log.py:224] Bad Request: /api/user/token/
25-02-2021 08:59:38 WARNING  [log.py:224] Bad Request: /api/user/create/
25-02-2021 08:59:38 WARNING  [log.py:224] Unauthorized: /api/user/me/
25-02-2021 08:59:38 WARNING  [log.py:224] Bad Request: /api/user/create/
25-02-2021 08:59:38 WARNING  [log.py:224] Unauthorized: /api/product/product/
25-02-2021 08:59:52 DEBUG    [selector_events.py:59] Using selector: EpollSelector
25-02-2021 08:59:52 INFO     [connectionpool.py:212] Starting new HTTP connection (1): data.fixer.io
25-02-2021 08:59:52 DEBUG    [connectionpool.py:394] "GET /api/latest?access_key=34e2df461e05e5871c51b4293d8a62c8 HTTP/1.1" 200 None
25-02-2021 08:59:54 WARNING  [log.py:224] Method Not Allowed: /api/user/me/
25-02-2021 08:59:55 WARNING  [log.py:224] Bad Request: /api/user/token/
25-02-2021 08:59:55 WARNING  [log.py:224] Bad Request: /api/user/token/
25-02-2021 08:59:55 WARNING  [log.py:224] Bad Request: /api/user/token/
25-02-2021 08:59:55 WARNING  [log.py:224] Bad Request: /api/user/create/
25-02-2021 08:59:55 WARNING  [log.py:224] Unauthorized: /api/user/me/
25-02-2021 08:59:55 WARNING  [log.py:224] Bad Request: /api/user/create/
25-02-2021 08:59:55 WARNING  [log.py:224] Unauthorized: /api/product/product/
25-02-2021 09:00:41 DEBUG    [selector_events.py:59] Using selector: EpollSelector
25-02-2021 09:00:41 INFO     [connectionpool.py:212] Starting new HTTP connection (1): data.fixer.io
25-02-2021 09:00:41 DEBUG    [connectionpool.py:394] "GET /api/latest?access_key=34e2df461e05e5871c51b4293d8a62c8 HTTP/1.1" 200 None
25-02-2021 09:00:43 WARNING  [log.py:224] Method Not Allowed: /api/user/me/
25-02-2021 09:00:44 WARNING  [log.py:224] Bad Request: /api/user/token/
25-02-2021 09:00:44 WARNING  [log.py:224] Bad Request: /api/user/token/
25-02-2021 09:00:44 WARNING  [log.py:224] Bad Request: /api/user/token/
25-02-2021 09:00:44 WARNING  [log.py:224] Bad Request: /api/user/create/
25-02-2021 09:00:44 WARNING  [log.py:224] Unauthorized: /api/user/me/
25-02-2021 09:00:44 WARNING  [log.py:224] Bad Request: /api/user/create/
25-02-2021 09:00:44 WARNING  [log.py:224] Unauthorized: /api/product/product/
25-02-2021 09:01:57 DEBUG    [selector_events.py:59] Using selector: EpollSelector
25-02-2021 09:01:57 INFO     [connectionpool.py:212] Starting new HTTP connection (1): data.fixer.io
25-02-2021 09:01:58 DEBUG    [connectionpool.py:394] "GET /api/latest?access_key=34e2df461e05e5871c51b4293d8a62c8 HTTP/1.1" 200 None
25-02-2021 09:01:59 WARNING  [log.py:224] Method Not Allowed: /api/user/me/
25-02-2021 09:02:00 WARNING  [log.py:224] Bad Request: /api/user/token/
25-02-2021 09:02:00 WARNING  [log.py:224] Bad Request: /api/user/token/
25-02-2021 09:02:00 WARNING  [log.py:224] Bad Request: /api/user/token/
25-02-2021 09:02:01 WARNING  [log.py:224] Bad Request: /api/user/create/
25-02-2021 09:02:01 WARNING  [log.py:224] Unauthorized: /api/user/me/
25-02-2021 09:02:01 WARNING  [log.py:224] Bad Request: /api/user/create/
25-02-2021 09:02:01 WARNING  [log.py:224] Unauthorized: /api/product/product/
25-02-2021 09:02:13 DEBUG    [selector_events.py:59] Using selector: EpollSelector
25-02-2021 09:02:13 INFO     [connectionpool.py:212] Starting new HTTP connection (1): data.fixer.io
25-02-2021 09:02:14 DEBUG    [connectionpool.py:394] "GET /api/latest?access_key=34e2df461e05e5871c51b4293d8a62c8 HTTP/1.1" 200 None
25-02-2021 09:02:15 WARNING  [log.py:224] Method Not Allowed: /api/user/me/
25-02-2021 09:02:16 WARNING  [log.py:224] Bad Request: /api/user/token/
25-02-2021 09:02:16 WARNING  [log.py:224] Bad Request: /api/user/token/
25-02-2021 09:02:16 WARNING  [log.py:224] Bad Request: /api/user/token/
25-02-2021 09:02:16 WARNING  [log.py:224] Bad Request: /api/user/create/
25-02-2021 09:02:16 WARNING  [log.py:224] Unauthorized: /api/user/me/
25-02-2021 09:02:17 WARNING  [log.py:224] Bad Request: /api/user/create/
25-02-2021 09:02:17 WARNING  [log.py:224] Unauthorized: /api/product/product/
25-02-2021 09:02:22 DEBUG    [selector_events.py:59] Using selector: EpollSelector
25-02-2021 09:02:22 INFO     [connectionpool.py:212] Starting new HTTP connection (1): data.fixer.io
25-02-2021 09:02:23 DEBUG    [connectionpool.py:394] "GET /api/latest?access_key=34e2df461e05e5871c51b4293d8a62c8 HTTP/1.1" 200 None
25-02-2021 09:02:24 WARNING  [log.py:224] Method Not Allowed: /api/user/me/
25-02-2021 09:02:25 WARNING  [log.py:224] Bad Request: /api/user/token/
25-02-2021 09:02:25 WARNING  [log.py:224] Bad Request: /api/user/token/
25-02-2021 09:02:25 WARNING  [log.py:224] Bad Request: /api/user/token/
25-02-2021 09:02:26 WARNING  [log.py:224] Bad Request: /api/user/create/
25-02-2021 09:02:26 WARNING  [log.py:224] Unauthorized: /api/user/me/
25-02-2021 09:02:26 WARNING  [log.py:224] Bad Request: /api/user/create/
25-02-2021 09:02:26 WARNING  [log.py:224] Unauthorized: /api/product/product/
25-02-2021 09:02:31 DEBUG    [selector_events.py:59] Using selector: EpollSelector
25-02-2021 09:02:32 INFO     [connectionpool.py:212] Starting new HTTP connection (1): data.fixer.io
25-02-2021 09:02:32 DEBUG    [connectionpool.py:394] "GET /api/latest?access_key=34e2df461e05e5871c51b4293d8a62c8 HTTP/1.1" 200 None
25-02-2021 09:02:33 WARNING  [log.py:224] Method Not Allowed: /api/user/me/
25-02-2021 09:02:34 WARNING  [log.py:224] Bad Request: /api/user/token/
25-02-2021 09:02:34 WARNING  [log.py:224] Bad Request: /api/user/token/
25-02-2021 09:02:34 WARNING  [log.py:224] Bad Request: /api/user/token/
25-02-2021 09:02:35 WARNING  [log.py:224] Bad Request: /api/user/create/
25-02-2021 09:02:35 WARNING  [log.py:224] Unauthorized: /api/user/me/
25-02-2021 09:02:35 WARNING  [log.py:224] Bad Request: /api/user/create/
25-02-2021 09:02:35 WARNING  [log.py:224] Unauthorized: /api/product/product/
25-02-2021 09:13:22 DEBUG    [selector_events.py:59] Using selector: EpollSelector
25-02-2021 09:13:22 INFO     [connectionpool.py:212] Starting new HTTP connection (1): data.fixer.io
25-02-2021 09:13:22 DEBUG    [connectionpool.py:394] "GET /api/latest?access_key=34e2df461e05e5871c51b4293d8a62c8 HTTP/1.1" 200 None
25-02-2021 09:13:24 WARNING  [log.py:224] Method Not Allowed: /api/user/me/
25-02-2021 09:13:25 WARNING  [log.py:224] Bad Request: /api/user/token/
25-02-2021 09:13:25 WARNING  [log.py:224] Bad Request: /api/user/token/
25-02-2021 09:13:25 WARNING  [log.py:224] Bad Request: /api/user/token/
25-02-2021 09:13:25 WARNING  [log.py:224] Bad Request: /api/user/create/
25-02-2021 09:13:25 WARNING  [log.py:224] Unauthorized: /api/user/me/
25-02-2021 09:13:25 WARNING  [log.py:224] Bad Request: /api/user/create/
25-02-2021 09:13:25 WARNING  [log.py:224] Unauthorized: /api/product/product/
25-02-2021 09:13:33 DEBUG    [selector_events.py:59] Using selector: EpollSelector
25-02-2021 09:13:33 INFO     [connectionpool.py:212] Starting new HTTP connection (1): data.fixer.io
25-02-2021 09:13:34 DEBUG    [connectionpool.py:394] "GET /api/latest?access_key=34e2df461e05e5871c51b4293d8a62c8 HTTP/1.1" 200 None
25-02-2021 09:13:35 WARNING  [log.py:224] Method Not Allowed: /api/user/me/
25-02-2021 09:13:36 WARNING  [log.py:224] Bad Request: /api/user/token/
25-02-2021 09:13:36 WARNING  [log.py:224] Bad Request: /api/user/token/
25-02-2021 09:13:36 WARNING  [log.py:224] Bad Request: /api/user/token/
25-02-2021 09:13:36 WARNING  [log.py:224] Bad Request: /api/user/create/
25-02-2021 09:13:36 WARNING  [log.py:224] Unauthorized: /api/user/me/
25-02-2021 09:13:37 WARNING  [log.py:224] Bad Request: /api/user/create/
25-02-2021 09:13:37 WARNING  [log.py:224] Unauthorized: /api/product/product/
25-02-2021 09:14:05 DEBUG    [selector_events.py:59] Using selector: EpollSelector
25-02-2021 09:14:05 INFO     [connectionpool.py:212] Starting new HTTP connection (1): data.fixer.io
25-02-2021 09:14:05 DEBUG    [connectionpool.py:394] "GET /api/latest?access_key=34e2df461e05e5871c51b4293d8a62c8 HTTP/1.1" 200 None
25-02-2021 09:14:07 WARNING  [log.py:224] Method Not Allowed: /api/user/me/
25-02-2021 09:14:08 WARNING  [log.py:224] Bad Request: /api/user/token/
25-02-2021 09:14:08 WARNING  [log.py:224] Bad Request: /api/user/token/
25-02-2021 09:14:08 WARNING  [log.py:224] Bad Request: /api/user/token/
25-02-2021 09:14:08 WARNING  [log.py:224] Bad Request: /api/user/create/
25-02-2021 09:14:08 WARNING  [log.py:224] Unauthorized: /api/user/me/
25-02-2021 09:14:08 WARNING  [log.py:224] Bad Request: /api/user/create/
25-02-2021 09:14:08 WARNING  [log.py:224] Unauthorized: /api/product/product/
25-02-2021 09:14:28 DEBUG    [selector_events.py:59] Using selector: EpollSelector
25-02-2021 09:14:28 INFO     [connectionpool.py:212] Starting new HTTP connection (1): data.fixer.io
25-02-2021 09:14:28 DEBUG    [connectionpool.py:394] "GET /api/latest?access_key=34e2df461e05e5871c51b4293d8a62c8 HTTP/1.1" 200 None
25-02-2021 09:14:30 WARNING  [log.py:224] Method Not Allowed: /api/user/me/
25-02-2021 09:14:31 WARNING  [log.py:224] Bad Request: /api/user/token/
25-02-2021 09:14:31 WARNING  [log.py:224] Bad Request: /api/user/token/
25-02-2021 09:14:31 WARNING  [log.py:224] Bad Request: /api/user/token/
25-02-2021 09:14:31 WARNING  [log.py:224] Bad Request: /api/user/create/
25-02-2021 09:14:31 WARNING  [log.py:224] Unauthorized: /api/user/me/
25-02-2021 09:14:31 WARNING  [log.py:224] Bad Request: /api/user/create/
25-02-2021 09:14:32 WARNING  [log.py:224] Unauthorized: /api/product/product/
25-02-2021 09:55:36 INFO     [autoreload.py:617] Watching for file changes with StatReloader
25-02-2021 09:55:44 DEBUG    [core.py:163] Successfully imported extension module "markdown.extensions.toc".
25-02-2021 09:55:44 DEBUG    [core.py:126] Successfully loaded extension "markdown.extensions.toc.TocExtension".
25-02-2021 09:55:45 DEBUG    [core.py:163] Successfully imported extension module "markdown.extensions.toc".
25-02-2021 09:55:45 DEBUG    [core.py:126] Successfully loaded extension "markdown.extensions.toc.TocExtension".
25-02-2021 09:55:50 DEBUG    [core.py:163] Successfully imported extension module "markdown.extensions.toc".
25-02-2021 09:55:50 DEBUG    [core.py:126] Successfully loaded extension "markdown.extensions.toc.TocExtension".
25-02-2021 09:57:39 DEBUG    [selector_events.py:59] Using selector: EpollSelector
25-02-2021 09:57:39 DEBUG    [selector_events.py:59] Using selector: EpollSelector
25-02-2021 09:57:40 DEBUG    [selector_events.py:59] Using selector: EpollSelector
25-02-2021 09:57:41 INFO     [connectionpool.py:212] Starting new HTTP connection (1): data.fixer.io
25-02-2021 09:57:41 DEBUG    [connectionpool.py:394] "GET /api/latest?access_key=34e2df461e05e5871c51b4293d8a62c8 HTTP/1.1" 200 None
25-02-2021 09:57:43 WARNING  [log.py:224] Method Not Allowed: /api/user/me/
25-02-2021 09:57:43 WARNING  [log.py:224] Bad Request: /api/user/token/
25-02-2021 09:57:43 WARNING  [log.py:224] Bad Request: /api/user/token/
25-02-2021 09:57:44 WARNING  [log.py:224] Bad Request: /api/user/token/
25-02-2021 09:57:44 WARNING  [log.py:224] Bad Request: /api/user/create/
25-02-2021 09:57:44 WARNING  [log.py:224] Unauthorized: /api/user/me/
25-02-2021 09:57:44 WARNING  [log.py:224] Bad Request: /api/user/create/
25-02-2021 09:57:44 WARNING  [log.py:224] Not Found: /api/product/product//1/
25-02-2021 09:57:44 WARNING  [log.py:224] Unauthorized: /api/product/product/
25-02-2021 09:58:14 DEBUG    [selector_events.py:59] Using selector: EpollSelector
25-02-2021 09:58:14 INFO     [connectionpool.py:212] Starting new HTTP connection (1): data.fixer.io
25-02-2021 09:58:14 DEBUG    [connectionpool.py:394] "GET /api/latest?access_key=34e2df461e05e5871c51b4293d8a62c8 HTTP/1.1" 200 None
25-02-2021 09:58:16 WARNING  [log.py:224] Method Not Allowed: /api/user/me/
25-02-2021 09:58:16 WARNING  [log.py:224] Bad Request: /api/user/token/
25-02-2021 09:58:16 WARNING  [log.py:224] Bad Request: /api/user/token/
25-02-2021 09:58:17 WARNING  [log.py:224] Bad Request: /api/user/token/
25-02-2021 09:58:17 WARNING  [log.py:224] Bad Request: /api/user/create/
25-02-2021 09:58:17 WARNING  [log.py:224] Unauthorized: /api/user/me/
25-02-2021 09:58:17 WARNING  [log.py:224] Bad Request: /api/user/create/
25-02-2021 09:58:17 WARNING  [log.py:224] Method Not Allowed: /api/product/product/
25-02-2021 09:58:17 WARNING  [log.py:224] Too Many Requests: /api/product/product/
25-02-2021 09:58:17 WARNING  [log.py:224] Unauthorized: /api/product/product/
25-02-2021 09:58:48 DEBUG    [selector_events.py:59] Using selector: EpollSelector
25-02-2021 09:58:48 INFO     [connectionpool.py:212] Starting new HTTP connection (1): data.fixer.io
25-02-2021 09:58:49 DEBUG    [connectionpool.py:394] "GET /api/latest?access_key=34e2df461e05e5871c51b4293d8a62c8 HTTP/1.1" 200 None
25-02-2021 09:58:50 WARNING  [log.py:224] Method Not Allowed: /api/user/me/
25-02-2021 09:58:51 WARNING  [log.py:224] Bad Request: /api/user/token/
25-02-2021 09:58:51 WARNING  [log.py:224] Bad Request: /api/user/token/
25-02-2021 09:58:51 WARNING  [log.py:224] Bad Request: /api/user/token/
25-02-2021 09:58:51 WARNING  [log.py:224] Bad Request: /api/user/create/
25-02-2021 09:58:51 WARNING  [log.py:224] Unauthorized: /api/user/me/
25-02-2021 09:58:51 WARNING  [log.py:224] Bad Request: /api/user/create/
25-02-2021 09:58:52 WARNING  [log.py:224] Unauthorized: /api/product/product/
25-02-2021 09:59:12 DEBUG    [selector_events.py:59] Using selector: EpollSelector
25-02-2021 09:59:13 INFO     [connectionpool.py:212] Starting new HTTP connection (1): data.fixer.io
25-02-2021 09:59:13 DEBUG    [connectionpool.py:394] "GET /api/latest?access_key=34e2df461e05e5871c51b4293d8a62c8 HTTP/1.1" 200 None
25-02-2021 09:59:14 WARNING  [log.py:224] Method Not Allowed: /api/user/me/
25-02-2021 09:59:15 WARNING  [log.py:224] Bad Request: /api/user/token/
25-02-2021 09:59:15 WARNING  [log.py:224] Bad Request: /api/user/token/
25-02-2021 09:59:15 WARNING  [log.py:224] Bad Request: /api/user/token/
25-02-2021 09:59:16 WARNING  [log.py:224] Bad Request: /api/user/create/
25-02-2021 09:59:16 WARNING  [log.py:224] Unauthorized: /api/user/me/
25-02-2021 09:59:16 WARNING  [log.py:224] Bad Request: /api/user/create/
25-02-2021 09:59:16 WARNING  [log.py:224] Method Not Allowed: /api/product/product/
25-02-2021 09:59:16 WARNING  [log.py:224] Too Many Requests: /api/product/product/
25-02-2021 09:59:16 WARNING  [log.py:224] Unauthorized: /api/product/product/
25-02-2021 09:59:46 DEBUG    [selector_events.py:59] Using selector: EpollSelector
25-02-2021 09:59:46 INFO     [connectionpool.py:212] Starting new HTTP connection (1): data.fixer.io
25-02-2021 09:59:46 DEBUG    [connectionpool.py:394] "GET /api/latest?access_key=34e2df461e05e5871c51b4293d8a62c8 HTTP/1.1" 200 None
25-02-2021 09:59:48 WARNING  [log.py:224] Method Not Allowed: /api/user/me/
25-02-2021 09:59:49 WARNING  [log.py:224] Bad Request: /api/user/token/
25-02-2021 09:59:49 WARNING  [log.py:224] Bad Request: /api/user/token/
25-02-2021 09:59:49 WARNING  [log.py:224] Bad Request: /api/user/token/
25-02-2021 09:59:49 WARNING  [log.py:224] Bad Request: /api/user/create/
25-02-2021 09:59:49 WARNING  [log.py:224] Unauthorized: /api/user/me/
25-02-2021 09:59:49 WARNING  [log.py:224] Bad Request: /api/user/create/
25-02-2021 09:59:49 WARNING  [log.py:224] Method Not Allowed: /api/product/product/
25-02-2021 09:59:50 WARNING  [log.py:224] Too Many Requests: /api/product/product/
25-02-2021 09:59:50 WARNING  [log.py:224] Unauthorized: /api/product/product/
25-02-2021 10:00:05 DEBUG    [selector_events.py:59] Using selector: EpollSelector
25-02-2021 10:00:05 INFO     [connectionpool.py:212] Starting new HTTP connection (1): data.fixer.io
25-02-2021 10:00:06 DEBUG    [connectionpool.py:394] "GET /api/latest?access_key=34e2df461e05e5871c51b4293d8a62c8 HTTP/1.1" 200 None
25-02-2021 10:00:07 WARNING  [log.py:224] Method Not Allowed: /api/user/me/
25-02-2021 10:00:08 WARNING  [log.py:224] Bad Request: /api/user/token/
25-02-2021 10:00:08 WARNING  [log.py:224] Bad Request: /api/user/token/
25-02-2021 10:00:08 WARNING  [log.py:224] Bad Request: /api/user/token/
25-02-2021 10:00:09 WARNING  [log.py:224] Bad Request: /api/user/create/
25-02-2021 10:00:09 WARNING  [log.py:224] Unauthorized: /api/user/me/
25-02-2021 10:00:09 WARNING  [log.py:224] Bad Request: /api/user/create/
25-02-2021 10:00:09 WARNING  [log.py:224] Method Not Allowed: /api/product/product/
25-02-2021 10:00:09 WARNING  [log.py:224] Too Many Requests: /api/product/product/
25-02-2021 10:00:09 WARNING  [log.py:224] Unauthorized: /api/product/product/
25-02-2021 10:01:06 DEBUG    [selector_events.py:59] Using selector: EpollSelector
25-02-2021 10:01:06 INFO     [connectionpool.py:212] Starting new HTTP connection (1): data.fixer.io
25-02-2021 10:01:06 DEBUG    [connectionpool.py:394] "GET /api/latest?access_key=34e2df461e05e5871c51b4293d8a62c8 HTTP/1.1" 200 None
25-02-2021 10:01:08 WARNING  [log.py:224] Method Not Allowed: /api/user/me/
25-02-2021 10:01:09 WARNING  [log.py:224] Bad Request: /api/user/token/
25-02-2021 10:01:09 WARNING  [log.py:224] Bad Request: /api/user/token/
25-02-2021 10:01:09 WARNING  [log.py:224] Bad Request: /api/user/token/
25-02-2021 10:01:09 WARNING  [log.py:224] Bad Request: /api/user/create/
25-02-2021 10:01:09 WARNING  [log.py:224] Unauthorized: /api/user/me/
25-02-2021 10:01:09 WARNING  [log.py:224] Bad Request: /api/user/create/
25-02-2021 10:01:10 WARNING  [log.py:224] Unauthorized: /api/product/product/
25-02-2021 10:01:14 DEBUG    [selector_events.py:59] Using selector: EpollSelector
25-02-2021 10:01:14 INFO     [connectionpool.py:212] Starting new HTTP connection (1): data.fixer.io
25-02-2021 10:01:14 DEBUG    [connectionpool.py:394] "GET /api/latest?access_key=34e2df461e05e5871c51b4293d8a62c8 HTTP/1.1" 200 None
25-02-2021 10:01:16 WARNING  [log.py:224] Method Not Allowed: /api/user/me/
25-02-2021 10:01:16 WARNING  [log.py:224] Bad Request: /api/user/token/
25-02-2021 10:01:16 WARNING  [log.py:224] Bad Request: /api/user/token/
25-02-2021 10:01:17 WARNING  [log.py:224] Bad Request: /api/user/token/
25-02-2021 10:01:17 WARNING  [log.py:224] Bad Request: /api/user/create/
25-02-2021 10:01:17 WARNING  [log.py:224] Unauthorized: /api/user/me/
25-02-2021 10:01:17 WARNING  [log.py:224] Bad Request: /api/user/create/
25-02-2021 10:01:17 WARNING  [log.py:224] Method Not Allowed: /api/product/product/
25-02-2021 10:01:17 WARNING  [log.py:224] Too Many Requests: /api/product/product/
25-02-2021 10:01:17 WARNING  [log.py:224] Unauthorized: /api/product/product/
25-02-2021 10:01:41 DEBUG    [selector_events.py:59] Using selector: EpollSelector
25-02-2021 10:01:41 INFO     [connectionpool.py:212] Starting new HTTP connection (1): data.fixer.io
25-02-2021 10:01:42 DEBUG    [connectionpool.py:394] "GET /api/latest?access_key=34e2df461e05e5871c51b4293d8a62c8 HTTP/1.1" 200 None
25-02-2021 10:01:43 WARNING  [log.py:224] Method Not Allowed: /api/user/me/
25-02-2021 10:01:44 WARNING  [log.py:224] Bad Request: /api/user/token/
25-02-2021 10:01:44 WARNING  [log.py:224] Bad Request: /api/user/token/
25-02-2021 10:01:44 WARNING  [log.py:224] Bad Request: /api/user/token/
25-02-2021 10:01:44 WARNING  [log.py:224] Bad Request: /api/user/create/
25-02-2021 10:01:44 WARNING  [log.py:224] Unauthorized: /api/user/me/
25-02-2021 10:01:44 WARNING  [log.py:224] Bad Request: /api/user/create/
25-02-2021 10:01:45 WARNING  [log.py:224] Method Not Allowed: /api/product/product/
25-02-2021 10:01:45 WARNING  [log.py:224] Too Many Requests: /api/product/product/
25-02-2021 10:01:45 WARNING  [log.py:224] Unauthorized: /api/product/product/
25-02-2021 10:02:06 DEBUG    [selector_events.py:59] Using selector: EpollSelector
25-02-2021 10:02:06 INFO     [connectionpool.py:212] Starting new HTTP connection (1): data.fixer.io
25-02-2021 10:02:06 DEBUG    [connectionpool.py:394] "GET /api/latest?access_key=34e2df461e05e5871c51b4293d8a62c8 HTTP/1.1" 200 None
25-02-2021 10:02:08 WARNING  [log.py:224] Method Not Allowed: /api/user/me/
25-02-2021 10:02:09 WARNING  [log.py:224] Bad Request: /api/user/token/
25-02-2021 10:02:09 WARNING  [log.py:224] Bad Request: /api/user/token/
25-02-2021 10:02:09 WARNING  [log.py:224] Bad Request: /api/user/token/
25-02-2021 10:02:09 WARNING  [log.py:224] Bad Request: /api/user/create/
25-02-2021 10:02:09 WARNING  [log.py:224] Unauthorized: /api/user/me/
25-02-2021 10:02:09 WARNING  [log.py:224] Bad Request: /api/user/create/
25-02-2021 10:02:09 WARNING  [log.py:224] Method Not Allowed: /api/product/product/
25-02-2021 10:02:09 WARNING  [log.py:224] Too Many Requests: /api/product/product/
25-02-2021 10:02:09 WARNING  [log.py:224] Unauthorized: /api/product/product/
25-02-2021 10:03:07 DEBUG    [selector_events.py:59] Using selector: EpollSelector
25-02-2021 10:03:07 INFO     [connectionpool.py:212] Starting new HTTP connection (1): data.fixer.io
25-02-2021 10:03:07 DEBUG    [connectionpool.py:394] "GET /api/latest?access_key=34e2df461e05e5871c51b4293d8a62c8 HTTP/1.1" 200 None
25-02-2021 10:03:09 WARNING  [log.py:224] Method Not Allowed: /api/user/me/
25-02-2021 10:03:10 WARNING  [log.py:224] Bad Request: /api/user/token/
25-02-2021 10:03:10 WARNING  [log.py:224] Bad Request: /api/user/token/
25-02-2021 10:03:10 WARNING  [log.py:224] Bad Request: /api/user/token/
25-02-2021 10:03:10 WARNING  [log.py:224] Bad Request: /api/user/create/
25-02-2021 10:03:10 WARNING  [log.py:224] Unauthorized: /api/user/me/
25-02-2021 10:03:10 WARNING  [log.py:224] Bad Request: /api/user/create/
25-02-2021 10:03:10 WARNING  [log.py:224] Method Not Allowed: /api/product/product/
25-02-2021 10:03:10 WARNING  [log.py:224] Too Many Requests: /api/product/product/
25-02-2021 10:03:10 WARNING  [log.py:224] Unauthorized: /api/product/product/
25-02-2021 10:04:33 DEBUG    [selector_events.py:59] Using selector: EpollSelector
25-02-2021 10:04:33 INFO     [connectionpool.py:212] Starting new HTTP connection (1): data.fixer.io
25-02-2021 10:04:33 DEBUG    [connectionpool.py:394] "GET /api/latest?access_key=34e2df461e05e5871c51b4293d8a62c8 HTTP/1.1" 200 None
25-02-2021 10:04:35 WARNING  [log.py:224] Method Not Allowed: /api/user/me/
25-02-2021 10:04:36 WARNING  [log.py:224] Bad Request: /api/user/token/
25-02-2021 10:04:36 WARNING  [log.py:224] Bad Request: /api/user/token/
25-02-2021 10:04:36 WARNING  [log.py:224] Bad Request: /api/user/token/
25-02-2021 10:04:36 WARNING  [log.py:224] Bad Request: /api/user/create/
25-02-2021 10:04:36 WARNING  [log.py:224] Unauthorized: /api/user/me/
25-02-2021 10:04:36 WARNING  [log.py:224] Bad Request: /api/user/create/
25-02-2021 10:04:36 WARNING  [log.py:224] Method Not Allowed: /api/product/product/
25-02-2021 10:04:37 WARNING  [log.py:224] Too Many Requests: /api/product/product/
25-02-2021 10:04:37 WARNING  [log.py:224] Unauthorized: /api/product/product/
25-02-2021 10:05:01 DEBUG    [selector_events.py:59] Using selector: EpollSelector
25-02-2021 10:05:01 INFO     [connectionpool.py:212] Starting new HTTP connection (1): data.fixer.io
25-02-2021 10:05:02 DEBUG    [connectionpool.py:394] "GET /api/latest?access_key=34e2df461e05e5871c51b4293d8a62c8 HTTP/1.1" 200 None
25-02-2021 10:05:03 WARNING  [log.py:224] Method Not Allowed: /api/user/me/
25-02-2021 10:05:04 WARNING  [log.py:224] Bad Request: /api/user/token/
25-02-2021 10:05:04 WARNING  [log.py:224] Bad Request: /api/user/token/
25-02-2021 10:05:04 WARNING  [log.py:224] Bad Request: /api/user/token/
25-02-2021 10:05:04 WARNING  [log.py:224] Bad Request: /api/user/create/
25-02-2021 10:05:04 WARNING  [log.py:224] Unauthorized: /api/user/me/
25-02-2021 10:05:04 WARNING  [log.py:224] Bad Request: /api/user/create/
25-02-2021 10:05:05 WARNING  [log.py:224] Unauthorized: /api/product/product/
25-02-2021 10:10:33 DEBUG    [selector_events.py:59] Using selector: EpollSelector
25-02-2021 10:10:33 INFO     [connectionpool.py:212] Starting new HTTP connection (1): data.fixer.io
25-02-2021 10:10:34 DEBUG    [connectionpool.py:394] "GET /api/latest?access_key=34e2df461e05e5871c51b4293d8a62c8 HTTP/1.1" 200 None
25-02-2021 10:10:35 WARNING  [log.py:224] Method Not Allowed: /api/user/me/
25-02-2021 10:10:36 WARNING  [log.py:224] Bad Request: /api/user/token/
25-02-2021 10:10:36 WARNING  [log.py:224] Bad Request: /api/user/token/
25-02-2021 10:10:37 WARNING  [log.py:224] Bad Request: /api/user/token/
25-02-2021 10:10:37 WARNING  [log.py:224] Bad Request: /api/user/create/
25-02-2021 10:10:37 WARNING  [log.py:224] Unauthorized: /api/user/me/
25-02-2021 10:10:37 WARNING  [log.py:224] Bad Request: /api/user/create/
25-02-2021 10:10:37 WARNING  [log.py:224] Too Many Requests: /api/product/product/
25-02-2021 10:10:37 WARNING  [log.py:224] Unauthorized: /api/product/product/
25-02-2021 10:12:19 DEBUG    [selector_events.py:59] Using selector: EpollSelector
25-02-2021 10:12:19 INFO     [connectionpool.py:212] Starting new HTTP connection (1): data.fixer.io
25-02-2021 10:12:20 DEBUG    [connectionpool.py:394] "GET /api/latest?access_key=34e2df461e05e5871c51b4293d8a62c8 HTTP/1.1" 200 None
25-02-2021 10:12:21 WARNING  [log.py:224] Method Not Allowed: /api/user/me/
25-02-2021 10:12:22 WARNING  [log.py:224] Bad Request: /api/user/token/
25-02-2021 10:12:22 WARNING  [log.py:224] Bad Request: /api/user/token/
25-02-2021 10:12:22 WARNING  [log.py:224] Bad Request: /api/user/token/
25-02-2021 10:12:23 WARNING  [log.py:224] Bad Request: /api/user/create/
25-02-2021 10:12:23 WARNING  [log.py:224] Unauthorized: /api/user/me/
25-02-2021 10:12:23 WARNING  [log.py:224] Bad Request: /api/user/create/
25-02-2021 10:12:23 WARNING  [log.py:224] Too Many Requests: /api/product/product/
25-02-2021 10:12:23 WARNING  [log.py:224] Unauthorized: /api/product/product/
25-02-2021 10:12:52 DEBUG    [selector_events.py:59] Using selector: EpollSelector
25-02-2021 10:12:52 INFO     [connectionpool.py:212] Starting new HTTP connection (1): data.fixer.io
25-02-2021 10:12:53 DEBUG    [connectionpool.py:394] "GET /api/latest?access_key=34e2df461e05e5871c51b4293d8a62c8 HTTP/1.1" 200 None
25-02-2021 10:12:54 WARNING  [log.py:224] Method Not Allowed: /api/user/me/
25-02-2021 10:12:55 WARNING  [log.py:224] Bad Request: /api/user/token/
25-02-2021 10:12:55 WARNING  [log.py:224] Bad Request: /api/user/token/
25-02-2021 10:12:55 WARNING  [log.py:224] Bad Request: /api/user/token/
25-02-2021 10:12:55 WARNING  [log.py:224] Bad Request: /api/user/create/
25-02-2021 10:12:55 WARNING  [log.py:224] Unauthorized: /api/user/me/
25-02-2021 10:12:56 WARNING  [log.py:224] Bad Request: /api/user/create/
25-02-2021 10:12:56 WARNING  [log.py:224] Too Many Requests: /api/product/product/
25-02-2021 10:12:56 WARNING  [log.py:224] Unauthorized: /api/product/product/
25-02-2021 10:13:35 DEBUG    [selector_events.py:59] Using selector: EpollSelector
25-02-2021 10:13:35 INFO     [connectionpool.py:212] Starting new HTTP connection (1): data.fixer.io
25-02-2021 10:13:35 DEBUG    [connectionpool.py:394] "GET /api/latest?access_key=34e2df461e05e5871c51b4293d8a62c8 HTTP/1.1" 200 None
25-02-2021 10:13:37 WARNING  [log.py:224] Method Not Allowed: /api/user/me/
25-02-2021 10:13:38 WARNING  [log.py:224] Bad Request: /api/user/token/
25-02-2021 10:13:38 WARNING  [log.py:224] Bad Request: /api/user/token/
25-02-2021 10:13:38 WARNING  [log.py:224] Bad Request: /api/user/token/
25-02-2021 10:13:38 WARNING  [log.py:224] Bad Request: /api/user/create/
25-02-2021 10:13:38 WARNING  [log.py:224] Unauthorized: /api/user/me/
25-02-2021 10:13:38 WARNING  [log.py:224] Bad Request: /api/user/create/
25-02-2021 10:13:38 WARNING  [log.py:224] Unauthorized: /api/product/product/
25-02-2021 10:13:49 DEBUG    [selector_events.py:59] Using selector: EpollSelector
25-02-2021 10:13:49 INFO     [connectionpool.py:212] Starting new HTTP connection (1): data.fixer.io
25-02-2021 10:13:50 DEBUG    [connectionpool.py:394] "GET /api/latest?access_key=34e2df461e05e5871c51b4293d8a62c8 HTTP/1.1" 200 None
25-02-2021 10:13:51 WARNING  [log.py:224] Method Not Allowed: /api/user/me/
25-02-2021 10:13:52 WARNING  [log.py:224] Bad Request: /api/user/token/
25-02-2021 10:13:52 WARNING  [log.py:224] Bad Request: /api/user/token/
25-02-2021 10:13:52 WARNING  [log.py:224] Bad Request: /api/user/token/
25-02-2021 10:13:52 WARNING  [log.py:224] Bad Request: /api/user/create/
25-02-2021 10:13:52 WARNING  [log.py:224] Unauthorized: /api/user/me/
25-02-2021 10:13:52 WARNING  [log.py:224] Bad Request: /api/user/create/
25-02-2021 10:13:53 WARNING  [log.py:224] Unauthorized: /api/product/product/
25-02-2021 10:14:06 DEBUG    [selector_events.py:59] Using selector: EpollSelector
25-02-2021 10:14:07 INFO     [connectionpool.py:212] Starting new HTTP connection (1): data.fixer.io
25-02-2021 10:14:07 DEBUG    [connectionpool.py:394] "GET /api/latest?access_key=34e2df461e05e5871c51b4293d8a62c8 HTTP/1.1" 200 None
25-02-2021 10:14:09 WARNING  [log.py:224] Method Not Allowed: /api/user/me/
25-02-2021 10:14:09 WARNING  [log.py:224] Bad Request: /api/user/token/
25-02-2021 10:14:09 WARNING  [log.py:224] Bad Request: /api/user/token/
25-02-2021 10:14:10 WARNING  [log.py:224] Bad Request: /api/user/token/
25-02-2021 10:14:10 WARNING  [log.py:224] Bad Request: /api/user/create/
25-02-2021 10:14:10 WARNING  [log.py:224] Unauthorized: /api/user/me/
25-02-2021 10:14:10 WARNING  [log.py:224] Bad Request: /api/user/create/
25-02-2021 10:14:10 WARNING  [log.py:224] Unauthorized: /api/product/product/
25-02-2021 10:14:23 DEBUG    [selector_events.py:59] Using selector: EpollSelector
25-02-2021 10:14:24 INFO     [connectionpool.py:212] Starting new HTTP connection (1): data.fixer.io
25-02-2021 10:14:24 DEBUG    [connectionpool.py:394] "GET /api/latest?access_key=34e2df461e05e5871c51b4293d8a62c8 HTTP/1.1" 200 None
25-02-2021 10:14:25 WARNING  [log.py:224] Method Not Allowed: /api/user/me/
25-02-2021 10:14:26 WARNING  [log.py:224] Bad Request: /api/user/token/
25-02-2021 10:14:26 WARNING  [log.py:224] Bad Request: /api/user/token/
25-02-2021 10:14:27 WARNING  [log.py:224] Bad Request: /api/user/token/
25-02-2021 10:14:27 WARNING  [log.py:224] Bad Request: /api/user/create/
25-02-2021 10:14:27 WARNING  [log.py:224] Unauthorized: /api/user/me/
25-02-2021 10:14:27 WARNING  [log.py:224] Bad Request: /api/user/create/
25-02-2021 10:14:27 WARNING  [log.py:224] Unauthorized: /api/product/product/
25-02-2021 10:15:07 DEBUG    [selector_events.py:59] Using selector: EpollSelector
25-02-2021 10:15:07 INFO     [connectionpool.py:212] Starting new HTTP connection (1): data.fixer.io
25-02-2021 10:15:08 DEBUG    [connectionpool.py:394] "GET /api/latest?access_key=34e2df461e05e5871c51b4293d8a62c8 HTTP/1.1" 200 None
25-02-2021 10:15:09 WARNING  [log.py:224] Method Not Allowed: /api/user/me/
25-02-2021 10:15:10 WARNING  [log.py:224] Bad Request: /api/user/token/
25-02-2021 10:15:10 WARNING  [log.py:224] Bad Request: /api/user/token/
25-02-2021 10:15:10 WARNING  [log.py:224] Bad Request: /api/user/token/
25-02-2021 10:15:10 WARNING  [log.py:224] Bad Request: /api/user/create/
25-02-2021 10:15:10 WARNING  [log.py:224] Unauthorized: /api/user/me/
25-02-2021 10:15:11 WARNING  [log.py:224] Bad Request: /api/user/create/
25-02-2021 10:15:11 WARNING  [log.py:224] Unauthorized: /api/product/product/
25-02-2021 10:16:43 DEBUG    [selector_events.py:59] Using selector: EpollSelector
25-02-2021 10:16:43 INFO     [connectionpool.py:212] Starting new HTTP connection (1): data.fixer.io
25-02-2021 10:16:43 DEBUG    [connectionpool.py:394] "GET /api/latest?access_key=34e2df461e05e5871c51b4293d8a62c8 HTTP/1.1" 200 None
25-02-2021 10:16:45 WARNING  [log.py:224] Method Not Allowed: /api/user/me/
25-02-2021 10:16:46 WARNING  [log.py:224] Bad Request: /api/user/token/
25-02-2021 10:16:46 WARNING  [log.py:224] Bad Request: /api/user/token/
25-02-2021 10:16:46 WARNING  [log.py:224] Bad Request: /api/user/token/
25-02-2021 10:16:46 WARNING  [log.py:224] Bad Request: /api/user/create/
25-02-2021 10:16:46 WARNING  [log.py:224] Unauthorized: /api/user/me/
25-02-2021 10:16:46 WARNING  [log.py:224] Bad Request: /api/user/create/
25-02-2021 10:16:47 WARNING  [log.py:224] Too Many Requests: /api/product/product/1/
25-02-2021 10:16:47 WARNING  [log.py:224] Unauthorized: /api/product/product/
25-02-2021 10:17:02 DEBUG    [selector_events.py:59] Using selector: EpollSelector
25-02-2021 10:17:03 INFO     [connectionpool.py:212] Starting new HTTP connection (1): data.fixer.io
25-02-2021 10:17:03 DEBUG    [connectionpool.py:394] "GET /api/latest?access_key=34e2df461e05e5871c51b4293d8a62c8 HTTP/1.1" 200 None
25-02-2021 10:17:04 WARNING  [log.py:224] Method Not Allowed: /api/user/me/
25-02-2021 10:17:05 WARNING  [log.py:224] Bad Request: /api/user/token/
25-02-2021 10:17:05 WARNING  [log.py:224] Bad Request: /api/user/token/
25-02-2021 10:17:05 WARNING  [log.py:224] Bad Request: /api/user/token/
25-02-2021 10:17:06 WARNING  [log.py:224] Bad Request: /api/user/create/
25-02-2021 10:17:06 WARNING  [log.py:224] Unauthorized: /api/user/me/
25-02-2021 10:17:06 WARNING  [log.py:224] Bad Request: /api/user/create/
25-02-2021 10:17:06 WARNING  [log.py:224] Too Many Requests: /api/product/product/1/
25-02-2021 10:17:06 WARNING  [log.py:224] Unauthorized: /api/product/product/
25-02-2021 10:17:37 DEBUG    [selector_events.py:59] Using selector: EpollSelector
25-02-2021 10:17:37 INFO     [connectionpool.py:212] Starting new HTTP connection (1): data.fixer.io
25-02-2021 10:17:38 DEBUG    [connectionpool.py:394] "GET /api/latest?access_key=34e2df461e05e5871c51b4293d8a62c8 HTTP/1.1" 200 None
25-02-2021 10:17:39 WARNING  [log.py:224] Method Not Allowed: /api/user/me/
25-02-2021 10:17:40 WARNING  [log.py:224] Bad Request: /api/user/token/
25-02-2021 10:17:40 WARNING  [log.py:224] Bad Request: /api/user/token/
25-02-2021 10:17:40 WARNING  [log.py:224] Bad Request: /api/user/token/
25-02-2021 10:17:41 WARNING  [log.py:224] Bad Request: /api/user/create/
25-02-2021 10:17:41 WARNING  [log.py:224] Unauthorized: /api/user/me/
25-02-2021 10:17:41 WARNING  [log.py:224] Bad Request: /api/user/create/
25-02-2021 10:17:41 WARNING  [log.py:224] Too Many Requests: /api/product/product/1/
25-02-2021 10:17:41 WARNING  [log.py:224] Unauthorized: /api/product/product/
25-02-2021 10:18:15 DEBUG    [selector_events.py:59] Using selector: EpollSelector
25-02-2021 10:18:16 INFO     [connectionpool.py:212] Starting new HTTP connection (1): data.fixer.io
25-02-2021 10:18:16 DEBUG    [connectionpool.py:394] "GET /api/latest?access_key=34e2df461e05e5871c51b4293d8a62c8 HTTP/1.1" 200 None
25-02-2021 10:18:18 WARNING  [log.py:224] Method Not Allowed: /api/user/me/
25-02-2021 10:18:19 WARNING  [log.py:224] Bad Request: /api/user/token/
25-02-2021 10:18:19 WARNING  [log.py:224] Bad Request: /api/user/token/
25-02-2021 10:18:19 WARNING  [log.py:224] Bad Request: /api/user/token/
25-02-2021 10:18:19 WARNING  [log.py:224] Bad Request: /api/user/create/
25-02-2021 10:18:19 WARNING  [log.py:224] Unauthorized: /api/user/me/
25-02-2021 10:18:19 WARNING  [log.py:224] Bad Request: /api/user/create/
25-02-2021 10:18:20 WARNING  [log.py:224] Unauthorized: /api/product/product/
25-02-2021 10:21:10 DEBUG    [selector_events.py:59] Using selector: EpollSelector
25-02-2021 10:21:10 INFO     [connectionpool.py:212] Starting new HTTP connection (1): data.fixer.io
25-02-2021 10:21:10 DEBUG    [connectionpool.py:394] "GET /api/latest?access_key=34e2df461e05e5871c51b4293d8a62c8 HTTP/1.1" 200 None
25-02-2021 10:21:12 WARNING  [log.py:224] Method Not Allowed: /api/user/me/
25-02-2021 10:21:13 WARNING  [log.py:224] Bad Request: /api/user/token/
25-02-2021 10:21:13 WARNING  [log.py:224] Bad Request: /api/user/token/
25-02-2021 10:21:13 WARNING  [log.py:224] Bad Request: /api/user/token/
25-02-2021 10:21:13 WARNING  [log.py:224] Bad Request: /api/user/create/
25-02-2021 10:21:13 WARNING  [log.py:224] Unauthorized: /api/user/me/
25-02-2021 10:21:13 WARNING  [log.py:224] Bad Request: /api/user/create/
25-02-2021 10:21:14 WARNING  [log.py:224] Unauthorized: /api/product/product/
25-02-2021 10:21:27 DEBUG    [selector_events.py:59] Using selector: EpollSelector
25-02-2021 10:21:28 INFO     [connectionpool.py:212] Starting new HTTP connection (1): data.fixer.io
25-02-2021 10:21:28 DEBUG    [connectionpool.py:394] "GET /api/latest?access_key=34e2df461e05e5871c51b4293d8a62c8 HTTP/1.1" 200 None
25-02-2021 10:21:29 WARNING  [log.py:224] Method Not Allowed: /api/user/me/
25-02-2021 10:21:30 WARNING  [log.py:224] Bad Request: /api/user/token/
25-02-2021 10:21:30 WARNING  [log.py:224] Bad Request: /api/user/token/
25-02-2021 10:21:30 WARNING  [log.py:224] Bad Request: /api/user/token/
25-02-2021 10:21:31 WARNING  [log.py:224] Bad Request: /api/user/create/
25-02-2021 10:21:31 WARNING  [log.py:224] Unauthorized: /api/user/me/
25-02-2021 10:21:31 WARNING  [log.py:224] Bad Request: /api/user/create/
25-02-2021 10:21:31 WARNING  [log.py:224] Too Many Requests: /api/product/product/
25-02-2021 10:21:31 WARNING  [log.py:224] Unauthorized: /api/product/product/
25-02-2021 10:22:07 DEBUG    [selector_events.py:59] Using selector: EpollSelector
25-02-2021 10:22:07 INFO     [connectionpool.py:212] Starting new HTTP connection (1): data.fixer.io
25-02-2021 10:22:08 DEBUG    [connectionpool.py:394] "GET /api/latest?access_key=34e2df461e05e5871c51b4293d8a62c8 HTTP/1.1" 200 None
25-02-2021 10:22:09 WARNING  [log.py:224] Method Not Allowed: /api/user/me/
25-02-2021 10:22:10 WARNING  [log.py:224] Bad Request: /api/user/token/
25-02-2021 10:22:10 WARNING  [log.py:224] Bad Request: /api/user/token/
25-02-2021 10:22:10 WARNING  [log.py:224] Bad Request: /api/user/token/
25-02-2021 10:22:10 WARNING  [log.py:224] Bad Request: /api/user/create/
25-02-2021 10:22:10 WARNING  [log.py:224] Unauthorized: /api/user/me/
25-02-2021 10:22:11 WARNING  [log.py:224] Bad Request: /api/user/create/
25-02-2021 10:22:11 WARNING  [log.py:224] Too Many Requests: /api/product/product/
25-02-2021 10:22:11 WARNING  [log.py:224] Unauthorized: /api/product/product/
25-02-2021 10:22:38 DEBUG    [selector_events.py:59] Using selector: EpollSelector
25-02-2021 10:22:38 INFO     [connectionpool.py:212] Starting new HTTP connection (1): data.fixer.io
25-02-2021 10:22:38 DEBUG    [connectionpool.py:394] "GET /api/latest?access_key=34e2df461e05e5871c51b4293d8a62c8 HTTP/1.1" 200 None
25-02-2021 10:22:40 WARNING  [log.py:224] Method Not Allowed: /api/user/me/
25-02-2021 10:22:41 WARNING  [log.py:224] Bad Request: /api/user/token/
25-02-2021 10:22:41 WARNING  [log.py:224] Bad Request: /api/user/token/
25-02-2021 10:22:41 WARNING  [log.py:224] Bad Request: /api/user/token/
25-02-2021 10:22:41 WARNING  [log.py:224] Bad Request: /api/user/create/
25-02-2021 10:22:41 WARNING  [log.py:224] Unauthorized: /api/user/me/
25-02-2021 10:22:41 WARNING  [log.py:224] Bad Request: /api/user/create/
25-02-2021 10:22:42 WARNING  [log.py:224] Too Many Requests: /api/product/product/
25-02-2021 10:22:42 WARNING  [log.py:224] Unauthorized: /api/product/product/
25-02-2021 10:22:57 DEBUG    [selector_events.py:59] Using selector: EpollSelector
25-02-2021 10:22:57 INFO     [connectionpool.py:212] Starting new HTTP connection (1): data.fixer.io
25-02-2021 10:22:57 DEBUG    [connectionpool.py:394] "GET /api/latest?access_key=34e2df461e05e5871c51b4293d8a62c8 HTTP/1.1" 200 None
25-02-2021 10:22:59 WARNING  [log.py:224] Method Not Allowed: /api/user/me/
25-02-2021 10:23:00 WARNING  [log.py:224] Bad Request: /api/user/token/
25-02-2021 10:23:00 WARNING  [log.py:224] Bad Request: /api/user/token/
25-02-2021 10:23:00 WARNING  [log.py:224] Bad Request: /api/user/token/
25-02-2021 10:23:00 WARNING  [log.py:224] Bad Request: /api/user/create/
25-02-2021 10:23:00 WARNING  [log.py:224] Unauthorized: /api/user/me/
25-02-2021 10:23:00 WARNING  [log.py:224] Bad Request: /api/user/create/
25-02-2021 10:23:01 WARNING  [log.py:224] Unauthorized: /api/product/product/
25-02-2021 10:23:48 DEBUG    [selector_events.py:59] Using selector: EpollSelector
25-02-2021 10:23:49 INFO     [connectionpool.py:212] Starting new HTTP connection (1): data.fixer.io
25-02-2021 10:23:49 DEBUG    [connectionpool.py:394] "GET /api/latest?access_key=34e2df461e05e5871c51b4293d8a62c8 HTTP/1.1" 200 None
25-02-2021 10:23:50 WARNING  [log.py:224] Method Not Allowed: /api/user/me/
25-02-2021 10:23:51 WARNING  [log.py:224] Bad Request: /api/user/token/
25-02-2021 10:23:51 WARNING  [log.py:224] Bad Request: /api/user/token/
25-02-2021 10:23:52 WARNING  [log.py:224] Bad Request: /api/user/token/
25-02-2021 10:23:52 WARNING  [log.py:224] Bad Request: /api/user/create/
25-02-2021 10:23:52 WARNING  [log.py:224] Unauthorized: /api/user/me/
25-02-2021 10:23:52 WARNING  [log.py:224] Bad Request: /api/user/create/
25-02-2021 10:23:52 WARNING  [log.py:224] Too Many Requests: /api/product/product/1/
25-02-2021 10:23:52 WARNING  [log.py:224] Unauthorized: /api/product/product/
25-02-2021 10:24:33 DEBUG    [selector_events.py:59] Using selector: EpollSelector
25-02-2021 10:24:33 INFO     [connectionpool.py:212] Starting new HTTP connection (1): data.fixer.io
25-02-2021 10:24:34 DEBUG    [connectionpool.py:394] "GET /api/latest?access_key=34e2df461e05e5871c51b4293d8a62c8 HTTP/1.1" 200 None
25-02-2021 10:24:35 WARNING  [log.py:224] Method Not Allowed: /api/user/me/
25-02-2021 10:24:36 WARNING  [log.py:224] Bad Request: /api/user/token/
25-02-2021 10:24:36 WARNING  [log.py:224] Bad Request: /api/user/token/
25-02-2021 10:24:36 WARNING  [log.py:224] Bad Request: /api/user/token/
25-02-2021 10:24:36 WARNING  [log.py:224] Bad Request: /api/user/create/
25-02-2021 10:24:36 WARNING  [log.py:224] Unauthorized: /api/user/me/
25-02-2021 10:24:37 WARNING  [log.py:224] Bad Request: /api/user/create/
25-02-2021 10:24:37 WARNING  [log.py:224] Too Many Requests: /api/product/product/1/
25-02-2021 10:24:37 WARNING  [log.py:224] Unauthorized: /api/product/product/
25-02-2021 10:25:51 DEBUG    [selector_events.py:59] Using selector: EpollSelector
25-02-2021 10:25:52 INFO     [connectionpool.py:212] Starting new HTTP connection (1): data.fixer.io
25-02-2021 10:25:52 DEBUG    [connectionpool.py:394] "GET /api/latest?access_key=34e2df461e05e5871c51b4293d8a62c8 HTTP/1.1" 200 None
25-02-2021 10:25:54 WARNING  [log.py:224] Method Not Allowed: /api/user/me/
25-02-2021 10:25:55 WARNING  [log.py:224] Bad Request: /api/user/token/
25-02-2021 10:25:55 WARNING  [log.py:224] Bad Request: /api/user/token/
25-02-2021 10:25:55 WARNING  [log.py:224] Bad Request: /api/user/token/
25-02-2021 10:25:55 WARNING  [log.py:224] Bad Request: /api/user/create/
25-02-2021 10:25:55 WARNING  [log.py:224] Unauthorized: /api/user/me/
25-02-2021 10:25:55 WARNING  [log.py:224] Bad Request: /api/user/create/
25-02-2021 10:25:55 WARNING  [log.py:224] Unauthorized: /api/product/product/
25-02-2021 10:26:35 INFO     [autoreload.py:617] Watching for file changes with StatReloader
25-02-2021 10:26:40 DEBUG    [core.py:163] Successfully imported extension module "markdown.extensions.toc".
25-02-2021 10:26:40 DEBUG    [core.py:126] Successfully loaded extension "markdown.extensions.toc.TocExtension".
25-02-2021 10:26:42 DEBUG    [core.py:163] Successfully imported extension module "markdown.extensions.toc".
25-02-2021 10:26:42 DEBUG    [core.py:126] Successfully loaded extension "markdown.extensions.toc.TocExtension".
25-02-2021 10:26:44 DEBUG    [core.py:163] Successfully imported extension module "markdown.extensions.toc".
25-02-2021 10:26:44 DEBUG    [core.py:126] Successfully loaded extension "markdown.extensions.toc.TocExtension".
25-02-2021 10:28:16 INFO     [autoreload.py:240] /home/mohamedwahba/Desktop/DEV/Order-System/product/serializers.py changed, reloading.
25-02-2021 10:28:16 DEBUG    [selector_events.py:59] Using selector: EpollSelector
25-02-2021 10:28:16 INFO     [autoreload.py:617] Watching for file changes with StatReloader
25-02-2021 10:28:18 DEBUG    [core.py:163] Successfully imported extension module "markdown.extensions.toc".
25-02-2021 10:28:18 DEBUG    [core.py:126] Successfully loaded extension "markdown.extensions.toc.TocExtension".
25-02-2021 10:28:19 DEBUG    [core.py:163] Successfully imported extension module "markdown.extensions.toc".
25-02-2021 10:28:19 DEBUG    [core.py:126] Successfully loaded extension "markdown.extensions.toc.TocExtension".
25-02-2021 10:28:19 DEBUG    [core.py:163] Successfully imported extension module "markdown.extensions.toc".
25-02-2021 10:28:19 DEBUG    [core.py:126] Successfully loaded extension "markdown.extensions.toc.TocExtension".
25-02-2021 10:28:20 DEBUG    [core.py:163] Successfully imported extension module "markdown.extensions.toc".
25-02-2021 10:28:20 DEBUG    [core.py:126] Successfully loaded extension "markdown.extensions.toc.TocExtension".
25-02-2021 10:28:20 DEBUG    [core.py:163] Successfully imported extension module "markdown.extensions.toc".
25-02-2021 10:28:20 DEBUG    [core.py:126] Successfully loaded extension "markdown.extensions.toc.TocExtension".
25-02-2021 10:28:20 DEBUG    [core.py:163] Successfully imported extension module "markdown.extensions.toc".
25-02-2021 10:28:20 DEBUG    [core.py:126] Successfully loaded extension "markdown.extensions.toc.TocExtension".
25-02-2021 10:28:20 WARNING  [log.py:224] Too Many Requests: /api/product/order/
25-02-2021 10:28:20 DEBUG    [core.py:163] Successfully imported extension module "markdown.extensions.toc".
25-02-2021 10:28:20 DEBUG    [core.py:126] Successfully loaded extension "markdown.extensions.toc.TocExtension".
25-02-2021 10:28:20 WARNING  [log.py:224] Too Many Requests: /api/product/order/
25-02-2021 10:28:20 DEBUG    [core.py:163] Successfully imported extension module "markdown.extensions.toc".
25-02-2021 10:28:20 DEBUG    [core.py:126] Successfully loaded extension "markdown.extensions.toc.TocExtension".
25-02-2021 10:28:20 WARNING  [log.py:224] Too Many Requests: /api/product/order/
25-02-2021 10:28:24 DEBUG    [selector_events.py:59] Using selector: EpollSelector
25-02-2021 10:28:24 DEBUG    [selector_events.py:59] Using selector: EpollSelector
25-02-2021 10:28:25 INFO     [autoreload.py:617] Watching for file changes with StatReloader
25-02-2021 10:28:34 INFO     [autoreload.py:240] /home/mohamedwahba/Desktop/DEV/Order-System/product/serializers.py changed, reloading.
25-02-2021 10:28:34 DEBUG    [selector_events.py:59] Using selector: EpollSelector
25-02-2021 10:28:35 INFO     [autoreload.py:617] Watching for file changes with StatReloader
25-02-2021 10:28:36 ERROR    [log.py:224] Internal Server Error: /api/product/order/
Traceback (most recent call last):
  File "/home/mohamedwahba/Desktop/DEV/Order-System/venv/lib/python3.8/site-packages/rest_framework/fields.py", line 457, in get_attribute
    return get_attribute(instance, self.source_attrs)
  File "/home/mohamedwahba/Desktop/DEV/Order-System/venv/lib/python3.8/site-packages/rest_framework/fields.py", line 97, in get_attribute
    instance = getattr(instance, attr)
AttributeError: 'Order' object has no attribute 'all_products'

During handling of the above exception, another exception occurred:

Traceback (most recent call last):
  File "/home/mohamedwahba/Desktop/DEV/Order-System/venv/lib/python3.8/site-packages/django/core/handlers/exception.py", line 47, in inner
    response = get_response(request)
  File "/home/mohamedwahba/Desktop/DEV/Order-System/venv/lib/python3.8/site-packages/django/core/handlers/base.py", line 181, in _get_response
    response = wrapped_callback(request, *callback_args, **callback_kwargs)
  File "/home/mohamedwahba/Desktop/DEV/Order-System/venv/lib/python3.8/site-packages/django/views/decorators/csrf.py", line 54, in wrapped_view
    return view_func(*args, **kwargs)
  File "/home/mohamedwahba/Desktop/DEV/Order-System/venv/lib/python3.8/site-packages/rest_framework/viewsets.py", line 125, in view
    return self.dispatch(request, *args, **kwargs)
  File "/home/mohamedwahba/Desktop/DEV/Order-System/venv/lib/python3.8/site-packages/rest_framework/views.py", line 509, in dispatch
    response = self.handle_exception(exc)
  File "/home/mohamedwahba/Desktop/DEV/Order-System/venv/lib/python3.8/site-packages/rest_framework/views.py", line 469, in handle_exception
    self.raise_uncaught_exception(exc)
  File "/home/mohamedwahba/Desktop/DEV/Order-System/venv/lib/python3.8/site-packages/rest_framework/views.py", line 480, in raise_uncaught_exception
    raise exc
  File "/home/mohamedwahba/Desktop/DEV/Order-System/venv/lib/python3.8/site-packages/rest_framework/views.py", line 506, in dispatch
    response = handler(request, *args, **kwargs)
  File "/home/mohamedwahba/Desktop/DEV/Order-System/venv/lib/python3.8/site-packages/rest_framework/mixins.py", line 46, in list
    return Response(serializer.data)
  File "/home/mohamedwahba/Desktop/DEV/Order-System/venv/lib/python3.8/site-packages/rest_framework/serializers.py", line 745, in data
    ret = super().data
  File "/home/mohamedwahba/Desktop/DEV/Order-System/venv/lib/python3.8/site-packages/rest_framework/serializers.py", line 246, in data
    self._data = self.to_representation(self.instance)
  File "/home/mohamedwahba/Desktop/DEV/Order-System/venv/lib/python3.8/site-packages/rest_framework/serializers.py", line 663, in to_representation
    return [
  File "/home/mohamedwahba/Desktop/DEV/Order-System/venv/lib/python3.8/site-packages/rest_framework/serializers.py", line 664, in <listcomp>
    self.child.to_representation(item) for item in iterable
  File "/home/mohamedwahba/Desktop/DEV/Order-System/venv/lib/python3.8/site-packages/rest_framework/serializers.py", line 502, in to_representation
    attribute = field.get_attribute(instance)
  File "/home/mohamedwahba/Desktop/DEV/Order-System/venv/lib/python3.8/site-packages/rest_framework/fields.py", line 490, in get_attribute
    raise type(exc)(msg)
AttributeError: Got AttributeError when attempting to get a value for field `all_products` on serializer `OrderSerializer`.
The serializer field might be named incorrectly and not match any attribute or key on the `Order` instance.
Original exception text was: 'Order' object has no attribute 'all_products'.
25-02-2021 10:29:13 INFO     [autoreload.py:240] /home/mohamedwahba/Desktop/DEV/Order-System/product/serializers.py changed, reloading.
25-02-2021 10:29:13 DEBUG    [selector_events.py:59] Using selector: EpollSelector
25-02-2021 10:29:13 INFO     [autoreload.py:617] Watching for file changes with StatReloader
25-02-2021 10:29:14 DEBUG    [core.py:163] Successfully imported extension module "markdown.extensions.toc".
25-02-2021 10:29:14 DEBUG    [core.py:126] Successfully loaded extension "markdown.extensions.toc.TocExtension".
25-02-2021 10:30:07 INFO     [autoreload.py:240] /home/mohamedwahba/Desktop/DEV/Order-System/product/serializers.py changed, reloading.
25-02-2021 10:30:07 DEBUG    [selector_events.py:59] Using selector: EpollSelector
25-02-2021 10:30:07 INFO     [autoreload.py:617] Watching for file changes with StatReloader
25-02-2021 10:30:07 ERROR    [log.py:224] Internal Server Error: /api/product/order/
Traceback (most recent call last):
  File "/home/mohamedwahba/Desktop/DEV/Order-System/venv/lib/python3.8/site-packages/rest_framework/fields.py", line 457, in get_attribute
    return get_attribute(instance, self.source_attrs)
  File "/home/mohamedwahba/Desktop/DEV/Order-System/venv/lib/python3.8/site-packages/rest_framework/fields.py", line 97, in get_attribute
    instance = getattr(instance, attr)
AttributeError: 'Product' object has no attribute 'products'

During handling of the above exception, another exception occurred:

Traceback (most recent call last):
  File "/home/mohamedwahba/Desktop/DEV/Order-System/venv/lib/python3.8/site-packages/django/core/handlers/exception.py", line 47, in inner
    response = get_response(request)
  File "/home/mohamedwahba/Desktop/DEV/Order-System/venv/lib/python3.8/site-packages/django/core/handlers/base.py", line 181, in _get_response
    response = wrapped_callback(request, *callback_args, **callback_kwargs)
  File "/home/mohamedwahba/Desktop/DEV/Order-System/venv/lib/python3.8/site-packages/django/views/decorators/csrf.py", line 54, in wrapped_view
    return view_func(*args, **kwargs)
  File "/home/mohamedwahba/Desktop/DEV/Order-System/venv/lib/python3.8/site-packages/rest_framework/viewsets.py", line 125, in view
    return self.dispatch(request, *args, **kwargs)
  File "/home/mohamedwahba/Desktop/DEV/Order-System/venv/lib/python3.8/site-packages/rest_framework/views.py", line 509, in dispatch
    response = self.handle_exception(exc)
  File "/home/mohamedwahba/Desktop/DEV/Order-System/venv/lib/python3.8/site-packages/rest_framework/views.py", line 469, in handle_exception
    self.raise_uncaught_exception(exc)
  File "/home/mohamedwahba/Desktop/DEV/Order-System/venv/lib/python3.8/site-packages/rest_framework/views.py", line 480, in raise_uncaught_exception
    raise exc
  File "/home/mohamedwahba/Desktop/DEV/Order-System/venv/lib/python3.8/site-packages/rest_framework/views.py", line 506, in dispatch
    response = handler(request, *args, **kwargs)
  File "/home/mohamedwahba/Desktop/DEV/Order-System/venv/lib/python3.8/site-packages/rest_framework/mixins.py", line 46, in list
    return Response(serializer.data)
  File "/home/mohamedwahba/Desktop/DEV/Order-System/venv/lib/python3.8/site-packages/rest_framework/serializers.py", line 745, in data
    ret = super().data
  File "/home/mohamedwahba/Desktop/DEV/Order-System/venv/lib/python3.8/site-packages/rest_framework/serializers.py", line 246, in data
    self._data = self.to_representation(self.instance)
  File "/home/mohamedwahba/Desktop/DEV/Order-System/venv/lib/python3.8/site-packages/rest_framework/serializers.py", line 663, in to_representation
    return [
  File "/home/mohamedwahba/Desktop/DEV/Order-System/venv/lib/python3.8/site-packages/rest_framework/serializers.py", line 664, in <listcomp>
    self.child.to_representation(item) for item in iterable
  File "/home/mohamedwahba/Desktop/DEV/Order-System/venv/lib/python3.8/site-packages/rest_framework/serializers.py", line 515, in to_representation
    ret[field.field_name] = field.to_representation(attribute)
  File "/home/mohamedwahba/Desktop/DEV/Order-System/venv/lib/python3.8/site-packages/rest_framework/serializers.py", line 663, in to_representation
    return [
  File "/home/mohamedwahba/Desktop/DEV/Order-System/venv/lib/python3.8/site-packages/rest_framework/serializers.py", line 664, in <listcomp>
    self.child.to_representation(item) for item in iterable
  File "/home/mohamedwahba/Desktop/DEV/Order-System/venv/lib/python3.8/site-packages/rest_framework/serializers.py", line 502, in to_representation
    attribute = field.get_attribute(instance)
  File "/home/mohamedwahba/Desktop/DEV/Order-System/venv/lib/python3.8/site-packages/rest_framework/fields.py", line 490, in get_attribute
    raise type(exc)(msg)
AttributeError: Got AttributeError when attempting to get a value for field `products` on serializer `CustomProductSerializer`.
The serializer field might be named incorrectly and not match any attribute or key on the `Product` instance.
Original exception text was: 'Product' object has no attribute 'products'.
25-02-2021 10:30:26 INFO     [autoreload.py:240] /home/mohamedwahba/Desktop/DEV/Order-System/product/serializers.py changed, reloading.
25-02-2021 10:30:26 DEBUG    [selector_events.py:59] Using selector: EpollSelector
25-02-2021 10:30:26 INFO     [autoreload.py:617] Watching for file changes with StatReloader
25-02-2021 10:30:26 ERROR    [log.py:224] Internal Server Error: /api/product/order/
Traceback (most recent call last):
  File "/home/mohamedwahba/Desktop/DEV/Order-System/venv/lib/python3.8/site-packages/rest_framework/fields.py", line 457, in get_attribute
    return get_attribute(instance, self.source_attrs)
  File "/home/mohamedwahba/Desktop/DEV/Order-System/venv/lib/python3.8/site-packages/rest_framework/fields.py", line 97, in get_attribute
    instance = getattr(instance, attr)
AttributeError: 'Product' object has no attribute 'products'

During handling of the above exception, another exception occurred:

Traceback (most recent call last):
  File "/home/mohamedwahba/Desktop/DEV/Order-System/venv/lib/python3.8/site-packages/django/core/handlers/exception.py", line 47, in inner
    response = get_response(request)
  File "/home/mohamedwahba/Desktop/DEV/Order-System/venv/lib/python3.8/site-packages/django/core/handlers/base.py", line 181, in _get_response
    response = wrapped_callback(request, *callback_args, **callback_kwargs)
  File "/home/mohamedwahba/Desktop/DEV/Order-System/venv/lib/python3.8/site-packages/django/views/decorators/csrf.py", line 54, in wrapped_view
    return view_func(*args, **kwargs)
  File "/home/mohamedwahba/Desktop/DEV/Order-System/venv/lib/python3.8/site-packages/rest_framework/viewsets.py", line 125, in view
    return self.dispatch(request, *args, **kwargs)
  File "/home/mohamedwahba/Desktop/DEV/Order-System/venv/lib/python3.8/site-packages/rest_framework/views.py", line 509, in dispatch
    response = self.handle_exception(exc)
  File "/home/mohamedwahba/Desktop/DEV/Order-System/venv/lib/python3.8/site-packages/rest_framework/views.py", line 469, in handle_exception
    self.raise_uncaught_exception(exc)
  File "/home/mohamedwahba/Desktop/DEV/Order-System/venv/lib/python3.8/site-packages/rest_framework/views.py", line 480, in raise_uncaught_exception
    raise exc
  File "/home/mohamedwahba/Desktop/DEV/Order-System/venv/lib/python3.8/site-packages/rest_framework/views.py", line 506, in dispatch
    response = handler(request, *args, **kwargs)
  File "/home/mohamedwahba/Desktop/DEV/Order-System/venv/lib/python3.8/site-packages/rest_framework/mixins.py", line 46, in list
    return Response(serializer.data)
  File "/home/mohamedwahba/Desktop/DEV/Order-System/venv/lib/python3.8/site-packages/rest_framework/serializers.py", line 745, in data
    ret = super().data
  File "/home/mohamedwahba/Desktop/DEV/Order-System/venv/lib/python3.8/site-packages/rest_framework/serializers.py", line 246, in data
    self._data = self.to_representation(self.instance)
  File "/home/mohamedwahba/Desktop/DEV/Order-System/venv/lib/python3.8/site-packages/rest_framework/serializers.py", line 663, in to_representation
    return [
  File "/home/mohamedwahba/Desktop/DEV/Order-System/venv/lib/python3.8/site-packages/rest_framework/serializers.py", line 664, in <listcomp>
    self.child.to_representation(item) for item in iterable
  File "/home/mohamedwahba/Desktop/DEV/Order-System/venv/lib/python3.8/site-packages/rest_framework/serializers.py", line 515, in to_representation
    ret[field.field_name] = field.to_representation(attribute)
  File "/home/mohamedwahba/Desktop/DEV/Order-System/venv/lib/python3.8/site-packages/rest_framework/serializers.py", line 663, in to_representation
    return [
  File "/home/mohamedwahba/Desktop/DEV/Order-System/venv/lib/python3.8/site-packages/rest_framework/serializers.py", line 664, in <listcomp>
    self.child.to_representation(item) for item in iterable
  File "/home/mohamedwahba/Desktop/DEV/Order-System/venv/lib/python3.8/site-packages/rest_framework/serializers.py", line 502, in to_representation
    attribute = field.get_attribute(instance)
  File "/home/mohamedwahba/Desktop/DEV/Order-System/venv/lib/python3.8/site-packages/rest_framework/fields.py", line 490, in get_attribute
    raise type(exc)(msg)
AttributeError: Got AttributeError when attempting to get a value for field `products` on serializer `CustomProductSerializer`.
The serializer field might be named incorrectly and not match any attribute or key on the `Product` instance.
Original exception text was: 'Product' object has no attribute 'products'.
25-02-2021 10:30:27 ERROR    [log.py:224] Internal Server Error: /api/product/order/
Traceback (most recent call last):
  File "/home/mohamedwahba/Desktop/DEV/Order-System/venv/lib/python3.8/site-packages/rest_framework/fields.py", line 457, in get_attribute
    return get_attribute(instance, self.source_attrs)
  File "/home/mohamedwahba/Desktop/DEV/Order-System/venv/lib/python3.8/site-packages/rest_framework/fields.py", line 97, in get_attribute
    instance = getattr(instance, attr)
AttributeError: 'Product' object has no attribute 'products'

During handling of the above exception, another exception occurred:

Traceback (most recent call last):
  File "/home/mohamedwahba/Desktop/DEV/Order-System/venv/lib/python3.8/site-packages/django/core/handlers/exception.py", line 47, in inner
    response = get_response(request)
  File "/home/mohamedwahba/Desktop/DEV/Order-System/venv/lib/python3.8/site-packages/django/core/handlers/base.py", line 181, in _get_response
    response = wrapped_callback(request, *callback_args, **callback_kwargs)
  File "/home/mohamedwahba/Desktop/DEV/Order-System/venv/lib/python3.8/site-packages/django/views/decorators/csrf.py", line 54, in wrapped_view
    return view_func(*args, **kwargs)
  File "/home/mohamedwahba/Desktop/DEV/Order-System/venv/lib/python3.8/site-packages/rest_framework/viewsets.py", line 125, in view
    return self.dispatch(request, *args, **kwargs)
  File "/home/mohamedwahba/Desktop/DEV/Order-System/venv/lib/python3.8/site-packages/rest_framework/views.py", line 509, in dispatch
    response = self.handle_exception(exc)
  File "/home/mohamedwahba/Desktop/DEV/Order-System/venv/lib/python3.8/site-packages/rest_framework/views.py", line 469, in handle_exception
    self.raise_uncaught_exception(exc)
  File "/home/mohamedwahba/Desktop/DEV/Order-System/venv/lib/python3.8/site-packages/rest_framework/views.py", line 480, in raise_uncaught_exception
    raise exc
  File "/home/mohamedwahba/Desktop/DEV/Order-System/venv/lib/python3.8/site-packages/rest_framework/views.py", line 506, in dispatch
    response = handler(request, *args, **kwargs)
  File "/home/mohamedwahba/Desktop/DEV/Order-System/venv/lib/python3.8/site-packages/rest_framework/mixins.py", line 46, in list
    return Response(serializer.data)
  File "/home/mohamedwahba/Desktop/DEV/Order-System/venv/lib/python3.8/site-packages/rest_framework/serializers.py", line 745, in data
    ret = super().data
  File "/home/mohamedwahba/Desktop/DEV/Order-System/venv/lib/python3.8/site-packages/rest_framework/serializers.py", line 246, in data
    self._data = self.to_representation(self.instance)
  File "/home/mohamedwahba/Desktop/DEV/Order-System/venv/lib/python3.8/site-packages/rest_framework/serializers.py", line 663, in to_representation
    return [
  File "/home/mohamedwahba/Desktop/DEV/Order-System/venv/lib/python3.8/site-packages/rest_framework/serializers.py", line 664, in <listcomp>
    self.child.to_representation(item) for item in iterable
  File "/home/mohamedwahba/Desktop/DEV/Order-System/venv/lib/python3.8/site-packages/rest_framework/serializers.py", line 515, in to_representation
    ret[field.field_name] = field.to_representation(attribute)
  File "/home/mohamedwahba/Desktop/DEV/Order-System/venv/lib/python3.8/site-packages/rest_framework/serializers.py", line 663, in to_representation
    return [
  File "/home/mohamedwahba/Desktop/DEV/Order-System/venv/lib/python3.8/site-packages/rest_framework/serializers.py", line 664, in <listcomp>
    self.child.to_representation(item) for item in iterable
  File "/home/mohamedwahba/Desktop/DEV/Order-System/venv/lib/python3.8/site-packages/rest_framework/serializers.py", line 502, in to_representation
    attribute = field.get_attribute(instance)
  File "/home/mohamedwahba/Desktop/DEV/Order-System/venv/lib/python3.8/site-packages/rest_framework/fields.py", line 490, in get_attribute
    raise type(exc)(msg)
AttributeError: Got AttributeError when attempting to get a value for field `products` on serializer `CustomProductSerializer`.
The serializer field might be named incorrectly and not match any attribute or key on the `Product` instance.
Original exception text was: 'Product' object has no attribute 'products'.
25-02-2021 10:30:28 ERROR    [log.py:224] Internal Server Error: /api/product/order/
Traceback (most recent call last):
  File "/home/mohamedwahba/Desktop/DEV/Order-System/venv/lib/python3.8/site-packages/rest_framework/fields.py", line 457, in get_attribute
    return get_attribute(instance, self.source_attrs)
  File "/home/mohamedwahba/Desktop/DEV/Order-System/venv/lib/python3.8/site-packages/rest_framework/fields.py", line 97, in get_attribute
    instance = getattr(instance, attr)
AttributeError: 'Product' object has no attribute 'products'

During handling of the above exception, another exception occurred:

Traceback (most recent call last):
  File "/home/mohamedwahba/Desktop/DEV/Order-System/venv/lib/python3.8/site-packages/django/core/handlers/exception.py", line 47, in inner
    response = get_response(request)
  File "/home/mohamedwahba/Desktop/DEV/Order-System/venv/lib/python3.8/site-packages/django/core/handlers/base.py", line 181, in _get_response
    response = wrapped_callback(request, *callback_args, **callback_kwargs)
  File "/home/mohamedwahba/Desktop/DEV/Order-System/venv/lib/python3.8/site-packages/django/views/decorators/csrf.py", line 54, in wrapped_view
    return view_func(*args, **kwargs)
  File "/home/mohamedwahba/Desktop/DEV/Order-System/venv/lib/python3.8/site-packages/rest_framework/viewsets.py", line 125, in view
    return self.dispatch(request, *args, **kwargs)
  File "/home/mohamedwahba/Desktop/DEV/Order-System/venv/lib/python3.8/site-packages/rest_framework/views.py", line 509, in dispatch
    response = self.handle_exception(exc)
  File "/home/mohamedwahba/Desktop/DEV/Order-System/venv/lib/python3.8/site-packages/rest_framework/views.py", line 469, in handle_exception
    self.raise_uncaught_exception(exc)
  File "/home/mohamedwahba/Desktop/DEV/Order-System/venv/lib/python3.8/site-packages/rest_framework/views.py", line 480, in raise_uncaught_exception
    raise exc
  File "/home/mohamedwahba/Desktop/DEV/Order-System/venv/lib/python3.8/site-packages/rest_framework/views.py", line 506, in dispatch
    response = handler(request, *args, **kwargs)
  File "/home/mohamedwahba/Desktop/DEV/Order-System/venv/lib/python3.8/site-packages/rest_framework/mixins.py", line 46, in list
    return Response(serializer.data)
  File "/home/mohamedwahba/Desktop/DEV/Order-System/venv/lib/python3.8/site-packages/rest_framework/serializers.py", line 745, in data
    ret = super().data
  File "/home/mohamedwahba/Desktop/DEV/Order-System/venv/lib/python3.8/site-packages/rest_framework/serializers.py", line 246, in data
    self._data = self.to_representation(self.instance)
  File "/home/mohamedwahba/Desktop/DEV/Order-System/venv/lib/python3.8/site-packages/rest_framework/serializers.py", line 663, in to_representation
    return [
  File "/home/mohamedwahba/Desktop/DEV/Order-System/venv/lib/python3.8/site-packages/rest_framework/serializers.py", line 664, in <listcomp>
    self.child.to_representation(item) for item in iterable
  File "/home/mohamedwahba/Desktop/DEV/Order-System/venv/lib/python3.8/site-packages/rest_framework/serializers.py", line 515, in to_representation
    ret[field.field_name] = field.to_representation(attribute)
  File "/home/mohamedwahba/Desktop/DEV/Order-System/venv/lib/python3.8/site-packages/rest_framework/serializers.py", line 663, in to_representation
    return [
  File "/home/mohamedwahba/Desktop/DEV/Order-System/venv/lib/python3.8/site-packages/rest_framework/serializers.py", line 664, in <listcomp>
    self.child.to_representation(item) for item in iterable
  File "/home/mohamedwahba/Desktop/DEV/Order-System/venv/lib/python3.8/site-packages/rest_framework/serializers.py", line 502, in to_representation
    attribute = field.get_attribute(instance)
  File "/home/mohamedwahba/Desktop/DEV/Order-System/venv/lib/python3.8/site-packages/rest_framework/fields.py", line 490, in get_attribute
    raise type(exc)(msg)
AttributeError: Got AttributeError when attempting to get a value for field `products` on serializer `CustomProductSerializer`.
The serializer field might be named incorrectly and not match any attribute or key on the `Product` instance.
Original exception text was: 'Product' object has no attribute 'products'.
25-02-2021 10:30:28 ERROR    [log.py:224] Internal Server Error: /api/product/order/
Traceback (most recent call last):
  File "/home/mohamedwahba/Desktop/DEV/Order-System/venv/lib/python3.8/site-packages/rest_framework/fields.py", line 457, in get_attribute
    return get_attribute(instance, self.source_attrs)
  File "/home/mohamedwahba/Desktop/DEV/Order-System/venv/lib/python3.8/site-packages/rest_framework/fields.py", line 97, in get_attribute
    instance = getattr(instance, attr)
AttributeError: 'Product' object has no attribute 'products'

During handling of the above exception, another exception occurred:

Traceback (most recent call last):
  File "/home/mohamedwahba/Desktop/DEV/Order-System/venv/lib/python3.8/site-packages/django/core/handlers/exception.py", line 47, in inner
    response = get_response(request)
  File "/home/mohamedwahba/Desktop/DEV/Order-System/venv/lib/python3.8/site-packages/django/core/handlers/base.py", line 181, in _get_response
    response = wrapped_callback(request, *callback_args, **callback_kwargs)
  File "/home/mohamedwahba/Desktop/DEV/Order-System/venv/lib/python3.8/site-packages/django/views/decorators/csrf.py", line 54, in wrapped_view
    return view_func(*args, **kwargs)
  File "/home/mohamedwahba/Desktop/DEV/Order-System/venv/lib/python3.8/site-packages/rest_framework/viewsets.py", line 125, in view
    return self.dispatch(request, *args, **kwargs)
  File "/home/mohamedwahba/Desktop/DEV/Order-System/venv/lib/python3.8/site-packages/rest_framework/views.py", line 509, in dispatch
    response = self.handle_exception(exc)
  File "/home/mohamedwahba/Desktop/DEV/Order-System/venv/lib/python3.8/site-packages/rest_framework/views.py", line 469, in handle_exception
    self.raise_uncaught_exception(exc)
  File "/home/mohamedwahba/Desktop/DEV/Order-System/venv/lib/python3.8/site-packages/rest_framework/views.py", line 480, in raise_uncaught_exception
    raise exc
  File "/home/mohamedwahba/Desktop/DEV/Order-System/venv/lib/python3.8/site-packages/rest_framework/views.py", line 506, in dispatch
    response = handler(request, *args, **kwargs)
  File "/home/mohamedwahba/Desktop/DEV/Order-System/venv/lib/python3.8/site-packages/rest_framework/mixins.py", line 46, in list
    return Response(serializer.data)
  File "/home/mohamedwahba/Desktop/DEV/Order-System/venv/lib/python3.8/site-packages/rest_framework/serializers.py", line 745, in data
    ret = super().data
  File "/home/mohamedwahba/Desktop/DEV/Order-System/venv/lib/python3.8/site-packages/rest_framework/serializers.py", line 246, in data
    self._data = self.to_representation(self.instance)
  File "/home/mohamedwahba/Desktop/DEV/Order-System/venv/lib/python3.8/site-packages/rest_framework/serializers.py", line 663, in to_representation
    return [
  File "/home/mohamedwahba/Desktop/DEV/Order-System/venv/lib/python3.8/site-packages/rest_framework/serializers.py", line 664, in <listcomp>
    self.child.to_representation(item) for item in iterable
  File "/home/mohamedwahba/Desktop/DEV/Order-System/venv/lib/python3.8/site-packages/rest_framework/serializers.py", line 515, in to_representation
    ret[field.field_name] = field.to_representation(attribute)
  File "/home/mohamedwahba/Desktop/DEV/Order-System/venv/lib/python3.8/site-packages/rest_framework/serializers.py", line 663, in to_representation
    return [
  File "/home/mohamedwahba/Desktop/DEV/Order-System/venv/lib/python3.8/site-packages/rest_framework/serializers.py", line 664, in <listcomp>
    self.child.to_representation(item) for item in iterable
  File "/home/mohamedwahba/Desktop/DEV/Order-System/venv/lib/python3.8/site-packages/rest_framework/serializers.py", line 502, in to_representation
    attribute = field.get_attribute(instance)
  File "/home/mohamedwahba/Desktop/DEV/Order-System/venv/lib/python3.8/site-packages/rest_framework/fields.py", line 490, in get_attribute
    raise type(exc)(msg)
AttributeError: Got AttributeError when attempting to get a value for field `products` on serializer `CustomProductSerializer`.
The serializer field might be named incorrectly and not match any attribute or key on the `Product` instance.
Original exception text was: 'Product' object has no attribute 'products'.
25-02-2021 10:30:28 ERROR    [log.py:224] Internal Server Error: /api/product/order/
Traceback (most recent call last):
  File "/home/mohamedwahba/Desktop/DEV/Order-System/venv/lib/python3.8/site-packages/rest_framework/fields.py", line 457, in get_attribute
    return get_attribute(instance, self.source_attrs)
  File "/home/mohamedwahba/Desktop/DEV/Order-System/venv/lib/python3.8/site-packages/rest_framework/fields.py", line 97, in get_attribute
    instance = getattr(instance, attr)
AttributeError: 'Product' object has no attribute 'products'

During handling of the above exception, another exception occurred:

Traceback (most recent call last):
  File "/home/mohamedwahba/Desktop/DEV/Order-System/venv/lib/python3.8/site-packages/django/core/handlers/exception.py", line 47, in inner
    response = get_response(request)
  File "/home/mohamedwahba/Desktop/DEV/Order-System/venv/lib/python3.8/site-packages/django/core/handlers/base.py", line 181, in _get_response
    response = wrapped_callback(request, *callback_args, **callback_kwargs)
  File "/home/mohamedwahba/Desktop/DEV/Order-System/venv/lib/python3.8/site-packages/django/views/decorators/csrf.py", line 54, in wrapped_view
    return view_func(*args, **kwargs)
  File "/home/mohamedwahba/Desktop/DEV/Order-System/venv/lib/python3.8/site-packages/rest_framework/viewsets.py", line 125, in view
    return self.dispatch(request, *args, **kwargs)
  File "/home/mohamedwahba/Desktop/DEV/Order-System/venv/lib/python3.8/site-packages/rest_framework/views.py", line 509, in dispatch
    response = self.handle_exception(exc)
  File "/home/mohamedwahba/Desktop/DEV/Order-System/venv/lib/python3.8/site-packages/rest_framework/views.py", line 469, in handle_exception
    self.raise_uncaught_exception(exc)
  File "/home/mohamedwahba/Desktop/DEV/Order-System/venv/lib/python3.8/site-packages/rest_framework/views.py", line 480, in raise_uncaught_exception
    raise exc
  File "/home/mohamedwahba/Desktop/DEV/Order-System/venv/lib/python3.8/site-packages/rest_framework/views.py", line 506, in dispatch
    response = handler(request, *args, **kwargs)
  File "/home/mohamedwahba/Desktop/DEV/Order-System/venv/lib/python3.8/site-packages/rest_framework/mixins.py", line 46, in list
    return Response(serializer.data)
  File "/home/mohamedwahba/Desktop/DEV/Order-System/venv/lib/python3.8/site-packages/rest_framework/serializers.py", line 745, in data
    ret = super().data
  File "/home/mohamedwahba/Desktop/DEV/Order-System/venv/lib/python3.8/site-packages/rest_framework/serializers.py", line 246, in data
    self._data = self.to_representation(self.instance)
  File "/home/mohamedwahba/Desktop/DEV/Order-System/venv/lib/python3.8/site-packages/rest_framework/serializers.py", line 663, in to_representation
    return [
  File "/home/mohamedwahba/Desktop/DEV/Order-System/venv/lib/python3.8/site-packages/rest_framework/serializers.py", line 664, in <listcomp>
    self.child.to_representation(item) for item in iterable
  File "/home/mohamedwahba/Desktop/DEV/Order-System/venv/lib/python3.8/site-packages/rest_framework/serializers.py", line 515, in to_representation
    ret[field.field_name] = field.to_representation(attribute)
  File "/home/mohamedwahba/Desktop/DEV/Order-System/venv/lib/python3.8/site-packages/rest_framework/serializers.py", line 663, in to_representation
    return [
  File "/home/mohamedwahba/Desktop/DEV/Order-System/venv/lib/python3.8/site-packages/rest_framework/serializers.py", line 664, in <listcomp>
    self.child.to_representation(item) for item in iterable
  File "/home/mohamedwahba/Desktop/DEV/Order-System/venv/lib/python3.8/site-packages/rest_framework/serializers.py", line 502, in to_representation
    attribute = field.get_attribute(instance)
  File "/home/mohamedwahba/Desktop/DEV/Order-System/venv/lib/python3.8/site-packages/rest_framework/fields.py", line 490, in get_attribute
    raise type(exc)(msg)
AttributeError: Got AttributeError when attempting to get a value for field `products` on serializer `CustomProductSerializer`.
The serializer field might be named incorrectly and not match any attribute or key on the `Product` instance.
Original exception text was: 'Product' object has no attribute 'products'.
25-02-2021 10:30:35 INFO     [autoreload.py:240] /home/mohamedwahba/Desktop/DEV/Order-System/product/serializers.py changed, reloading.
25-02-2021 10:30:35 DEBUG    [selector_events.py:59] Using selector: EpollSelector
25-02-2021 10:30:36 INFO     [autoreload.py:617] Watching for file changes with StatReloader
25-02-2021 10:30:36 DEBUG    [core.py:163] Successfully imported extension module "markdown.extensions.toc".
25-02-2021 10:30:36 DEBUG    [core.py:126] Successfully loaded extension "markdown.extensions.toc.TocExtension".
25-02-2021 10:30:49 INFO     [autoreload.py:240] /home/mohamedwahba/Desktop/DEV/Order-System/product/serializers.py changed, reloading.
25-02-2021 10:30:49 DEBUG    [selector_events.py:59] Using selector: EpollSelector
25-02-2021 10:30:50 INFO     [autoreload.py:617] Watching for file changes with StatReloader
25-02-2021 10:30:50 ERROR    [log.py:224] Internal Server Error: /api/product/order/
Traceback (most recent call last):
  File "/home/mohamedwahba/Desktop/DEV/Order-System/venv/lib/python3.8/site-packages/rest_framework/fields.py", line 457, in get_attribute
    return get_attribute(instance, self.source_attrs)
  File "/home/mohamedwahba/Desktop/DEV/Order-System/venv/lib/python3.8/site-packages/rest_framework/fields.py", line 97, in get_attribute
    instance = getattr(instance, attr)
AttributeError: 'Product' object has no attribute 'products'

During handling of the above exception, another exception occurred:

Traceback (most recent call last):
  File "/home/mohamedwahba/Desktop/DEV/Order-System/venv/lib/python3.8/site-packages/django/core/handlers/exception.py", line 47, in inner
    response = get_response(request)
  File "/home/mohamedwahba/Desktop/DEV/Order-System/venv/lib/python3.8/site-packages/django/core/handlers/base.py", line 181, in _get_response
    response = wrapped_callback(request, *callback_args, **callback_kwargs)
  File "/home/mohamedwahba/Desktop/DEV/Order-System/venv/lib/python3.8/site-packages/django/views/decorators/csrf.py", line 54, in wrapped_view
    return view_func(*args, **kwargs)
  File "/home/mohamedwahba/Desktop/DEV/Order-System/venv/lib/python3.8/site-packages/rest_framework/viewsets.py", line 125, in view
    return self.dispatch(request, *args, **kwargs)
  File "/home/mohamedwahba/Desktop/DEV/Order-System/venv/lib/python3.8/site-packages/rest_framework/views.py", line 509, in dispatch
    response = self.handle_exception(exc)
  File "/home/mohamedwahba/Desktop/DEV/Order-System/venv/lib/python3.8/site-packages/rest_framework/views.py", line 469, in handle_exception
    self.raise_uncaught_exception(exc)
  File "/home/mohamedwahba/Desktop/DEV/Order-System/venv/lib/python3.8/site-packages/rest_framework/views.py", line 480, in raise_uncaught_exception
    raise exc
  File "/home/mohamedwahba/Desktop/DEV/Order-System/venv/lib/python3.8/site-packages/rest_framework/views.py", line 506, in dispatch
    response = handler(request, *args, **kwargs)
  File "/home/mohamedwahba/Desktop/DEV/Order-System/venv/lib/python3.8/site-packages/rest_framework/mixins.py", line 46, in list
    return Response(serializer.data)
  File "/home/mohamedwahba/Desktop/DEV/Order-System/venv/lib/python3.8/site-packages/rest_framework/serializers.py", line 745, in data
    ret = super().data
  File "/home/mohamedwahba/Desktop/DEV/Order-System/venv/lib/python3.8/site-packages/rest_framework/serializers.py", line 246, in data
    self._data = self.to_representation(self.instance)
  File "/home/mohamedwahba/Desktop/DEV/Order-System/venv/lib/python3.8/site-packages/rest_framework/serializers.py", line 663, in to_representation
    return [
  File "/home/mohamedwahba/Desktop/DEV/Order-System/venv/lib/python3.8/site-packages/rest_framework/serializers.py", line 664, in <listcomp>
    self.child.to_representation(item) for item in iterable
  File "/home/mohamedwahba/Desktop/DEV/Order-System/venv/lib/python3.8/site-packages/rest_framework/serializers.py", line 515, in to_representation
    ret[field.field_name] = field.to_representation(attribute)
  File "/home/mohamedwahba/Desktop/DEV/Order-System/venv/lib/python3.8/site-packages/rest_framework/serializers.py", line 663, in to_representation
    return [
  File "/home/mohamedwahba/Desktop/DEV/Order-System/venv/lib/python3.8/site-packages/rest_framework/serializers.py", line 664, in <listcomp>
    self.child.to_representation(item) for item in iterable
  File "/home/mohamedwahba/Desktop/DEV/Order-System/venv/lib/python3.8/site-packages/rest_framework/serializers.py", line 502, in to_representation
    attribute = field.get_attribute(instance)
  File "/home/mohamedwahba/Desktop/DEV/Order-System/venv/lib/python3.8/site-packages/rest_framework/fields.py", line 490, in get_attribute
    raise type(exc)(msg)
AttributeError: Got AttributeError when attempting to get a value for field `products` on serializer `CustomProductSerializer`.
The serializer field might be named incorrectly and not match any attribute or key on the `Product` instance.
Original exception text was: 'Product' object has no attribute 'products'.
25-02-2021 10:31:29 INFO     [autoreload.py:240] /home/mohamedwahba/Desktop/DEV/Order-System/product/serializers.py changed, reloading.
25-02-2021 10:31:29 DEBUG    [selector_events.py:59] Using selector: EpollSelector
25-02-2021 10:31:29 INFO     [autoreload.py:617] Watching for file changes with StatReloader
25-02-2021 10:32:30 INFO     [autoreload.py:240] /home/mohamedwahba/Desktop/DEV/Order-System/product/serializers.py changed, reloading.
25-02-2021 10:32:30 DEBUG    [selector_events.py:59] Using selector: EpollSelector
25-02-2021 10:32:30 INFO     [autoreload.py:617] Watching for file changes with StatReloader
25-02-2021 10:33:44 DEBUG    [selector_events.py:59] Using selector: EpollSelector
25-02-2021 10:33:45 DEBUG    [selector_events.py:59] Using selector: EpollSelector
25-02-2021 10:33:46 DEBUG    [selector_events.py:59] Using selector: EpollSelector
25-02-2021 10:33:46 INFO     [connectionpool.py:212] Starting new HTTP connection (1): data.fixer.io
25-02-2021 10:33:47 DEBUG    [connectionpool.py:394] "GET /api/latest?access_key=34e2df461e05e5871c51b4293d8a62c8 HTTP/1.1" 200 None
25-02-2021 10:33:48 WARNING  [log.py:224] Method Not Allowed: /api/user/me/
25-02-2021 10:33:49 WARNING  [log.py:224] Bad Request: /api/user/token/
25-02-2021 10:33:49 WARNING  [log.py:224] Bad Request: /api/user/token/
25-02-2021 10:33:49 WARNING  [log.py:224] Bad Request: /api/user/token/
25-02-2021 10:33:49 WARNING  [log.py:224] Bad Request: /api/user/create/
25-02-2021 10:33:49 WARNING  [log.py:224] Unauthorized: /api/user/me/
25-02-2021 10:33:49 WARNING  [log.py:224] Bad Request: /api/user/create/
25-02-2021 10:33:50 WARNING  [log.py:224] Too Many Requests: /api/product/product/1/
25-02-2021 10:33:50 WARNING  [log.py:224] Unauthorized: /api/product/product/
25-02-2021 10:34:11 DEBUG    [selector_events.py:59] Using selector: EpollSelector
25-02-2021 10:34:12 INFO     [connectionpool.py:212] Starting new HTTP connection (1): data.fixer.io
25-02-2021 10:34:12 DEBUG    [connectionpool.py:394] "GET /api/latest?access_key=34e2df461e05e5871c51b4293d8a62c8 HTTP/1.1" 200 None
25-02-2021 10:34:14 WARNING  [log.py:224] Method Not Allowed: /api/user/me/
25-02-2021 10:34:14 WARNING  [log.py:224] Bad Request: /api/user/token/
25-02-2021 10:34:14 WARNING  [log.py:224] Bad Request: /api/user/token/
25-02-2021 10:34:15 WARNING  [log.py:224] Bad Request: /api/user/token/
25-02-2021 10:34:15 WARNING  [log.py:224] Bad Request: /api/user/create/
25-02-2021 10:34:15 WARNING  [log.py:224] Unauthorized: /api/user/me/
25-02-2021 10:34:15 WARNING  [log.py:224] Bad Request: /api/user/create/
25-02-2021 10:34:15 WARNING  [log.py:224] Too Many Requests: /api/product/product/1/
25-02-2021 10:34:15 WARNING  [log.py:224] Unauthorized: /api/product/product/
25-02-2021 10:34:30 DEBUG    [selector_events.py:59] Using selector: EpollSelector
25-02-2021 10:34:30 INFO     [connectionpool.py:212] Starting new HTTP connection (1): data.fixer.io
25-02-2021 10:34:31 DEBUG    [connectionpool.py:394] "GET /api/latest?access_key=34e2df461e05e5871c51b4293d8a62c8 HTTP/1.1" 200 None
25-02-2021 10:34:32 WARNING  [log.py:224] Method Not Allowed: /api/user/me/
25-02-2021 10:34:33 WARNING  [log.py:224] Bad Request: /api/user/token/
25-02-2021 10:34:33 WARNING  [log.py:224] Bad Request: /api/user/token/
25-02-2021 10:34:33 WARNING  [log.py:224] Bad Request: /api/user/token/
25-02-2021 10:34:34 WARNING  [log.py:224] Bad Request: /api/user/create/
25-02-2021 10:34:34 WARNING  [log.py:224] Unauthorized: /api/user/me/
25-02-2021 10:34:34 WARNING  [log.py:224] Bad Request: /api/user/create/
25-02-2021 10:34:34 WARNING  [log.py:224] Unauthorized: /api/product/product/
25-02-2021 10:35:21 DEBUG    [selector_events.py:59] Using selector: EpollSelector
25-02-2021 10:35:21 INFO     [connectionpool.py:212] Starting new HTTP connection (1): data.fixer.io
25-02-2021 10:35:22 DEBUG    [connectionpool.py:394] "GET /api/latest?access_key=34e2df461e05e5871c51b4293d8a62c8 HTTP/1.1" 200 None
25-02-2021 10:35:23 WARNING  [log.py:224] Method Not Allowed: /api/user/me/
25-02-2021 10:35:24 WARNING  [log.py:224] Bad Request: /api/user/token/
25-02-2021 10:35:24 WARNING  [log.py:224] Bad Request: /api/user/token/
25-02-2021 10:35:25 WARNING  [log.py:224] Bad Request: /api/user/token/
25-02-2021 10:35:25 WARNING  [log.py:224] Bad Request: /api/user/create/
25-02-2021 10:35:25 WARNING  [log.py:224] Unauthorized: /api/user/me/
25-02-2021 10:35:25 WARNING  [log.py:224] Bad Request: /api/user/create/
25-02-2021 10:35:25 WARNING  [log.py:224] Unauthorized: /api/product/product/
25-02-2021 10:36:12 DEBUG    [selector_events.py:59] Using selector: EpollSelector
25-02-2021 10:36:12 INFO     [connectionpool.py:212] Starting new HTTP connection (1): data.fixer.io
25-02-2021 10:36:12 DEBUG    [connectionpool.py:394] "GET /api/latest?access_key=34e2df461e05e5871c51b4293d8a62c8 HTTP/1.1" 200 None
25-02-2021 10:36:14 WARNING  [log.py:224] Method Not Allowed: /api/user/me/
25-02-2021 10:36:15 WARNING  [log.py:224] Bad Request: /api/user/token/
25-02-2021 10:36:15 WARNING  [log.py:224] Bad Request: /api/user/token/
25-02-2021 10:36:15 WARNING  [log.py:224] Bad Request: /api/user/token/
25-02-2021 10:36:15 WARNING  [log.py:224] Bad Request: /api/user/create/
25-02-2021 10:36:15 WARNING  [log.py:224] Unauthorized: /api/user/me/
25-02-2021 10:36:15 WARNING  [log.py:224] Bad Request: /api/user/create/
25-02-2021 10:36:16 WARNING  [log.py:224] Unauthorized: /api/product/product/
25-02-2021 10:36:27 DEBUG    [selector_events.py:59] Using selector: EpollSelector
25-02-2021 10:36:27 INFO     [connectionpool.py:212] Starting new HTTP connection (1): data.fixer.io
25-02-2021 10:36:28 DEBUG    [connectionpool.py:394] "GET /api/latest?access_key=34e2df461e05e5871c51b4293d8a62c8 HTTP/1.1" 200 None
25-02-2021 10:36:29 WARNING  [log.py:224] Method Not Allowed: /api/user/me/
25-02-2021 10:36:30 WARNING  [log.py:224] Bad Request: /api/user/token/
25-02-2021 10:36:30 WARNING  [log.py:224] Bad Request: /api/user/token/
25-02-2021 10:36:30 WARNING  [log.py:224] Bad Request: /api/user/token/
25-02-2021 10:36:31 WARNING  [log.py:224] Bad Request: /api/user/create/
25-02-2021 10:36:31 WARNING  [log.py:224] Unauthorized: /api/user/me/
25-02-2021 10:36:31 WARNING  [log.py:224] Bad Request: /api/user/create/
25-02-2021 10:36:31 WARNING  [log.py:224] Unauthorized: /api/product/product/
25-02-2021 10:37:21 DEBUG    [selector_events.py:59] Using selector: EpollSelector
25-02-2021 10:37:21 INFO     [connectionpool.py:212] Starting new HTTP connection (1): data.fixer.io
25-02-2021 10:37:22 DEBUG    [connectionpool.py:394] "GET /api/latest?access_key=34e2df461e05e5871c51b4293d8a62c8 HTTP/1.1" 200 None
25-02-2021 10:37:23 WARNING  [log.py:224] Method Not Allowed: /api/user/me/
25-02-2021 10:37:24 WARNING  [log.py:224] Bad Request: /api/user/token/
25-02-2021 10:37:24 WARNING  [log.py:224] Bad Request: /api/user/token/
25-02-2021 10:37:24 WARNING  [log.py:224] Bad Request: /api/user/token/
25-02-2021 10:37:24 WARNING  [log.py:224] Bad Request: /api/user/create/
25-02-2021 10:37:24 WARNING  [log.py:224] Unauthorized: /api/user/me/
25-02-2021 10:37:25 WARNING  [log.py:224] Bad Request: /api/user/create/
25-02-2021 10:37:25 WARNING  [log.py:224] Unauthorized: /api/product/product/
25-02-2021 10:37:44 DEBUG    [selector_events.py:59] Using selector: EpollSelector
25-02-2021 10:37:44 INFO     [connectionpool.py:212] Starting new HTTP connection (1): data.fixer.io
25-02-2021 10:37:45 DEBUG    [connectionpool.py:394] "GET /api/latest?access_key=34e2df461e05e5871c51b4293d8a62c8 HTTP/1.1" 200 None
25-02-2021 10:37:46 WARNING  [log.py:224] Method Not Allowed: /api/user/me/
25-02-2021 10:37:47 WARNING  [log.py:224] Bad Request: /api/user/token/
25-02-2021 10:37:47 WARNING  [log.py:224] Bad Request: /api/user/token/
25-02-2021 10:37:47 WARNING  [log.py:224] Bad Request: /api/user/token/
25-02-2021 10:37:47 WARNING  [log.py:224] Bad Request: /api/user/create/
25-02-2021 10:37:47 WARNING  [log.py:224] Unauthorized: /api/user/me/
25-02-2021 10:37:47 WARNING  [log.py:224] Bad Request: /api/user/create/
25-02-2021 10:37:48 WARNING  [log.py:224] Too Many Requests: /api/product/product/
25-02-2021 10:37:48 WARNING  [log.py:224] Unauthorized: /api/product/product/
25-02-2021 10:38:40 DEBUG    [selector_events.py:59] Using selector: EpollSelector
25-02-2021 10:38:41 INFO     [connectionpool.py:212] Starting new HTTP connection (1): data.fixer.io
25-02-2021 10:38:41 DEBUG    [connectionpool.py:394] "GET /api/latest?access_key=34e2df461e05e5871c51b4293d8a62c8 HTTP/1.1" 200 None
25-02-2021 10:38:43 WARNING  [log.py:224] Method Not Allowed: /api/user/me/
25-02-2021 10:38:44 WARNING  [log.py:224] Bad Request: /api/user/token/
25-02-2021 10:38:44 WARNING  [log.py:224] Bad Request: /api/user/token/
25-02-2021 10:38:44 WARNING  [log.py:224] Bad Request: /api/user/token/
25-02-2021 10:38:44 WARNING  [log.py:224] Bad Request: /api/user/create/
25-02-2021 10:38:44 WARNING  [log.py:224] Unauthorized: /api/user/me/
25-02-2021 10:38:44 WARNING  [log.py:224] Bad Request: /api/user/create/
25-02-2021 10:38:44 WARNING  [log.py:224] Too Many Requests: /api/product/product/
25-02-2021 10:38:44 WARNING  [log.py:224] Unauthorized: /api/product/product/
25-02-2021 10:38:50 DEBUG    [selector_events.py:59] Using selector: EpollSelector
25-02-2021 10:38:50 INFO     [connectionpool.py:212] Starting new HTTP connection (1): data.fixer.io
25-02-2021 10:38:51 DEBUG    [connectionpool.py:394] "GET /api/latest?access_key=34e2df461e05e5871c51b4293d8a62c8 HTTP/1.1" 200 None
25-02-2021 10:38:52 WARNING  [log.py:224] Method Not Allowed: /api/user/me/
25-02-2021 10:38:53 WARNING  [log.py:224] Bad Request: /api/user/token/
25-02-2021 10:38:53 WARNING  [log.py:224] Bad Request: /api/user/token/
25-02-2021 10:38:53 WARNING  [log.py:224] Bad Request: /api/user/token/
25-02-2021 10:38:53 WARNING  [log.py:224] Bad Request: /api/user/create/
25-02-2021 10:38:53 WARNING  [log.py:224] Unauthorized: /api/user/me/
25-02-2021 10:38:54 WARNING  [log.py:224] Bad Request: /api/user/create/
25-02-2021 10:38:54 WARNING  [log.py:224] Too Many Requests: /api/product/product/
25-02-2021 10:38:54 WARNING  [log.py:224] Unauthorized: /api/product/product/
25-02-2021 10:39:13 DEBUG    [selector_events.py:59] Using selector: EpollSelector
25-02-2021 10:39:13 INFO     [connectionpool.py:212] Starting new HTTP connection (1): data.fixer.io
25-02-2021 10:39:14 DEBUG    [connectionpool.py:394] "GET /api/latest?access_key=34e2df461e05e5871c51b4293d8a62c8 HTTP/1.1" 200 None
25-02-2021 10:39:15 WARNING  [log.py:224] Method Not Allowed: /api/user/me/
25-02-2021 10:39:16 WARNING  [log.py:224] Bad Request: /api/user/token/
25-02-2021 10:39:16 WARNING  [log.py:224] Bad Request: /api/user/token/
25-02-2021 10:39:16 WARNING  [log.py:224] Bad Request: /api/user/token/
25-02-2021 10:39:16 WARNING  [log.py:224] Bad Request: /api/user/create/
25-02-2021 10:39:16 WARNING  [log.py:224] Unauthorized: /api/user/me/
25-02-2021 10:39:16 WARNING  [log.py:224] Bad Request: /api/user/create/
25-02-2021 10:39:17 WARNING  [log.py:224] Too Many Requests: /api/product/product/
25-02-2021 10:39:17 WARNING  [log.py:224] Unauthorized: /api/product/product/
25-02-2021 10:40:01 DEBUG    [selector_events.py:59] Using selector: EpollSelector
25-02-2021 10:40:01 INFO     [connectionpool.py:212] Starting new HTTP connection (1): data.fixer.io
25-02-2021 10:40:02 DEBUG    [connectionpool.py:394] "GET /api/latest?access_key=34e2df461e05e5871c51b4293d8a62c8 HTTP/1.1" 200 None
25-02-2021 10:40:03 WARNING  [log.py:224] Method Not Allowed: /api/user/me/
25-02-2021 10:40:04 WARNING  [log.py:224] Bad Request: /api/user/token/
25-02-2021 10:40:04 WARNING  [log.py:224] Bad Request: /api/user/token/
25-02-2021 10:40:04 WARNING  [log.py:224] Bad Request: /api/user/token/
25-02-2021 10:40:05 WARNING  [log.py:224] Bad Request: /api/user/create/
25-02-2021 10:40:05 WARNING  [log.py:224] Unauthorized: /api/user/me/
25-02-2021 10:40:05 WARNING  [log.py:224] Bad Request: /api/user/create/
25-02-2021 10:40:05 WARNING  [log.py:224] Too Many Requests: /api/product/product/
25-02-2021 10:40:05 WARNING  [log.py:224] Unauthorized: /api/product/product/
25-02-2021 10:41:03 DEBUG    [selector_events.py:59] Using selector: EpollSelector
25-02-2021 10:41:03 INFO     [connectionpool.py:212] Starting new HTTP connection (1): data.fixer.io
25-02-2021 10:41:04 DEBUG    [connectionpool.py:394] "GET /api/latest?access_key=34e2df461e05e5871c51b4293d8a62c8 HTTP/1.1" 200 None
25-02-2021 10:41:05 WARNING  [log.py:224] Method Not Allowed: /api/user/me/
25-02-2021 10:41:06 WARNING  [log.py:224] Bad Request: /api/user/token/
25-02-2021 10:41:06 WARNING  [log.py:224] Bad Request: /api/user/token/
25-02-2021 10:41:06 WARNING  [log.py:224] Bad Request: /api/user/token/
25-02-2021 10:41:07 WARNING  [log.py:224] Bad Request: /api/user/create/
25-02-2021 10:41:07 WARNING  [log.py:224] Unauthorized: /api/user/me/
25-02-2021 10:41:07 WARNING  [log.py:224] Bad Request: /api/user/create/
25-02-2021 10:41:07 WARNING  [log.py:224] Unauthorized: /api/product/product/
25-02-2021 10:41:18 DEBUG    [selector_events.py:59] Using selector: EpollSelector
25-02-2021 10:41:18 INFO     [connectionpool.py:212] Starting new HTTP connection (1): data.fixer.io
25-02-2021 10:41:19 DEBUG    [connectionpool.py:394] "GET /api/latest?access_key=34e2df461e05e5871c51b4293d8a62c8 HTTP/1.1" 200 None
25-02-2021 10:41:20 WARNING  [log.py:224] Method Not Allowed: /api/user/me/
25-02-2021 10:41:21 WARNING  [log.py:224] Bad Request: /api/user/token/
25-02-2021 10:41:21 WARNING  [log.py:224] Bad Request: /api/user/token/
25-02-2021 10:41:21 WARNING  [log.py:224] Bad Request: /api/user/token/
25-02-2021 10:41:21 WARNING  [log.py:224] Bad Request: /api/user/create/
25-02-2021 10:41:21 WARNING  [log.py:224] Unauthorized: /api/user/me/
25-02-2021 10:41:21 WARNING  [log.py:224] Bad Request: /api/user/create/
25-02-2021 10:41:22 WARNING  [log.py:224] Unauthorized: /api/product/product/
25-02-2021 10:42:51 DEBUG    [selector_events.py:59] Using selector: EpollSelector
25-02-2021 10:42:51 INFO     [connectionpool.py:212] Starting new HTTP connection (1): data.fixer.io
25-02-2021 10:42:52 DEBUG    [connectionpool.py:394] "GET /api/latest?access_key=34e2df461e05e5871c51b4293d8a62c8 HTTP/1.1" 200 None
25-02-2021 10:42:53 WARNING  [log.py:224] Method Not Allowed: /api/user/me/
25-02-2021 10:42:54 WARNING  [log.py:224] Bad Request: /api/user/token/
25-02-2021 10:42:54 WARNING  [log.py:224] Bad Request: /api/user/token/
25-02-2021 10:42:54 WARNING  [log.py:224] Bad Request: /api/user/token/
25-02-2021 10:42:54 WARNING  [log.py:224] Bad Request: /api/user/create/
25-02-2021 10:42:54 WARNING  [log.py:224] Unauthorized: /api/user/me/
25-02-2021 10:42:54 WARNING  [log.py:224] Bad Request: /api/user/create/
25-02-2021 10:42:55 WARNING  [log.py:224] Bad Request: /api/product/product/
25-02-2021 10:42:55 WARNING  [log.py:224] Unauthorized: /api/product/product/
25-02-2021 10:43:41 INFO     [autoreload.py:617] Watching for file changes with StatReloader
25-02-2021 10:43:43 DEBUG    [core.py:163] Successfully imported extension module "markdown.extensions.toc".
25-02-2021 10:43:43 DEBUG    [core.py:126] Successfully loaded extension "markdown.extensions.toc.TocExtension".
25-02-2021 10:44:38 DEBUG    [selector_events.py:59] Using selector: EpollSelector
25-02-2021 10:44:38 DEBUG    [selector_events.py:59] Using selector: EpollSelector
25-02-2021 10:44:39 DEBUG    [selector_events.py:59] Using selector: EpollSelector
25-02-2021 10:44:40 INFO     [connectionpool.py:212] Starting new HTTP connection (1): data.fixer.io
25-02-2021 10:44:40 DEBUG    [connectionpool.py:394] "GET /api/latest?access_key=34e2df461e05e5871c51b4293d8a62c8 HTTP/1.1" 200 None
25-02-2021 10:44:41 WARNING  [log.py:224] Method Not Allowed: /api/user/me/
25-02-2021 10:44:42 WARNING  [log.py:224] Bad Request: /api/user/token/
25-02-2021 10:44:42 WARNING  [log.py:224] Bad Request: /api/user/token/
25-02-2021 10:44:42 WARNING  [log.py:224] Bad Request: /api/user/token/
25-02-2021 10:44:43 WARNING  [log.py:224] Bad Request: /api/user/create/
25-02-2021 10:44:43 WARNING  [log.py:224] Unauthorized: /api/user/me/
25-02-2021 10:44:43 WARNING  [log.py:224] Bad Request: /api/user/create/
25-02-2021 10:44:43 WARNING  [log.py:224] Bad Request: /api/product/product/
25-02-2021 10:44:43 WARNING  [log.py:224] Unauthorized: /api/product/product/
25-02-2021 10:45:07 DEBUG    [selector_events.py:59] Using selector: EpollSelector
25-02-2021 10:45:07 INFO     [connectionpool.py:212] Starting new HTTP connection (1): data.fixer.io
25-02-2021 10:45:08 DEBUG    [connectionpool.py:394] "GET /api/latest?access_key=34e2df461e05e5871c51b4293d8a62c8 HTTP/1.1" 200 None
25-02-2021 10:45:09 WARNING  [log.py:224] Method Not Allowed: /api/user/me/
25-02-2021 10:45:10 WARNING  [log.py:224] Bad Request: /api/user/token/
25-02-2021 10:45:10 WARNING  [log.py:224] Bad Request: /api/user/token/
25-02-2021 10:45:10 WARNING  [log.py:224] Bad Request: /api/user/token/
25-02-2021 10:45:10 WARNING  [log.py:224] Bad Request: /api/user/create/
25-02-2021 10:45:10 WARNING  [log.py:224] Unauthorized: /api/user/me/
25-02-2021 10:45:10 WARNING  [log.py:224] Bad Request: /api/user/create/
25-02-2021 10:45:11 WARNING  [log.py:224] Bad Request: /api/product/product/
25-02-2021 10:45:11 WARNING  [log.py:224] Unauthorized: /api/product/product/
25-02-2021 10:45:43 DEBUG    [selector_events.py:59] Using selector: EpollSelector
25-02-2021 10:45:43 INFO     [connectionpool.py:212] Starting new HTTP connection (1): data.fixer.io
25-02-2021 10:45:44 DEBUG    [connectionpool.py:394] "GET /api/latest?access_key=34e2df461e05e5871c51b4293d8a62c8 HTTP/1.1" 200 None
25-02-2021 10:45:45 WARNING  [log.py:224] Method Not Allowed: /api/user/me/
25-02-2021 10:45:46 WARNING  [log.py:224] Bad Request: /api/user/token/
25-02-2021 10:45:46 WARNING  [log.py:224] Bad Request: /api/user/token/
25-02-2021 10:45:46 WARNING  [log.py:224] Bad Request: /api/user/token/
25-02-2021 10:45:46 WARNING  [log.py:224] Bad Request: /api/user/create/
25-02-2021 10:45:46 WARNING  [log.py:224] Unauthorized: /api/user/me/
25-02-2021 10:45:46 WARNING  [log.py:224] Bad Request: /api/user/create/
25-02-2021 10:45:47 WARNING  [log.py:224] Bad Request: /api/product/product/
25-02-2021 10:45:47 WARNING  [log.py:224] Unauthorized: /api/product/product/
25-02-2021 10:46:30 DEBUG    [selector_events.py:59] Using selector: EpollSelector
25-02-2021 10:46:30 INFO     [connectionpool.py:212] Starting new HTTP connection (1): data.fixer.io
25-02-2021 10:46:30 DEBUG    [connectionpool.py:394] "GET /api/latest?access_key=34e2df461e05e5871c51b4293d8a62c8 HTTP/1.1" 200 None
25-02-2021 10:46:32 WARNING  [log.py:224] Method Not Allowed: /api/user/me/
25-02-2021 10:46:32 WARNING  [log.py:224] Bad Request: /api/user/token/
25-02-2021 10:46:32 WARNING  [log.py:224] Bad Request: /api/user/token/
25-02-2021 10:46:33 WARNING  [log.py:224] Bad Request: /api/user/token/
25-02-2021 10:46:33 WARNING  [log.py:224] Bad Request: /api/user/create/
25-02-2021 10:46:33 WARNING  [log.py:224] Unauthorized: /api/user/me/
25-02-2021 10:46:33 WARNING  [log.py:224] Bad Request: /api/user/create/
25-02-2021 10:46:33 WARNING  [log.py:224] Unauthorized: /api/product/product/
25-02-2021 10:47:17 DEBUG    [selector_events.py:59] Using selector: EpollSelector
25-02-2021 10:47:18 INFO     [connectionpool.py:212] Starting new HTTP connection (1): data.fixer.io
25-02-2021 10:47:18 DEBUG    [connectionpool.py:394] "GET /api/latest?access_key=34e2df461e05e5871c51b4293d8a62c8 HTTP/1.1" 200 None
25-02-2021 10:47:19 WARNING  [log.py:224] Method Not Allowed: /api/user/me/
25-02-2021 10:47:20 WARNING  [log.py:224] Bad Request: /api/user/token/
25-02-2021 10:47:20 WARNING  [log.py:224] Bad Request: /api/user/token/
25-02-2021 10:47:20 WARNING  [log.py:224] Bad Request: /api/user/token/
25-02-2021 10:47:21 WARNING  [log.py:224] Bad Request: /api/user/create/
25-02-2021 10:47:21 WARNING  [log.py:224] Unauthorized: /api/user/me/
25-02-2021 10:47:21 WARNING  [log.py:224] Bad Request: /api/user/create/
25-02-2021 10:47:21 WARNING  [log.py:224] Unauthorized: /api/product/product/
25-02-2021 10:55:54 DEBUG    [selector_events.py:59] Using selector: EpollSelector
25-02-2021 10:55:54 INFO     [connectionpool.py:212] Starting new HTTP connection (1): data.fixer.io
25-02-2021 10:55:55 DEBUG    [connectionpool.py:394] "GET /api/latest?access_key=34e2df461e05e5871c51b4293d8a62c8 HTTP/1.1" 200 None
25-02-2021 10:55:56 WARNING  [log.py:224] Method Not Allowed: /api/user/me/
25-02-2021 10:55:57 WARNING  [log.py:224] Bad Request: /api/user/token/
25-02-2021 10:55:57 WARNING  [log.py:224] Bad Request: /api/user/token/
25-02-2021 10:55:57 WARNING  [log.py:224] Bad Request: /api/user/token/
25-02-2021 10:55:57 WARNING  [log.py:224] Bad Request: /api/user/create/
25-02-2021 10:55:57 WARNING  [log.py:224] Unauthorized: /api/user/me/
25-02-2021 10:55:57 WARNING  [log.py:224] Bad Request: /api/user/create/
25-02-2021 10:55:58 WARNING  [log.py:224] Unauthorized: /api/product/product/
25-02-2021 10:57:34 DEBUG    [selector_events.py:59] Using selector: EpollSelector
25-02-2021 10:57:34 INFO     [connectionpool.py:212] Starting new HTTP connection (1): data.fixer.io
25-02-2021 10:57:34 DEBUG    [connectionpool.py:394] "GET /api/latest?access_key=34e2df461e05e5871c51b4293d8a62c8 HTTP/1.1" 200 None
25-02-2021 10:57:36 WARNING  [log.py:224] Method Not Allowed: /api/user/me/
25-02-2021 10:57:37 WARNING  [log.py:224] Bad Request: /api/user/token/
25-02-2021 10:57:37 WARNING  [log.py:224] Bad Request: /api/user/token/
25-02-2021 10:57:37 WARNING  [log.py:224] Bad Request: /api/user/token/
25-02-2021 10:57:37 WARNING  [log.py:224] Bad Request: /api/user/create/
25-02-2021 10:57:37 WARNING  [log.py:224] Unauthorized: /api/user/me/
25-02-2021 10:57:37 WARNING  [log.py:224] Bad Request: /api/user/create/
25-02-2021 10:57:38 WARNING  [log.py:224] Unauthorized: /api/product/product/
25-02-2021 10:57:56 DEBUG    [selector_events.py:59] Using selector: EpollSelector
25-02-2021 10:57:56 INFO     [connectionpool.py:212] Starting new HTTP connection (1): data.fixer.io
25-02-2021 10:57:56 DEBUG    [connectionpool.py:394] "GET /api/latest?access_key=34e2df461e05e5871c51b4293d8a62c8 HTTP/1.1" 200 None
25-02-2021 10:57:58 WARNING  [log.py:224] Method Not Allowed: /api/user/me/
25-02-2021 10:57:59 WARNING  [log.py:224] Bad Request: /api/user/token/
25-02-2021 10:57:59 WARNING  [log.py:224] Bad Request: /api/user/token/
25-02-2021 10:57:59 WARNING  [log.py:224] Bad Request: /api/user/token/
25-02-2021 10:57:59 WARNING  [log.py:224] Bad Request: /api/user/create/
25-02-2021 10:57:59 WARNING  [log.py:224] Unauthorized: /api/user/me/
25-02-2021 10:57:59 WARNING  [log.py:224] Bad Request: /api/user/create/
25-02-2021 10:57:59 WARNING  [log.py:224] Unauthorized: /api/product/product/
25-02-2021 10:59:34 DEBUG    [selector_events.py:59] Using selector: EpollSelector
25-02-2021 10:59:34 INFO     [connectionpool.py:212] Starting new HTTP connection (1): data.fixer.io
25-02-2021 10:59:34 DEBUG    [connectionpool.py:394] "GET /api/latest?access_key=34e2df461e05e5871c51b4293d8a62c8 HTTP/1.1" 200 None
25-02-2021 10:59:36 WARNING  [log.py:224] Method Not Allowed: /api/user/me/
25-02-2021 10:59:37 WARNING  [log.py:224] Bad Request: /api/user/token/
25-02-2021 10:59:37 WARNING  [log.py:224] Bad Request: /api/user/token/
25-02-2021 10:59:37 WARNING  [log.py:224] Bad Request: /api/user/token/
25-02-2021 10:59:37 WARNING  [log.py:224] Bad Request: /api/user/create/
25-02-2021 10:59:37 WARNING  [log.py:224] Unauthorized: /api/user/me/
25-02-2021 10:59:37 WARNING  [log.py:224] Bad Request: /api/user/create/
25-02-2021 10:59:37 WARNING  [log.py:224] Bad Request: /api/product/product/
25-02-2021 10:59:38 WARNING  [log.py:224] Unauthorized: /api/product/product/
25-02-2021 11:00:31 DEBUG    [selector_events.py:59] Using selector: EpollSelector
25-02-2021 11:00:31 INFO     [connectionpool.py:212] Starting new HTTP connection (1): data.fixer.io
25-02-2021 11:00:31 DEBUG    [connectionpool.py:394] "GET /api/latest?access_key=34e2df461e05e5871c51b4293d8a62c8 HTTP/1.1" 200 None
25-02-2021 11:00:33 WARNING  [log.py:224] Method Not Allowed: /api/user/me/
25-02-2021 11:00:34 WARNING  [log.py:224] Bad Request: /api/user/token/
25-02-2021 11:00:34 WARNING  [log.py:224] Bad Request: /api/user/token/
25-02-2021 11:00:34 WARNING  [log.py:224] Bad Request: /api/user/token/
25-02-2021 11:00:34 WARNING  [log.py:224] Bad Request: /api/user/create/
25-02-2021 11:00:34 WARNING  [log.py:224] Unauthorized: /api/user/me/
25-02-2021 11:00:34 WARNING  [log.py:224] Bad Request: /api/user/create/
25-02-2021 11:00:34 WARNING  [log.py:224] Bad Request: /api/product/product/
25-02-2021 11:00:35 WARNING  [log.py:224] Unauthorized: /api/product/product/
25-02-2021 11:01:08 DEBUG    [selector_events.py:59] Using selector: EpollSelector
25-02-2021 11:01:08 INFO     [connectionpool.py:212] Starting new HTTP connection (1): data.fixer.io
25-02-2021 11:01:09 DEBUG    [connectionpool.py:394] "GET /api/latest?access_key=34e2df461e05e5871c51b4293d8a62c8 HTTP/1.1" 200 None
25-02-2021 11:01:10 WARNING  [log.py:224] Method Not Allowed: /api/user/me/
25-02-2021 11:01:11 WARNING  [log.py:224] Bad Request: /api/user/token/
25-02-2021 11:01:11 WARNING  [log.py:224] Bad Request: /api/user/token/
25-02-2021 11:01:11 WARNING  [log.py:224] Bad Request: /api/user/token/
25-02-2021 11:01:12 WARNING  [log.py:224] Bad Request: /api/user/create/
25-02-2021 11:01:12 WARNING  [log.py:224] Unauthorized: /api/user/me/
25-02-2021 11:01:12 WARNING  [log.py:224] Bad Request: /api/user/create/
25-02-2021 11:01:12 WARNING  [log.py:224] Bad Request: /api/product/product/
25-02-2021 11:01:12 WARNING  [log.py:224] Unauthorized: /api/product/product/
25-02-2021 11:01:50 DEBUG    [selector_events.py:59] Using selector: EpollSelector
25-02-2021 11:01:50 INFO     [connectionpool.py:212] Starting new HTTP connection (1): data.fixer.io
25-02-2021 11:01:51 DEBUG    [connectionpool.py:394] "GET /api/latest?access_key=34e2df461e05e5871c51b4293d8a62c8 HTTP/1.1" 200 None
25-02-2021 11:01:52 WARNING  [log.py:224] Method Not Allowed: /api/user/me/
25-02-2021 11:01:53 WARNING  [log.py:224] Bad Request: /api/user/token/
25-02-2021 11:01:53 WARNING  [log.py:224] Bad Request: /api/user/token/
25-02-2021 11:01:53 WARNING  [log.py:224] Bad Request: /api/user/token/
25-02-2021 11:01:53 WARNING  [log.py:224] Bad Request: /api/user/create/
25-02-2021 11:01:53 WARNING  [log.py:224] Unauthorized: /api/user/me/
25-02-2021 11:01:53 WARNING  [log.py:224] Bad Request: /api/user/create/
25-02-2021 11:01:54 WARNING  [log.py:224] Bad Request: /api/product/product/
25-02-2021 11:01:54 WARNING  [log.py:224] Unauthorized: /api/product/product/
25-02-2021 11:02:13 DEBUG    [selector_events.py:59] Using selector: EpollSelector
25-02-2021 11:02:13 INFO     [connectionpool.py:212] Starting new HTTP connection (1): data.fixer.io
25-02-2021 11:02:13 DEBUG    [connectionpool.py:394] "GET /api/latest?access_key=34e2df461e05e5871c51b4293d8a62c8 HTTP/1.1" 200 None
25-02-2021 11:02:15 WARNING  [log.py:224] Method Not Allowed: /api/user/me/
25-02-2021 11:02:15 WARNING  [log.py:224] Bad Request: /api/user/token/
25-02-2021 11:02:15 WARNING  [log.py:224] Bad Request: /api/user/token/
25-02-2021 11:02:16 WARNING  [log.py:224] Bad Request: /api/user/token/
25-02-2021 11:02:16 WARNING  [log.py:224] Bad Request: /api/user/create/
25-02-2021 11:02:16 WARNING  [log.py:224] Unauthorized: /api/user/me/
25-02-2021 11:02:16 WARNING  [log.py:224] Bad Request: /api/user/create/
25-02-2021 11:02:16 WARNING  [log.py:224] Unauthorized: /api/product/product/
25-02-2021 11:02:28 DEBUG    [selector_events.py:59] Using selector: EpollSelector
25-02-2021 11:02:28 INFO     [connectionpool.py:212] Starting new HTTP connection (1): data.fixer.io
25-02-2021 11:02:29 DEBUG    [connectionpool.py:394] "GET /api/latest?access_key=34e2df461e05e5871c51b4293d8a62c8 HTTP/1.1" 200 None
25-02-2021 11:02:30 WARNING  [log.py:224] Method Not Allowed: /api/user/me/
25-02-2021 11:02:31 WARNING  [log.py:224] Bad Request: /api/user/token/
25-02-2021 11:02:31 WARNING  [log.py:224] Bad Request: /api/user/token/
25-02-2021 11:02:31 WARNING  [log.py:224] Bad Request: /api/user/token/
25-02-2021 11:02:31 WARNING  [log.py:224] Bad Request: /api/user/create/
25-02-2021 11:02:31 WARNING  [log.py:224] Unauthorized: /api/user/me/
25-02-2021 11:02:31 WARNING  [log.py:224] Bad Request: /api/user/create/
25-02-2021 11:02:32 WARNING  [log.py:224] Unauthorized: /api/product/product/
25-02-2021 11:48:07 DEBUG    [selector_events.py:59] Using selector: EpollSelector
25-02-2021 11:48:08 INFO     [connectionpool.py:212] Starting new HTTP connection (1): data.fixer.io
25-02-2021 11:48:08 DEBUG    [connectionpool.py:394] "GET /api/latest?access_key=34e2df461e05e5871c51b4293d8a62c8 HTTP/1.1" 200 None
25-02-2021 11:48:10 WARNING  [log.py:224] Method Not Allowed: /api/user/me/
25-02-2021 11:48:11 WARNING  [log.py:224] Bad Request: /api/user/token/
25-02-2021 11:48:11 WARNING  [log.py:224] Bad Request: /api/user/token/
25-02-2021 11:48:12 WARNING  [log.py:224] Bad Request: /api/user/token/
25-02-2021 11:48:12 WARNING  [log.py:224] Bad Request: /api/user/create/
25-02-2021 11:48:12 WARNING  [log.py:224] Unauthorized: /api/user/me/
25-02-2021 11:48:12 WARNING  [log.py:224] Bad Request: /api/user/create/
25-02-2021 11:48:12 WARNING  [log.py:224] Unauthorized: /api/product/product/
25-02-2021 11:48:35 DEBUG    [selector_events.py:59] Using selector: EpollSelector
25-02-2021 11:48:36 INFO     [connectionpool.py:212] Starting new HTTP connection (1): data.fixer.io
25-02-2021 11:48:36 DEBUG    [connectionpool.py:394] "GET /api/latest?access_key=34e2df461e05e5871c51b4293d8a62c8 HTTP/1.1" 200 None
25-02-2021 11:48:38 WARNING  [log.py:224] Method Not Allowed: /api/user/me/
25-02-2021 11:48:39 WARNING  [log.py:224] Bad Request: /api/user/token/
25-02-2021 11:48:39 WARNING  [log.py:224] Bad Request: /api/user/token/
25-02-2021 11:48:39 WARNING  [log.py:224] Bad Request: /api/user/token/
25-02-2021 11:48:39 WARNING  [log.py:224] Bad Request: /api/user/create/
25-02-2021 11:48:39 WARNING  [log.py:224] Unauthorized: /api/user/me/
25-02-2021 11:48:39 WARNING  [log.py:224] Bad Request: /api/user/create/
25-02-2021 11:48:40 WARNING  [log.py:224] Too Many Requests: /api/product/product/
25-02-2021 11:48:40 WARNING  [log.py:224] Unauthorized: /api/product/product/
25-02-2021 11:49:13 DEBUG    [selector_events.py:59] Using selector: EpollSelector
25-02-2021 11:49:13 INFO     [connectionpool.py:212] Starting new HTTP connection (1): data.fixer.io
25-02-2021 11:49:13 DEBUG    [connectionpool.py:394] "GET /api/latest?access_key=34e2df461e05e5871c51b4293d8a62c8 HTTP/1.1" 200 None
25-02-2021 11:49:15 WARNING  [log.py:224] Method Not Allowed: /api/user/me/
25-02-2021 11:49:16 WARNING  [log.py:224] Bad Request: /api/user/token/
25-02-2021 11:49:16 WARNING  [log.py:224] Bad Request: /api/user/token/
25-02-2021 11:49:16 WARNING  [log.py:224] Bad Request: /api/user/token/
25-02-2021 11:49:16 WARNING  [log.py:224] Bad Request: /api/user/create/
25-02-2021 11:49:16 WARNING  [log.py:224] Unauthorized: /api/user/me/
25-02-2021 11:49:16 WARNING  [log.py:224] Bad Request: /api/user/create/
25-02-2021 11:49:17 WARNING  [log.py:224] Unauthorized: /api/product/product/
25-02-2021 11:49:50 DEBUG    [selector_events.py:59] Using selector: EpollSelector
25-02-2021 11:49:51 INFO     [connectionpool.py:212] Starting new HTTP connection (1): data.fixer.io
25-02-2021 11:49:51 DEBUG    [connectionpool.py:394] "GET /api/latest?access_key=34e2df461e05e5871c51b4293d8a62c8 HTTP/1.1" 200 None
25-02-2021 11:49:53 WARNING  [log.py:224] Method Not Allowed: /api/user/me/
25-02-2021 11:49:54 WARNING  [log.py:224] Bad Request: /api/user/token/
25-02-2021 11:49:54 WARNING  [log.py:224] Bad Request: /api/user/token/
25-02-2021 11:49:54 WARNING  [log.py:224] Bad Request: /api/user/token/
25-02-2021 11:49:54 WARNING  [log.py:224] Bad Request: /api/user/create/
25-02-2021 11:49:54 WARNING  [log.py:224] Unauthorized: /api/user/me/
25-02-2021 11:49:54 WARNING  [log.py:224] Bad Request: /api/user/create/
25-02-2021 11:49:55 WARNING  [log.py:224] Unauthorized: /api/product/product/
25-02-2021 11:57:36 DEBUG    [selector_events.py:59] Using selector: EpollSelector
25-02-2021 11:57:36 INFO     [connectionpool.py:212] Starting new HTTP connection (1): data.fixer.io
25-02-2021 11:57:37 DEBUG    [connectionpool.py:394] "GET /api/latest?access_key=34e2df461e05e5871c51b4293d8a62c8 HTTP/1.1" 200 None
25-02-2021 11:57:38 WARNING  [log.py:224] Method Not Allowed: /api/user/me/
25-02-2021 11:57:39 WARNING  [log.py:224] Bad Request: /api/user/token/
25-02-2021 11:57:39 WARNING  [log.py:224] Bad Request: /api/user/token/
25-02-2021 11:57:39 WARNING  [log.py:224] Bad Request: /api/user/token/
25-02-2021 11:57:39 WARNING  [log.py:224] Bad Request: /api/user/create/
25-02-2021 11:57:39 WARNING  [log.py:224] Unauthorized: /api/user/me/
25-02-2021 11:57:40 WARNING  [log.py:224] Bad Request: /api/user/create/
25-02-2021 11:57:40 WARNING  [log.py:224] Too Many Requests: /api/product/product/1/
25-02-2021 11:57:40 WARNING  [log.py:224] Unauthorized: /api/product/product/
25-02-2021 11:58:15 DEBUG    [selector_events.py:59] Using selector: EpollSelector
25-02-2021 11:58:15 INFO     [connectionpool.py:212] Starting new HTTP connection (1): data.fixer.io
25-02-2021 11:58:15 DEBUG    [connectionpool.py:394] "GET /api/latest?access_key=34e2df461e05e5871c51b4293d8a62c8 HTTP/1.1" 200 None
25-02-2021 11:58:17 WARNING  [log.py:224] Method Not Allowed: /api/user/me/
25-02-2021 11:58:17 WARNING  [log.py:224] Bad Request: /api/user/token/
25-02-2021 11:58:17 WARNING  [log.py:224] Bad Request: /api/user/token/
25-02-2021 11:58:18 WARNING  [log.py:224] Bad Request: /api/user/token/
25-02-2021 11:58:18 WARNING  [log.py:224] Bad Request: /api/user/create/
25-02-2021 11:58:18 WARNING  [log.py:224] Unauthorized: /api/user/me/
25-02-2021 11:58:18 WARNING  [log.py:224] Bad Request: /api/user/create/
25-02-2021 11:58:19 WARNING  [log.py:224] Too Many Requests: /api/product/product/
25-02-2021 11:58:19 WARNING  [log.py:224] Unauthorized: /api/product/product/
25-02-2021 11:58:29 DEBUG    [selector_events.py:59] Using selector: EpollSelector
25-02-2021 11:58:29 INFO     [connectionpool.py:212] Starting new HTTP connection (1): data.fixer.io
25-02-2021 11:58:30 DEBUG    [connectionpool.py:394] "GET /api/latest?access_key=34e2df461e05e5871c51b4293d8a62c8 HTTP/1.1" 200 None
25-02-2021 11:58:31 WARNING  [log.py:224] Method Not Allowed: /api/user/me/
25-02-2021 11:58:32 WARNING  [log.py:224] Bad Request: /api/user/token/
25-02-2021 11:58:32 WARNING  [log.py:224] Bad Request: /api/user/token/
25-02-2021 11:58:32 WARNING  [log.py:224] Bad Request: /api/user/token/
25-02-2021 11:58:32 WARNING  [log.py:224] Bad Request: /api/user/create/
25-02-2021 11:58:32 WARNING  [log.py:224] Unauthorized: /api/user/me/
25-02-2021 11:58:32 WARNING  [log.py:224] Bad Request: /api/user/create/
25-02-2021 11:58:33 WARNING  [log.py:224] Unauthorized: /api/product/product/
25-02-2021 12:06:37 INFO     [autoreload.py:617] Watching for file changes with StatReloader
25-02-2021 12:06:43 WARNING  [log.py:224] Not Found: /
25-02-2021 12:06:46 WARNING  [log.py:224] Not Found: /
25-02-2021 12:07:30 DEBUG    [core.py:163] Successfully imported extension module "markdown.extensions.toc".
25-02-2021 12:07:30 DEBUG    [core.py:126] Successfully loaded extension "markdown.extensions.toc.TocExtension".
25-02-2021 12:07:30 WARNING  [log.py:224] Method Not Allowed: /api/user/create/
25-02-2021 12:09:02 DEBUG    [core.py:163] Successfully imported extension module "markdown.extensions.toc".
25-02-2021 12:09:02 DEBUG    [core.py:126] Successfully loaded extension "markdown.extensions.toc.TocExtension".
25-02-2021 12:09:02 WARNING  [log.py:224] Method Not Allowed: /api/user/token/
25-02-2021 12:09:49 DEBUG    [core.py:163] Successfully imported extension module "markdown.extensions.toc".
25-02-2021 12:09:49 DEBUG    [core.py:126] Successfully loaded extension "markdown.extensions.toc.TocExtension".
25-02-2021 12:12:32 DEBUG    [core.py:163] Successfully imported extension module "markdown.extensions.toc".
25-02-2021 12:12:32 DEBUG    [core.py:126] Successfully loaded extension "markdown.extensions.toc.TocExtension".
25-02-2021 12:12:36 DEBUG    [core.py:163] Successfully imported extension module "markdown.extensions.toc".
25-02-2021 12:12:36 DEBUG    [core.py:126] Successfully loaded extension "markdown.extensions.toc.TocExtension".
25-02-2021 12:15:29 DEBUG    [core.py:163] Successfully imported extension module "markdown.extensions.toc".
25-02-2021 12:15:29 DEBUG    [core.py:126] Successfully loaded extension "markdown.extensions.toc.TocExtension".
25-02-2021 12:16:24 DEBUG    [core.py:163] Successfully imported extension module "markdown.extensions.toc".
25-02-2021 12:16:24 DEBUG    [core.py:126] Successfully loaded extension "markdown.extensions.toc.TocExtension".
25-02-2021 12:23:31 DEBUG    [core.py:163] Successfully imported extension module "markdown.extensions.toc".
25-02-2021 12:23:31 DEBUG    [core.py:126] Successfully loaded extension "markdown.extensions.toc.TocExtension".
25-02-2021 12:23:31 DEBUG    [core.py:163] Successfully imported extension module "markdown.extensions.toc".
25-02-2021 12:23:31 DEBUG    [core.py:126] Successfully loaded extension "markdown.extensions.toc.TocExtension".
25-02-2021 12:23:32 DEBUG    [core.py:163] Successfully imported extension module "markdown.extensions.toc".
25-02-2021 12:23:32 DEBUG    [core.py:126] Successfully loaded extension "markdown.extensions.toc.TocExtension".
25-02-2021 12:23:33 DEBUG    [core.py:163] Successfully imported extension module "markdown.extensions.toc".
25-02-2021 12:23:33 DEBUG    [core.py:126] Successfully loaded extension "markdown.extensions.toc.TocExtension".
25-02-2021 12:23:36 DEBUG    [core.py:163] Successfully imported extension module "markdown.extensions.toc".
25-02-2021 12:23:36 DEBUG    [core.py:126] Successfully loaded extension "markdown.extensions.toc.TocExtension".
25-02-2021 12:23:36 WARNING  [log.py:224] Method Not Allowed: /api/user/token/
25-02-2021 12:23:37 DEBUG    [core.py:163] Successfully imported extension module "markdown.extensions.toc".
25-02-2021 12:23:37 DEBUG    [core.py:126] Successfully loaded extension "markdown.extensions.toc.TocExtension".
25-02-2021 12:23:37 WARNING  [log.py:224] Method Not Allowed: /api/user/create/
25-02-2021 12:23:44 DEBUG    [core.py:163] Successfully imported extension module "markdown.extensions.toc".
25-02-2021 12:23:44 DEBUG    [core.py:126] Successfully loaded extension "markdown.extensions.toc.TocExtension".
25-02-2021 12:23:44 WARNING  [log.py:224] Method Not Allowed: /api/user/create/
25-02-2021 12:25:19 WARNING  [log.py:224] Bad Request: /api/user/create/
25-02-2021 12:25:33 DEBUG    [selector_events.py:59] Using selector: EpollSelector
25-02-2021 12:25:33 DEBUG    [selector_events.py:59] Using selector: EpollSelector
25-02-2021 12:25:44 DEBUG    [selector_events.py:59] Using selector: EpollSelector
25-02-2021 12:25:47 INFO     [connectionpool.py:212] Starting new HTTP connection (1): data.fixer.io
25-02-2021 12:25:48 DEBUG    [connectionpool.py:394] "GET /api/latest?access_key=34e2df461e05e5871c51b4293d8a62c8 HTTP/1.1" 200 None
25-02-2021 12:25:53 INFO     [autoreload.py:617] Watching for file changes with StatReloader
25-02-2021 12:27:34 DEBUG    [selector_events.py:59] Using selector: EpollSelector
25-02-2021 12:27:34 DEBUG    [selector_events.py:59] Using selector: EpollSelector
25-02-2021 12:27:35 DEBUG    [selector_events.py:59] Using selector: EpollSelector
25-02-2021 12:27:39 INFO     [connectionpool.py:212] Starting new HTTP connection (1): data.fixer.io
25-02-2021 12:27:40 DEBUG    [connectionpool.py:394] "GET /api/latest?access_key=34e2df461e05e5871c51b4293d8a62c8 HTTP/1.1" 200 None
25-02-2021 12:27:51 INFO     [autoreload.py:617] Watching for file changes with StatReloader
25-02-2021 12:29:04 DEBUG    [core.py:163] Successfully imported extension module "markdown.extensions.toc".
25-02-2021 12:29:04 DEBUG    [core.py:126] Successfully loaded extension "markdown.extensions.toc.TocExtension".
25-02-2021 12:29:04 WARNING  [log.py:224] Method Not Allowed: /api/user/token/
25-02-2021 12:30:03 WARNING  [log.py:224] Unauthorized: /api/user/me/
25-02-2021 12:30:03 WARNING  [log.py:224] Unauthorized: /api/user/me/
25-02-2021 12:30:06 DEBUG    [core.py:163] Successfully imported extension module "markdown.extensions.toc".
25-02-2021 12:30:06 DEBUG    [core.py:126] Successfully loaded extension "markdown.extensions.toc.TocExtension".
25-02-2021 12:30:06 WARNING  [log.py:224] Method Not Allowed: /api/user/token/
25-02-2021 12:30:17 DEBUG    [core.py:163] Successfully imported extension module "markdown.extensions.toc".
25-02-2021 12:30:17 DEBUG    [core.py:126] Successfully loaded extension "markdown.extensions.toc.TocExtension".
25-02-2021 12:30:17 WARNING  [log.py:224] Method Not Allowed: /api/user/token/
25-02-2021 12:30:19 DEBUG    [core.py:163] Successfully imported extension module "markdown.extensions.toc".
25-02-2021 12:30:19 DEBUG    [core.py:126] Successfully loaded extension "markdown.extensions.toc.TocExtension".
25-02-2021 12:30:19 WARNING  [log.py:224] Method Not Allowed: /api/user/token/
25-02-2021 12:30:21 DEBUG    [core.py:163] Successfully imported extension module "markdown.extensions.toc".
25-02-2021 12:30:21 DEBUG    [core.py:126] Successfully loaded extension "markdown.extensions.toc.TocExtension".
25-02-2021 12:30:21 WARNING  [log.py:224] Method Not Allowed: /api/user/token/
25-02-2021 12:30:23 DEBUG    [core.py:163] Successfully imported extension module "markdown.extensions.toc".
25-02-2021 12:30:23 DEBUG    [core.py:126] Successfully loaded extension "markdown.extensions.toc.TocExtension".
25-02-2021 12:31:25 WARNING  [log.py:224] Method Not Allowed: /api/user/me/
25-02-2021 12:31:51 DEBUG    [core.py:163] Successfully imported extension module "markdown.extensions.toc".
25-02-2021 12:31:51 DEBUG    [core.py:126] Successfully loaded extension "markdown.extensions.toc.TocExtension".
25-02-2021 12:31:54 DEBUG    [core.py:163] Successfully imported extension module "markdown.extensions.toc".
25-02-2021 12:31:54 DEBUG    [core.py:126] Successfully loaded extension "markdown.extensions.toc.TocExtension".
25-02-2021 12:32:58 DEBUG    [core.py:163] Successfully imported extension module "markdown.extensions.toc".
25-02-2021 12:32:58 DEBUG    [core.py:126] Successfully loaded extension "markdown.extensions.toc.TocExtension".
25-02-2021 12:33:05 DEBUG    [core.py:163] Successfully imported extension module "markdown.extensions.toc".
25-02-2021 12:33:05 DEBUG    [core.py:126] Successfully loaded extension "markdown.extensions.toc.TocExtension".
25-02-2021 12:33:15 DEBUG    [core.py:163] Successfully imported extension module "markdown.extensions.toc".
25-02-2021 12:33:15 DEBUG    [core.py:126] Successfully loaded extension "markdown.extensions.toc.TocExtension".
25-02-2021 12:33:15 WARNING  [log.py:224] Method Not Allowed: /api/user/token/
25-02-2021 12:33:22 DEBUG    [core.py:163] Successfully imported extension module "markdown.extensions.toc".
25-02-2021 12:33:22 DEBUG    [core.py:126] Successfully loaded extension "markdown.extensions.toc.TocExtension".
25-02-2021 12:33:33 DEBUG    [core.py:163] Successfully imported extension module "markdown.extensions.toc".
25-02-2021 12:33:33 DEBUG    [core.py:126] Successfully loaded extension "markdown.extensions.toc.TocExtension".
25-02-2021 12:33:35 DEBUG    [core.py:163] Successfully imported extension module "markdown.extensions.toc".
25-02-2021 12:33:35 DEBUG    [core.py:126] Successfully loaded extension "markdown.extensions.toc.TocExtension".
25-02-2021 12:35:41 WARNING  [log.py:224] Forbidden: /api/product/product/
25-02-2021 12:37:05 WARNING  [log.py:224] Bad Request: /api/product/product/1/
25-02-2021 12:38:32 DEBUG    [core.py:163] Successfully imported extension module "markdown.extensions.toc".
25-02-2021 12:38:32 DEBUG    [core.py:126] Successfully loaded extension "markdown.extensions.toc.TocExtension".
25-02-2021 12:40:29 DEBUG    [core.py:163] Successfully imported extension module "markdown.extensions.toc".
25-02-2021 12:40:29 DEBUG    [core.py:126] Successfully loaded extension "markdown.extensions.toc.TocExtension".
25-02-2021 12:40:29 WARNING  [log.py:224] Not Found: /api/product/product/total-revenue/
25-02-2021 12:40:55 DEBUG    [core.py:163] Successfully imported extension module "markdown.extensions.toc".
25-02-2021 12:40:55 DEBUG    [core.py:126] Successfully loaded extension "markdown.extensions.toc.TocExtension".
25-02-2021 12:42:24 DEBUG    [selector_events.py:59] Using selector: EpollSelector
25-02-2021 12:42:24 DEBUG    [selector_events.py:59] Using selector: EpollSelector
25-02-2021 12:46:59 DEBUG    [selector_events.py:59] Using selector: EpollSelector
25-02-2021 12:46:59 INFO     [connectionpool.py:212] Starting new HTTP connection (1): data.fixer.io
25-02-2021 12:47:00 DEBUG    [connectionpool.py:394] "GET /api/latest?access_key=34e2df461e05e5871c51b4293d8a62c8 HTTP/1.1" 200 None
25-02-2021 12:47:01 WARNING  [log.py:224] Method Not Allowed: /api/user/me/
25-02-2021 12:47:02 WARNING  [log.py:224] Bad Request: /api/user/token/
25-02-2021 12:47:02 WARNING  [log.py:224] Bad Request: /api/user/token/
25-02-2021 12:47:03 WARNING  [log.py:224] Bad Request: /api/user/token/
25-02-2021 12:47:03 WARNING  [log.py:224] Bad Request: /api/user/create/
25-02-2021 12:47:03 WARNING  [log.py:224] Unauthorized: /api/user/me/
25-02-2021 12:47:03 WARNING  [log.py:224] Bad Request: /api/user/create/
25-02-2021 12:47:03 WARNING  [log.py:224] Unauthorized: /api/product/product/
25-02-2021 12:49:28 INFO     [autoreload.py:617] Watching for file changes with StatReloader
25-02-2021 12:49:37 DEBUG    [core.py:163] Successfully imported extension module "markdown.extensions.toc".
25-02-2021 12:49:37 DEBUG    [core.py:126] Successfully loaded extension "markdown.extensions.toc.TocExtension".
25-02-2021 12:50:41 ERROR    [log.py:224] Internal Server Error: /api/product/order/
Traceback (most recent call last):
  File "/home/mohamedwahba/Desktop/DEV/Order-System/venv/lib/python3.8/site-packages/django/core/handlers/exception.py", line 47, in inner
    response = get_response(request)
  File "/home/mohamedwahba/Desktop/DEV/Order-System/venv/lib/python3.8/site-packages/django/core/handlers/base.py", line 181, in _get_response
    response = wrapped_callback(request, *callback_args, **callback_kwargs)
  File "/home/mohamedwahba/Desktop/DEV/Order-System/venv/lib/python3.8/site-packages/django/views/decorators/csrf.py", line 54, in wrapped_view
    return view_func(*args, **kwargs)
  File "/home/mohamedwahba/Desktop/DEV/Order-System/venv/lib/python3.8/site-packages/rest_framework/viewsets.py", line 125, in view
    return self.dispatch(request, *args, **kwargs)
  File "/home/mohamedwahba/Desktop/DEV/Order-System/venv/lib/python3.8/site-packages/rest_framework/views.py", line 509, in dispatch
    response = self.handle_exception(exc)
  File "/home/mohamedwahba/Desktop/DEV/Order-System/venv/lib/python3.8/site-packages/rest_framework/views.py", line 469, in handle_exception
    self.raise_uncaught_exception(exc)
  File "/home/mohamedwahba/Desktop/DEV/Order-System/venv/lib/python3.8/site-packages/rest_framework/views.py", line 480, in raise_uncaught_exception
    raise exc
  File "/home/mohamedwahba/Desktop/DEV/Order-System/venv/lib/python3.8/site-packages/rest_framework/views.py", line 506, in dispatch
    response = handler(request, *args, **kwargs)
  File "/home/mohamedwahba/Desktop/DEV/Order-System/venv/lib/python3.8/site-packages/rest_framework/mixins.py", line 19, in create
    self.perform_create(serializer)
  File "/home/mohamedwahba/Desktop/DEV/Order-System/product/views.py", line 66, in perform_create
    serializer.save(user=self.request.user)
  File "/home/mohamedwahba/Desktop/DEV/Order-System/venv/lib/python3.8/site-packages/rest_framework/serializers.py", line 205, in save
    self.instance = self.create(validated_data)
  File "/home/mohamedwahba/Desktop/DEV/Order-System/product/serializers.py", line 46, in create
    product_item = Product.objects.get(id=product.get('id'))
  File "/home/mohamedwahba/Desktop/DEV/Order-System/venv/lib/python3.8/site-packages/django/db/models/manager.py", line 85, in manager_method
    return getattr(self.get_queryset(), name)(*args, **kwargs)
  File "/home/mohamedwahba/Desktop/DEV/Order-System/venv/lib/python3.8/site-packages/django/db/models/query.py", line 429, in get
    raise self.model.DoesNotExist(
product.models.Product.DoesNotExist: Product matching query does not exist.
25-02-2021 12:51:32 DEBUG    [core.py:163] Successfully imported extension module "markdown.extensions.toc".
25-02-2021 12:51:32 DEBUG    [core.py:126] Successfully loaded extension "markdown.extensions.toc.TocExtension".
25-02-2021 12:51:42 DEBUG    [core.py:163] Successfully imported extension module "markdown.extensions.toc".
25-02-2021 12:51:42 DEBUG    [core.py:126] Successfully loaded extension "markdown.extensions.toc.TocExtension".
25-02-2021 12:51:46 ERROR    [log.py:224] Internal Server Error: /api/product/order/
Traceback (most recent call last):
  File "/home/mohamedwahba/Desktop/DEV/Order-System/venv/lib/python3.8/site-packages/django/core/handlers/exception.py", line 47, in inner
    response = get_response(request)
  File "/home/mohamedwahba/Desktop/DEV/Order-System/venv/lib/python3.8/site-packages/django/core/handlers/base.py", line 181, in _get_response
    response = wrapped_callback(request, *callback_args, **callback_kwargs)
  File "/home/mohamedwahba/Desktop/DEV/Order-System/venv/lib/python3.8/site-packages/django/views/decorators/csrf.py", line 54, in wrapped_view
    return view_func(*args, **kwargs)
  File "/home/mohamedwahba/Desktop/DEV/Order-System/venv/lib/python3.8/site-packages/rest_framework/viewsets.py", line 125, in view
    return self.dispatch(request, *args, **kwargs)
  File "/home/mohamedwahba/Desktop/DEV/Order-System/venv/lib/python3.8/site-packages/rest_framework/views.py", line 509, in dispatch
    response = self.handle_exception(exc)
  File "/home/mohamedwahba/Desktop/DEV/Order-System/venv/lib/python3.8/site-packages/rest_framework/views.py", line 469, in handle_exception
    self.raise_uncaught_exception(exc)
  File "/home/mohamedwahba/Desktop/DEV/Order-System/venv/lib/python3.8/site-packages/rest_framework/views.py", line 480, in raise_uncaught_exception
    raise exc
  File "/home/mohamedwahba/Desktop/DEV/Order-System/venv/lib/python3.8/site-packages/rest_framework/views.py", line 506, in dispatch
    response = handler(request, *args, **kwargs)
  File "/home/mohamedwahba/Desktop/DEV/Order-System/venv/lib/python3.8/site-packages/rest_framework/mixins.py", line 19, in create
    self.perform_create(serializer)
  File "/home/mohamedwahba/Desktop/DEV/Order-System/product/views.py", line 66, in perform_create
    serializer.save(user=self.request.user)
  File "/home/mohamedwahba/Desktop/DEV/Order-System/venv/lib/python3.8/site-packages/rest_framework/serializers.py", line 205, in save
    self.instance = self.create(validated_data)
  File "/home/mohamedwahba/Desktop/DEV/Order-System/product/serializers.py", line 46, in create
    product_item = Product.objects.get(id=product.get('id'))
  File "/home/mohamedwahba/Desktop/DEV/Order-System/venv/lib/python3.8/site-packages/django/db/models/manager.py", line 85, in manager_method
    return getattr(self.get_queryset(), name)(*args, **kwargs)
  File "/home/mohamedwahba/Desktop/DEV/Order-System/venv/lib/python3.8/site-packages/django/db/models/query.py", line 429, in get
    raise self.model.DoesNotExist(
product.models.Product.DoesNotExist: Product matching query does not exist.
25-02-2021 12:51:55 DEBUG    [core.py:163] Successfully imported extension module "markdown.extensions.toc".
25-02-2021 12:51:55 DEBUG    [core.py:126] Successfully loaded extension "markdown.extensions.toc.TocExtension".
25-02-2021 12:52:00 DEBUG    [core.py:163] Successfully imported extension module "markdown.extensions.toc".
25-02-2021 12:52:00 DEBUG    [core.py:126] Successfully loaded extension "markdown.extensions.toc.TocExtension".
25-02-2021 12:52:18 ERROR    [log.py:224] Internal Server Error: /api/product/order/
Traceback (most recent call last):
  File "/home/mohamedwahba/Desktop/DEV/Order-System/venv/lib/python3.8/site-packages/django/core/handlers/exception.py", line 47, in inner
    response = get_response(request)
  File "/home/mohamedwahba/Desktop/DEV/Order-System/venv/lib/python3.8/site-packages/django/core/handlers/base.py", line 181, in _get_response
    response = wrapped_callback(request, *callback_args, **callback_kwargs)
  File "/home/mohamedwahba/Desktop/DEV/Order-System/venv/lib/python3.8/site-packages/django/views/decorators/csrf.py", line 54, in wrapped_view
    return view_func(*args, **kwargs)
  File "/home/mohamedwahba/Desktop/DEV/Order-System/venv/lib/python3.8/site-packages/rest_framework/viewsets.py", line 125, in view
    return self.dispatch(request, *args, **kwargs)
  File "/home/mohamedwahba/Desktop/DEV/Order-System/venv/lib/python3.8/site-packages/rest_framework/views.py", line 509, in dispatch
    response = self.handle_exception(exc)
  File "/home/mohamedwahba/Desktop/DEV/Order-System/venv/lib/python3.8/site-packages/rest_framework/views.py", line 469, in handle_exception
    self.raise_uncaught_exception(exc)
  File "/home/mohamedwahba/Desktop/DEV/Order-System/venv/lib/python3.8/site-packages/rest_framework/views.py", line 480, in raise_uncaught_exception
    raise exc
  File "/home/mohamedwahba/Desktop/DEV/Order-System/venv/lib/python3.8/site-packages/rest_framework/views.py", line 506, in dispatch
    response = handler(request, *args, **kwargs)
  File "/home/mohamedwahba/Desktop/DEV/Order-System/venv/lib/python3.8/site-packages/rest_framework/mixins.py", line 19, in create
    self.perform_create(serializer)
  File "/home/mohamedwahba/Desktop/DEV/Order-System/product/views.py", line 66, in perform_create
    serializer.save(user=self.request.user)
  File "/home/mohamedwahba/Desktop/DEV/Order-System/venv/lib/python3.8/site-packages/rest_framework/serializers.py", line 205, in save
    self.instance = self.create(validated_data)
  File "/home/mohamedwahba/Desktop/DEV/Order-System/product/serializers.py", line 46, in create
    product_item = Product.objects.get(id=product.get('id'))
  File "/home/mohamedwahba/Desktop/DEV/Order-System/venv/lib/python3.8/site-packages/django/db/models/manager.py", line 85, in manager_method
    return getattr(self.get_queryset(), name)(*args, **kwargs)
  File "/home/mohamedwahba/Desktop/DEV/Order-System/venv/lib/python3.8/site-packages/django/db/models/query.py", line 429, in get
    raise self.model.DoesNotExist(
product.models.Product.DoesNotExist: Product matching query does not exist.
25-02-2021 12:52:22 DEBUG    [core.py:163] Successfully imported extension module "markdown.extensions.toc".
25-02-2021 12:52:22 DEBUG    [core.py:126] Successfully loaded extension "markdown.extensions.toc.TocExtension".
25-02-2021 12:52:24 DEBUG    [core.py:163] Successfully imported extension module "markdown.extensions.toc".
25-02-2021 12:52:24 DEBUG    [core.py:126] Successfully loaded extension "markdown.extensions.toc.TocExtension".
25-02-2021 12:52:24 WARNING  [log.py:224] Too Many Requests: /api/product/product/
25-02-2021 12:52:30 DEBUG    [selector_events.py:59] Using selector: EpollSelector
25-02-2021 12:52:30 DEBUG    [selector_events.py:59] Using selector: EpollSelector
25-02-2021 12:52:31 INFO     [autoreload.py:617] Watching for file changes with StatReloader
25-02-2021 12:52:33 DEBUG    [core.py:163] Successfully imported extension module "markdown.extensions.toc".
25-02-2021 12:52:33 DEBUG    [core.py:126] Successfully loaded extension "markdown.extensions.toc.TocExtension".
25-02-2021 12:53:52 INFO     [autoreload.py:240] /home/mohamedwahba/Desktop/DEV/Order-System/product/views.py changed, reloading.
25-02-2021 12:53:52 DEBUG    [selector_events.py:59] Using selector: EpollSelector
25-02-2021 12:53:52 INFO     [autoreload.py:617] Watching for file changes with StatReloader
25-02-2021 12:57:51 INFO     [autoreload.py:240] /home/mohamedwahba/Desktop/DEV/Order-System/product/views.py changed, reloading.
25-02-2021 12:57:51 DEBUG    [selector_events.py:59] Using selector: EpollSelector
25-02-2021 12:57:51 INFO     [autoreload.py:617] Watching for file changes with StatReloader
25-02-2021 12:57:54 ERROR    [log.py:224] Internal Server Error: /api/product/order/
Traceback (most recent call last):
  File "/home/mohamedwahba/Desktop/DEV/Order-System/venv/lib/python3.8/site-packages/django/core/handlers/exception.py", line 47, in inner
    response = get_response(request)
  File "/home/mohamedwahba/Desktop/DEV/Order-System/venv/lib/python3.8/site-packages/django/core/handlers/base.py", line 181, in _get_response
    response = wrapped_callback(request, *callback_args, **callback_kwargs)
  File "/home/mohamedwahba/Desktop/DEV/Order-System/venv/lib/python3.8/site-packages/django/views/decorators/csrf.py", line 54, in wrapped_view
    return view_func(*args, **kwargs)
  File "/home/mohamedwahba/Desktop/DEV/Order-System/venv/lib/python3.8/site-packages/rest_framework/viewsets.py", line 125, in view
    return self.dispatch(request, *args, **kwargs)
  File "/home/mohamedwahba/Desktop/DEV/Order-System/venv/lib/python3.8/site-packages/rest_framework/views.py", line 509, in dispatch
    response = self.handle_exception(exc)
  File "/home/mohamedwahba/Desktop/DEV/Order-System/venv/lib/python3.8/site-packages/rest_framework/views.py", line 469, in handle_exception
    self.raise_uncaught_exception(exc)
  File "/home/mohamedwahba/Desktop/DEV/Order-System/venv/lib/python3.8/site-packages/rest_framework/views.py", line 480, in raise_uncaught_exception
    raise exc
  File "/home/mohamedwahba/Desktop/DEV/Order-System/venv/lib/python3.8/site-packages/rest_framework/views.py", line 506, in dispatch
    response = handler(request, *args, **kwargs)
  File "/home/mohamedwahba/Desktop/DEV/Order-System/venv/lib/python3.8/site-packages/rest_framework/mixins.py", line 19, in create
    self.perform_create(serializer)
  File "/home/mohamedwahba/Desktop/DEV/Order-System/product/views.py", line 67, in perform_create
    serializer.save(user=self.request.user)
  File "/home/mohamedwahba/Desktop/DEV/Order-System/venv/lib/python3.8/site-packages/rest_framework/serializers.py", line 205, in save
    self.instance = self.create(validated_data)
  File "/home/mohamedwahba/Desktop/DEV/Order-System/product/serializers.py", line 46, in create
    product_item = Product.objects.get(id=product.get('id'))
  File "/home/mohamedwahba/Desktop/DEV/Order-System/venv/lib/python3.8/site-packages/django/db/models/manager.py", line 85, in manager_method
    return getattr(self.get_queryset(), name)(*args, **kwargs)
  File "/home/mohamedwahba/Desktop/DEV/Order-System/venv/lib/python3.8/site-packages/django/db/models/query.py", line 429, in get
    raise self.model.DoesNotExist(
product.models.Product.DoesNotExist: Product matching query does not exist.
25-02-2021 12:58:29 INFO     [autoreload.py:240] /home/mohamedwahba/Desktop/DEV/Order-System/product/views.py changed, reloading.
25-02-2021 12:58:29 DEBUG    [selector_events.py:59] Using selector: EpollSelector
25-02-2021 12:58:29 INFO     [autoreload.py:617] Watching for file changes with StatReloader
25-02-2021 12:59:24 INFO     [autoreload.py:240] /home/mohamedwahba/Desktop/DEV/Order-System/product/serializers.py changed, reloading.
25-02-2021 12:59:24 DEBUG    [selector_events.py:59] Using selector: EpollSelector
25-02-2021 12:59:24 INFO     [autoreload.py:617] Watching for file changes with StatReloader
25-02-2021 12:59:26 ERROR    [log.py:224] Internal Server Error: /api/product/order/
Traceback (most recent call last):
  File "/home/mohamedwahba/Desktop/DEV/Order-System/venv/lib/python3.8/site-packages/django/core/handlers/exception.py", line 47, in inner
    response = get_response(request)
  File "/home/mohamedwahba/Desktop/DEV/Order-System/venv/lib/python3.8/site-packages/django/core/handlers/base.py", line 181, in _get_response
    response = wrapped_callback(request, *callback_args, **callback_kwargs)
  File "/home/mohamedwahba/Desktop/DEV/Order-System/venv/lib/python3.8/site-packages/django/views/decorators/csrf.py", line 54, in wrapped_view
    return view_func(*args, **kwargs)
  File "/home/mohamedwahba/Desktop/DEV/Order-System/venv/lib/python3.8/site-packages/rest_framework/viewsets.py", line 125, in view
    return self.dispatch(request, *args, **kwargs)
  File "/home/mohamedwahba/Desktop/DEV/Order-System/venv/lib/python3.8/site-packages/rest_framework/views.py", line 509, in dispatch
    response = self.handle_exception(exc)
  File "/home/mohamedwahba/Desktop/DEV/Order-System/venv/lib/python3.8/site-packages/rest_framework/views.py", line 469, in handle_exception
    self.raise_uncaught_exception(exc)
  File "/home/mohamedwahba/Desktop/DEV/Order-System/venv/lib/python3.8/site-packages/rest_framework/views.py", line 480, in raise_uncaught_exception
    raise exc
  File "/home/mohamedwahba/Desktop/DEV/Order-System/venv/lib/python3.8/site-packages/rest_framework/views.py", line 506, in dispatch
    response = handler(request, *args, **kwargs)
  File "/home/mohamedwahba/Desktop/DEV/Order-System/venv/lib/python3.8/site-packages/rest_framework/mixins.py", line 19, in create
    self.perform_create(serializer)
  File "/home/mohamedwahba/Desktop/DEV/Order-System/product/views.py", line 66, in perform_create
    serializer.save(user=self.request.user)
  File "/home/mohamedwahba/Desktop/DEV/Order-System/venv/lib/python3.8/site-packages/rest_framework/serializers.py", line 205, in save
    self.instance = self.create(validated_data)
  File "/home/mohamedwahba/Desktop/DEV/Order-System/product/serializers.py", line 46, in create
    product_item = Product.objects.get(id=product.get('id'))
  File "/home/mohamedwahba/Desktop/DEV/Order-System/venv/lib/python3.8/site-packages/django/db/models/manager.py", line 85, in manager_method
    return getattr(self.get_queryset(), name)(*args, **kwargs)
  File "/home/mohamedwahba/Desktop/DEV/Order-System/venv/lib/python3.8/site-packages/django/db/models/query.py", line 429, in get
    raise self.model.DoesNotExist(
product.models.Product.DoesNotExist: Product matching query does not exist.
25-02-2021 12:59:29 ERROR    [log.py:224] Internal Server Error: /api/product/order/
Traceback (most recent call last):
  File "/home/mohamedwahba/Desktop/DEV/Order-System/venv/lib/python3.8/site-packages/django/core/handlers/exception.py", line 47, in inner
    response = get_response(request)
  File "/home/mohamedwahba/Desktop/DEV/Order-System/venv/lib/python3.8/site-packages/django/core/handlers/base.py", line 181, in _get_response
    response = wrapped_callback(request, *callback_args, **callback_kwargs)
  File "/home/mohamedwahba/Desktop/DEV/Order-System/venv/lib/python3.8/site-packages/django/views/decorators/csrf.py", line 54, in wrapped_view
    return view_func(*args, **kwargs)
  File "/home/mohamedwahba/Desktop/DEV/Order-System/venv/lib/python3.8/site-packages/rest_framework/viewsets.py", line 125, in view
    return self.dispatch(request, *args, **kwargs)
  File "/home/mohamedwahba/Desktop/DEV/Order-System/venv/lib/python3.8/site-packages/rest_framework/views.py", line 509, in dispatch
    response = self.handle_exception(exc)
  File "/home/mohamedwahba/Desktop/DEV/Order-System/venv/lib/python3.8/site-packages/rest_framework/views.py", line 469, in handle_exception
    self.raise_uncaught_exception(exc)
  File "/home/mohamedwahba/Desktop/DEV/Order-System/venv/lib/python3.8/site-packages/rest_framework/views.py", line 480, in raise_uncaught_exception
    raise exc
  File "/home/mohamedwahba/Desktop/DEV/Order-System/venv/lib/python3.8/site-packages/rest_framework/views.py", line 506, in dispatch
    response = handler(request, *args, **kwargs)
  File "/home/mohamedwahba/Desktop/DEV/Order-System/venv/lib/python3.8/site-packages/rest_framework/mixins.py", line 19, in create
    self.perform_create(serializer)
  File "/home/mohamedwahba/Desktop/DEV/Order-System/product/views.py", line 66, in perform_create
    serializer.save(user=self.request.user)
  File "/home/mohamedwahba/Desktop/DEV/Order-System/venv/lib/python3.8/site-packages/rest_framework/serializers.py", line 205, in save
    self.instance = self.create(validated_data)
  File "/home/mohamedwahba/Desktop/DEV/Order-System/product/serializers.py", line 46, in create
    product_item = Product.objects.get(id=product.get('id'))
  File "/home/mohamedwahba/Desktop/DEV/Order-System/venv/lib/python3.8/site-packages/django/db/models/manager.py", line 85, in manager_method
    return getattr(self.get_queryset(), name)(*args, **kwargs)
  File "/home/mohamedwahba/Desktop/DEV/Order-System/venv/lib/python3.8/site-packages/django/db/models/query.py", line 429, in get
    raise self.model.DoesNotExist(
product.models.Product.DoesNotExist: Product matching query does not exist.
25-02-2021 12:59:49 ERROR    [log.py:224] Internal Server Error: /api/product/order/
Traceback (most recent call last):
  File "/home/mohamedwahba/Desktop/DEV/Order-System/venv/lib/python3.8/site-packages/django/core/handlers/exception.py", line 47, in inner
    response = get_response(request)
  File "/home/mohamedwahba/Desktop/DEV/Order-System/venv/lib/python3.8/site-packages/django/core/handlers/base.py", line 181, in _get_response
    response = wrapped_callback(request, *callback_args, **callback_kwargs)
  File "/home/mohamedwahba/Desktop/DEV/Order-System/venv/lib/python3.8/site-packages/django/views/decorators/csrf.py", line 54, in wrapped_view
    return view_func(*args, **kwargs)
  File "/home/mohamedwahba/Desktop/DEV/Order-System/venv/lib/python3.8/site-packages/rest_framework/viewsets.py", line 125, in view
    return self.dispatch(request, *args, **kwargs)
  File "/home/mohamedwahba/Desktop/DEV/Order-System/venv/lib/python3.8/site-packages/rest_framework/views.py", line 509, in dispatch
    response = self.handle_exception(exc)
  File "/home/mohamedwahba/Desktop/DEV/Order-System/venv/lib/python3.8/site-packages/rest_framework/views.py", line 469, in handle_exception
    self.raise_uncaught_exception(exc)
  File "/home/mohamedwahba/Desktop/DEV/Order-System/venv/lib/python3.8/site-packages/rest_framework/views.py", line 480, in raise_uncaught_exception
    raise exc
  File "/home/mohamedwahba/Desktop/DEV/Order-System/venv/lib/python3.8/site-packages/rest_framework/views.py", line 506, in dispatch
    response = handler(request, *args, **kwargs)
  File "/home/mohamedwahba/Desktop/DEV/Order-System/venv/lib/python3.8/site-packages/rest_framework/mixins.py", line 19, in create
    self.perform_create(serializer)
  File "/home/mohamedwahba/Desktop/DEV/Order-System/product/views.py", line 66, in perform_create
    serializer.save(user=self.request.user)
  File "/home/mohamedwahba/Desktop/DEV/Order-System/venv/lib/python3.8/site-packages/rest_framework/serializers.py", line 205, in save
    self.instance = self.create(validated_data)
  File "/home/mohamedwahba/Desktop/DEV/Order-System/product/serializers.py", line 46, in create
    product_item = Product.objects.first(id=product.get('id'))
  File "/home/mohamedwahba/Desktop/DEV/Order-System/venv/lib/python3.8/site-packages/django/db/models/manager.py", line 85, in manager_method
    return getattr(self.get_queryset(), name)(*args, **kwargs)
  File "/home/mohamedwahba/Desktop/DEV/Order-System/venv/lib/python3.8/site-packages/django/db/models/query.py", line 429, in get
    raise self.model.DoesNotExist(
product.models.Product.DoesNotExist: Product matching query does not exist.
25-02-2021 12:59:49 INFO     [autoreload.py:240] /home/mohamedwahba/Desktop/DEV/Order-System/product/serializers.py changed, reloading.
25-02-2021 12:59:49 DEBUG    [selector_events.py:59] Using selector: EpollSelector
25-02-2021 12:59:49 INFO     [autoreload.py:617] Watching for file changes with StatReloader
25-02-2021 12:59:56 ERROR    [log.py:224] Internal Server Error: /api/product/order/
Traceback (most recent call last):
  File "/home/mohamedwahba/Desktop/DEV/Order-System/venv/lib/python3.8/site-packages/django/core/handlers/exception.py", line 47, in inner
    response = get_response(request)
  File "/home/mohamedwahba/Desktop/DEV/Order-System/venv/lib/python3.8/site-packages/django/core/handlers/base.py", line 181, in _get_response
    response = wrapped_callback(request, *callback_args, **callback_kwargs)
  File "/home/mohamedwahba/Desktop/DEV/Order-System/venv/lib/python3.8/site-packages/django/views/decorators/csrf.py", line 54, in wrapped_view
    return view_func(*args, **kwargs)
  File "/home/mohamedwahba/Desktop/DEV/Order-System/venv/lib/python3.8/site-packages/rest_framework/viewsets.py", line 125, in view
    return self.dispatch(request, *args, **kwargs)
  File "/home/mohamedwahba/Desktop/DEV/Order-System/venv/lib/python3.8/site-packages/rest_framework/views.py", line 509, in dispatch
    response = self.handle_exception(exc)
  File "/home/mohamedwahba/Desktop/DEV/Order-System/venv/lib/python3.8/site-packages/rest_framework/views.py", line 469, in handle_exception
    self.raise_uncaught_exception(exc)
  File "/home/mohamedwahba/Desktop/DEV/Order-System/venv/lib/python3.8/site-packages/rest_framework/views.py", line 480, in raise_uncaught_exception
    raise exc
  File "/home/mohamedwahba/Desktop/DEV/Order-System/venv/lib/python3.8/site-packages/rest_framework/views.py", line 506, in dispatch
    response = handler(request, *args, **kwargs)
  File "/home/mohamedwahba/Desktop/DEV/Order-System/venv/lib/python3.8/site-packages/rest_framework/mixins.py", line 19, in create
    self.perform_create(serializer)
  File "/home/mohamedwahba/Desktop/DEV/Order-System/product/views.py", line 66, in perform_create
    serializer.save(user=self.request.user)
  File "/home/mohamedwahba/Desktop/DEV/Order-System/venv/lib/python3.8/site-packages/rest_framework/serializers.py", line 205, in save
    self.instance = self.create(validated_data)
  File "/home/mohamedwahba/Desktop/DEV/Order-System/product/serializers.py", line 46, in create
    product_item = Product.objects.first(id=product.get('id'))
  File "/home/mohamedwahba/Desktop/DEV/Order-System/venv/lib/python3.8/site-packages/django/db/models/manager.py", line 85, in manager_method
    return getattr(self.get_queryset(), name)(*args, **kwargs)
TypeError: first() got an unexpected keyword argument 'id'
25-02-2021 13:00:18 INFO     [autoreload.py:240] /home/mohamedwahba/Desktop/DEV/Order-System/product/serializers.py changed, reloading.
25-02-2021 13:00:18 DEBUG    [selector_events.py:59] Using selector: EpollSelector
25-02-2021 13:00:19 INFO     [autoreload.py:617] Watching for file changes with StatReloader
25-02-2021 13:01:42 INFO     [autoreload.py:240] /home/mohamedwahba/Desktop/DEV/Order-System/product/serializers.py changed, reloading.
25-02-2021 13:01:42 DEBUG    [selector_events.py:59] Using selector: EpollSelector
25-02-2021 13:01:42 INFO     [autoreload.py:617] Watching for file changes with StatReloader
25-02-2021 13:01:45 ERROR    [log.py:224] Internal Server Error: /api/product/order/
Traceback (most recent call last):
  File "/home/mohamedwahba/Desktop/DEV/Order-System/venv/lib/python3.8/site-packages/rest_framework/fields.py", line 457, in get_attribute
    return get_attribute(instance, self.source_attrs)
  File "/home/mohamedwahba/Desktop/DEV/Order-System/venv/lib/python3.8/site-packages/rest_framework/fields.py", line 97, in get_attribute
    instance = getattr(instance, attr)
AttributeError: 'Response' object has no attribute 'products'

During handling of the above exception, another exception occurred:

Traceback (most recent call last):
  File "/home/mohamedwahba/Desktop/DEV/Order-System/venv/lib/python3.8/site-packages/django/core/handlers/exception.py", line 47, in inner
    response = get_response(request)
  File "/home/mohamedwahba/Desktop/DEV/Order-System/venv/lib/python3.8/site-packages/django/core/handlers/base.py", line 181, in _get_response
    response = wrapped_callback(request, *callback_args, **callback_kwargs)
  File "/home/mohamedwahba/Desktop/DEV/Order-System/venv/lib/python3.8/site-packages/django/views/decorators/csrf.py", line 54, in wrapped_view
    return view_func(*args, **kwargs)
  File "/home/mohamedwahba/Desktop/DEV/Order-System/venv/lib/python3.8/site-packages/rest_framework/viewsets.py", line 125, in view
    return self.dispatch(request, *args, **kwargs)
  File "/home/mohamedwahba/Desktop/DEV/Order-System/venv/lib/python3.8/site-packages/rest_framework/views.py", line 509, in dispatch
    response = self.handle_exception(exc)
  File "/home/mohamedwahba/Desktop/DEV/Order-System/venv/lib/python3.8/site-packages/rest_framework/views.py", line 469, in handle_exception
    self.raise_uncaught_exception(exc)
  File "/home/mohamedwahba/Desktop/DEV/Order-System/venv/lib/python3.8/site-packages/rest_framework/views.py", line 480, in raise_uncaught_exception
    raise exc
  File "/home/mohamedwahba/Desktop/DEV/Order-System/venv/lib/python3.8/site-packages/rest_framework/views.py", line 506, in dispatch
    response = handler(request, *args, **kwargs)
  File "/home/mohamedwahba/Desktop/DEV/Order-System/venv/lib/python3.8/site-packages/rest_framework/mixins.py", line 20, in create
    headers = self.get_success_headers(serializer.data)
  File "/home/mohamedwahba/Desktop/DEV/Order-System/venv/lib/python3.8/site-packages/rest_framework/serializers.py", line 548, in data
    ret = super().data
  File "/home/mohamedwahba/Desktop/DEV/Order-System/venv/lib/python3.8/site-packages/rest_framework/serializers.py", line 246, in data
    self._data = self.to_representation(self.instance)
  File "/home/mohamedwahba/Desktop/DEV/Order-System/venv/lib/python3.8/site-packages/rest_framework/serializers.py", line 502, in to_representation
    attribute = field.get_attribute(instance)
  File "/home/mohamedwahba/Desktop/DEV/Order-System/venv/lib/python3.8/site-packages/rest_framework/fields.py", line 490, in get_attribute
    raise type(exc)(msg)
AttributeError: Got AttributeError when attempting to get a value for field `products` on serializer `OrderSerializer`.
The serializer field might be named incorrectly and not match any attribute or key on the `Response` instance.
Original exception text was: 'Response' object has no attribute 'products'.
25-02-2021 13:02:04 ERROR    [log.py:224] Internal Server Error: /api/product/order/
Traceback (most recent call last):
  File "/home/mohamedwahba/Desktop/DEV/Order-System/venv/lib/python3.8/site-packages/rest_framework/fields.py", line 457, in get_attribute
    return get_attribute(instance, self.source_attrs)
  File "/home/mohamedwahba/Desktop/DEV/Order-System/venv/lib/python3.8/site-packages/rest_framework/fields.py", line 97, in get_attribute
    instance = getattr(instance, attr)
AttributeError: 'Response' object has no attribute 'products'

During handling of the above exception, another exception occurred:

Traceback (most recent call last):
  File "/home/mohamedwahba/Desktop/DEV/Order-System/venv/lib/python3.8/site-packages/django/core/handlers/exception.py", line 47, in inner
    response = get_response(request)
  File "/home/mohamedwahba/Desktop/DEV/Order-System/venv/lib/python3.8/site-packages/django/core/handlers/base.py", line 181, in _get_response
    response = wrapped_callback(request, *callback_args, **callback_kwargs)
  File "/home/mohamedwahba/Desktop/DEV/Order-System/venv/lib/python3.8/site-packages/django/views/decorators/csrf.py", line 54, in wrapped_view
    return view_func(*args, **kwargs)
  File "/home/mohamedwahba/Desktop/DEV/Order-System/venv/lib/python3.8/site-packages/rest_framework/viewsets.py", line 125, in view
    return self.dispatch(request, *args, **kwargs)
  File "/home/mohamedwahba/Desktop/DEV/Order-System/venv/lib/python3.8/site-packages/rest_framework/views.py", line 509, in dispatch
    response = self.handle_exception(exc)
  File "/home/mohamedwahba/Desktop/DEV/Order-System/venv/lib/python3.8/site-packages/rest_framework/views.py", line 469, in handle_exception
    self.raise_uncaught_exception(exc)
  File "/home/mohamedwahba/Desktop/DEV/Order-System/venv/lib/python3.8/site-packages/rest_framework/views.py", line 480, in raise_uncaught_exception
    raise exc
  File "/home/mohamedwahba/Desktop/DEV/Order-System/venv/lib/python3.8/site-packages/rest_framework/views.py", line 506, in dispatch
    response = handler(request, *args, **kwargs)
  File "/home/mohamedwahba/Desktop/DEV/Order-System/venv/lib/python3.8/site-packages/rest_framework/mixins.py", line 20, in create
    headers = self.get_success_headers(serializer.data)
  File "/home/mohamedwahba/Desktop/DEV/Order-System/venv/lib/python3.8/site-packages/rest_framework/serializers.py", line 548, in data
    ret = super().data
  File "/home/mohamedwahba/Desktop/DEV/Order-System/venv/lib/python3.8/site-packages/rest_framework/serializers.py", line 246, in data
    self._data = self.to_representation(self.instance)
  File "/home/mohamedwahba/Desktop/DEV/Order-System/venv/lib/python3.8/site-packages/rest_framework/serializers.py", line 502, in to_representation
    attribute = field.get_attribute(instance)
  File "/home/mohamedwahba/Desktop/DEV/Order-System/venv/lib/python3.8/site-packages/rest_framework/fields.py", line 490, in get_attribute
    raise type(exc)(msg)
AttributeError: Got AttributeError when attempting to get a value for field `products` on serializer `OrderSerializer`.
The serializer field might be named incorrectly and not match any attribute or key on the `Response` instance.
Original exception text was: 'Response' object has no attribute 'products'.
25-02-2021 13:02:04 INFO     [autoreload.py:240] /home/mohamedwahba/Desktop/DEV/Order-System/product/serializers.py changed, reloading.
25-02-2021 13:02:04 DEBUG    [selector_events.py:59] Using selector: EpollSelector
25-02-2021 13:02:05 INFO     [autoreload.py:617] Watching for file changes with StatReloader
25-02-2021 13:03:14 INFO     [autoreload.py:240] /home/mohamedwahba/Desktop/DEV/Order-System/product/views.py changed, reloading.
25-02-2021 13:03:14 DEBUG    [selector_events.py:59] Using selector: EpollSelector
25-02-2021 13:03:14 INFO     [autoreload.py:617] Watching for file changes with StatReloader
25-02-2021 13:03:33 INFO     [autoreload.py:240] /home/mohamedwahba/Desktop/DEV/Order-System/product/views.py changed, reloading.
25-02-2021 13:03:33 DEBUG    [selector_events.py:59] Using selector: EpollSelector
25-02-2021 13:03:33 INFO     [autoreload.py:617] Watching for file changes with StatReloader
25-02-2021 13:03:35 DEBUG    [selector_events.py:59] Using selector: EpollSelector
25-02-2021 13:03:35 DEBUG    [selector_events.py:59] Using selector: EpollSelector
